[2025-08-13T20:07:48.601+0000] {taskinstance.py:1956} INFO - Dependencies all met for dep_context=non-requeueable deps ti=<TaskInstance: bank_data_generation_dag.generate_bank_data scheduled__2025-08-13T19:00:00+00:00 [queued]>
[2025-08-13T20:07:48.623+0000] {taskinstance.py:1956} INFO - Dependencies all met for dep_context=requeueable deps ti=<TaskInstance: bank_data_generation_dag.generate_bank_data scheduled__2025-08-13T19:00:00+00:00 [queued]>
[2025-08-13T20:07:48.624+0000] {taskinstance.py:2170} INFO - Starting attempt 1 of 1
[2025-08-13T20:07:48.658+0000] {taskinstance.py:2191} INFO - Executing <Task(DockerOperator): generate_bank_data> on 2025-08-13 19:00:00+00:00
[2025-08-13T20:07:48.669+0000] {standard_task_runner.py:60} INFO - Started process 49 to run task
[2025-08-13T20:07:48.685+0000] {standard_task_runner.py:87} INFO - Running: ['***', 'tasks', 'run', 'bank_data_generation_dag', 'generate_bank_data', 'scheduled__2025-08-13T19:00:00+00:00', '--job-id', '4', '--raw', '--subdir', 'DAGS_FOLDER/bank_data_dag.py', '--cfg-path', '/tmp/tmpz91d1q6z']
[2025-08-13T20:07:48.687+0000] {standard_task_runner.py:88} INFO - Job 4: Subtask generate_bank_data
[2025-08-13T20:07:48.879+0000] {task_command.py:423} INFO - Running <TaskInstance: bank_data_generation_dag.generate_bank_data scheduled__2025-08-13T19:00:00+00:00 [running]> on host dfcc3bfc409d
[2025-08-13T20:07:49.097+0000] {taskinstance.py:2480} INFO - Exporting env vars: AIRFLOW_CTX_DAG_OWNER='***' AIRFLOW_CTX_DAG_ID='bank_data_generation_dag' AIRFLOW_CTX_TASK_ID='generate_bank_data' AIRFLOW_CTX_EXECUTION_DATE='2025-08-13T19:00:00+00:00' AIRFLOW_CTX_TRY_NUMBER='1' AIRFLOW_CTX_DAG_RUN_ID='scheduled__2025-08-13T19:00:00+00:00'
[2025-08-13T20:07:49.249+0000] {docker.py:359} INFO - Starting docker container from image arlequin-pyspark-client
[2025-08-13T20:07:52.248+0000] {docker.py:429} INFO - ⏳ Esperando que el maestro de Spark esté disponible en spark-master:7077...
❌ Un error crítico ha ocurrido: [Errno -2] Name or service not known
[2025-08-13T20:07:52.924+0000] {taskinstance.py:2698} ERROR - Task failed with exception
Traceback (most recent call last):
  File "/home/airflow/.local/lib/python3.9/site-packages/airflow/models/taskinstance.py", line 433, in _execute_task
    result = execute_callable(context=context, **execute_callable_kwargs)
  File "/home/airflow/.local/lib/python3.9/site-packages/airflow/providers/docker/operators/docker.py", line 502, in execute
    return self._run_image()
  File "/home/airflow/.local/lib/python3.9/site-packages/airflow/providers/docker/operators/docker.py", line 376, in _run_image
    return self._run_image_with_mounts(self.mounts, add_tmp_variable=False)
  File "/home/airflow/.local/lib/python3.9/site-packages/airflow/providers/docker/operators/docker.py", line 437, in _run_image_with_mounts
    raise DockerContainerFailedException(f"Docker container failed: {result!r}", logs=log_lines)
airflow.providers.docker.exceptions.DockerContainerFailedException: Docker container failed: {'StatusCode': 1}
[2025-08-13T20:07:52.932+0000] {taskinstance.py:1138} INFO - Marking task as FAILED. dag_id=bank_data_generation_dag, task_id=generate_bank_data, execution_date=20250813T190000, start_date=20250813T200748, end_date=20250813T200752
[2025-08-13T20:07:52.980+0000] {standard_task_runner.py:107} ERROR - Failed to execute job 4 for task generate_bank_data (Docker container failed: {'StatusCode': 1}; 49)
[2025-08-13T20:07:53.026+0000] {local_task_job_runner.py:234} INFO - Task exited with return code 1
[2025-08-13T20:07:53.065+0000] {taskinstance.py:3280} INFO - 0 downstream tasks scheduled from follow-on schedule check
