[2025-08-07T22:44:00.256+0000] {scheduler_job_runner.py:1586} WARNING - Marking task instance <TaskInstance: bank_data_generation_dag.generate_bank_data scheduled__2025-08-07T21:00:00+00:00 [queued]> stuck in queued as failed. If the task instance has available retries, it will be retried.
[2025-08-07T22:44:00.657+0000] {scheduler_job_runner.py:781} ERROR - Executor reports task instance <TaskInstance: bank_data_generation_dag.generate_bank_data scheduled__2025-08-07T21:00:00+00:00 [queued]> finished (failed) although the task says it's queued. (Info: None) Was the task killed externally?
