[2025-08-13T13:21:43.258+0000] {taskinstance.py:1956} INFO - Dependencies all met for dep_context=non-requeueable deps ti=<TaskInstance: bank_data_generation_dag.generate_bank_data scheduled__2025-08-13T12:00:00+00:00 [queued]>
[2025-08-13T13:21:43.285+0000] {taskinstance.py:1956} INFO - Dependencies all met for dep_context=requeueable deps ti=<TaskInstance: bank_data_generation_dag.generate_bank_data scheduled__2025-08-13T12:00:00+00:00 [queued]>
[2025-08-13T13:21:43.287+0000] {taskinstance.py:2170} INFO - Starting attempt 1 of 1
[2025-08-13T13:21:43.328+0000] {taskinstance.py:2191} INFO - Executing <Task(DockerOperator): generate_bank_data> on 2025-08-13 12:00:00+00:00
[2025-08-13T13:21:43.365+0000] {standard_task_runner.py:60} INFO - Started process 49 to run task
[2025-08-13T13:21:43.370+0000] {standard_task_runner.py:87} INFO - Running: ['***', 'tasks', 'run', 'bank_data_generation_dag', 'generate_bank_data', 'scheduled__2025-08-13T12:00:00+00:00', '--job-id', '2', '--raw', '--subdir', 'DAGS_FOLDER/bank_data_dag.py', '--cfg-path', '/tmp/tmp4zug5945']
[2025-08-13T13:21:43.373+0000] {standard_task_runner.py:88} INFO - Job 2: Subtask generate_bank_data
[2025-08-13T13:21:43.441+0000] {warnings.py:109} WARNING - /home/***/.local/lib/python3.9/site-packages/***/settings.py:194: DeprecationWarning: The sql_alchemy_conn option in [core] has been moved to the sql_alchemy_conn option in [database] - the old setting has been used, but please update your config.
  SQL_ALCHEMY_CONN = conf.get("database", "SQL_ALCHEMY_CONN")

[2025-08-13T13:21:43.669+0000] {task_command.py:423} INFO - Running <TaskInstance: bank_data_generation_dag.generate_bank_data scheduled__2025-08-13T12:00:00+00:00 [running]> on host 81a061516138
[2025-08-13T13:21:43.987+0000] {taskinstance.py:2480} INFO - Exporting env vars: AIRFLOW_CTX_DAG_OWNER='***' AIRFLOW_CTX_DAG_ID='bank_data_generation_dag' AIRFLOW_CTX_TASK_ID='generate_bank_data' AIRFLOW_CTX_EXECUTION_DATE='2025-08-13T12:00:00+00:00' AIRFLOW_CTX_TRY_NUMBER='1' AIRFLOW_CTX_DAG_RUN_ID='scheduled__2025-08-13T12:00:00+00:00'
[2025-08-13T13:21:44.333+0000] {docker.py:359} INFO - Starting docker container from image arlequin-pyspark-client
[2025-08-13T13:21:44.876+0000] {taskinstance.py:2698} ERROR - Task failed with exception
Traceback (most recent call last):
  File "/home/airflow/.local/lib/python3.9/site-packages/docker/api/client.py", line 265, in _raise_for_status
    response.raise_for_status()
  File "/home/airflow/.local/lib/python3.9/site-packages/requests/models.py", line 1021, in raise_for_status
    raise HTTPError(http_error_msg, response=self)
requests.exceptions.HTTPError: 400 Client Error: Bad Request for url: http+docker://localhost/v1.51/containers/create

The above exception was the direct cause of the following exception:

Traceback (most recent call last):
  File "/home/airflow/.local/lib/python3.9/site-packages/airflow/models/taskinstance.py", line 433, in _execute_task
    result = execute_callable(context=context, **execute_callable_kwargs)
  File "/home/airflow/.local/lib/python3.9/site-packages/airflow/providers/docker/operators/docker.py", line 502, in execute
    return self._run_image()
  File "/home/airflow/.local/lib/python3.9/site-packages/airflow/providers/docker/operators/docker.py", line 376, in _run_image
    return self._run_image_with_mounts(self.mounts, add_tmp_variable=False)
  File "/home/airflow/.local/lib/python3.9/site-packages/airflow/providers/docker/operators/docker.py", line 391, in _run_image_with_mounts
    self.container = self.cli.create_container(
  File "/home/airflow/.local/lib/python3.9/site-packages/docker/api/container.py", line 439, in create_container
    return self.create_container_from_config(config, name, platform)
  File "/home/airflow/.local/lib/python3.9/site-packages/docker/api/container.py", line 456, in create_container_from_config
    return self._result(res, True)
  File "/home/airflow/.local/lib/python3.9/site-packages/docker/api/client.py", line 271, in _result
    self._raise_for_status(response)
  File "/home/airflow/.local/lib/python3.9/site-packages/docker/api/client.py", line 267, in _raise_for_status
    raise create_api_error_from_http_exception(e) from e
  File "/home/airflow/.local/lib/python3.9/site-packages/docker/errors.py", line 39, in create_api_error_from_http_exception
    raise cls(e, response=response, explanation=explanation) from e
docker.errors.APIError: 400 Client Error for http+docker://localhost/v1.51/containers/create: Bad Request ("invalid mount config for type "bind": bind source path does not exist: /opt/airflow/scripts")
[2025-08-13T13:21:44.957+0000] {taskinstance.py:1138} INFO - Marking task as FAILED. dag_id=bank_data_generation_dag, task_id=generate_bank_data, execution_date=20250813T120000, start_date=20250813T132143, end_date=20250813T132144
[2025-08-13T13:21:45.054+0000] {standard_task_runner.py:107} ERROR - Failed to execute job 2 for task generate_bank_data (400 Client Error for http+docker://localhost/v1.51/containers/create: Bad Request ("invalid mount config for type "bind": bind source path does not exist: /opt/airflow/scripts"); 49)
[2025-08-13T13:21:45.115+0000] {local_task_job_runner.py:234} INFO - Task exited with return code 1
[2025-08-13T13:21:45.143+0000] {taskinstance.py:3280} INFO - 0 downstream tasks scheduled from follow-on schedule check
[2025-08-13T13:36:08.446+0000] {taskinstance.py:1956} INFO - Dependencies all met for dep_context=non-requeueable deps ti=<TaskInstance: bank_data_generation_dag.generate_bank_data scheduled__2025-08-13T12:00:00+00:00 [queued]>
[2025-08-13T13:36:08.460+0000] {taskinstance.py:1956} INFO - Dependencies all met for dep_context=requeueable deps ti=<TaskInstance: bank_data_generation_dag.generate_bank_data scheduled__2025-08-13T12:00:00+00:00 [queued]>
[2025-08-13T13:36:08.461+0000] {taskinstance.py:2170} INFO - Starting attempt 1 of 1
[2025-08-13T13:36:08.483+0000] {taskinstance.py:2191} INFO - Executing <Task(DockerOperator): generate_bank_data> on 2025-08-13 12:00:00+00:00
[2025-08-13T13:36:08.491+0000] {standard_task_runner.py:60} INFO - Started process 48 to run task
[2025-08-13T13:36:08.496+0000] {standard_task_runner.py:87} INFO - Running: ['***', 'tasks', 'run', 'bank_data_generation_dag', 'generate_bank_data', 'scheduled__2025-08-13T12:00:00+00:00', '--job-id', '2', '--raw', '--subdir', 'DAGS_FOLDER/bank_data_dag.py', '--cfg-path', '/tmp/tmpiu26bjay']
[2025-08-13T13:36:08.499+0000] {standard_task_runner.py:88} INFO - Job 2: Subtask generate_bank_data
[2025-08-13T13:36:08.525+0000] {warnings.py:109} WARNING - /home/***/.local/lib/python3.9/site-packages/***/settings.py:194: DeprecationWarning: The sql_alchemy_conn option in [core] has been moved to the sql_alchemy_conn option in [database] - the old setting has been used, but please update your config.
  SQL_ALCHEMY_CONN = conf.get("database", "SQL_ALCHEMY_CONN")

[2025-08-13T13:36:08.578+0000] {task_command.py:423} INFO - Running <TaskInstance: bank_data_generation_dag.generate_bank_data scheduled__2025-08-13T12:00:00+00:00 [running]> on host b8b84f2a33e0
[2025-08-13T13:36:08.698+0000] {taskinstance.py:2480} INFO - Exporting env vars: AIRFLOW_CTX_DAG_OWNER='***' AIRFLOW_CTX_DAG_ID='bank_data_generation_dag' AIRFLOW_CTX_TASK_ID='generate_bank_data' AIRFLOW_CTX_EXECUTION_DATE='2025-08-13T12:00:00+00:00' AIRFLOW_CTX_TRY_NUMBER='1' AIRFLOW_CTX_DAG_RUN_ID='scheduled__2025-08-13T12:00:00+00:00'
[2025-08-13T13:36:08.897+0000] {docker.py:359} INFO - Starting docker container from image arlequin-pyspark-client
[2025-08-13T13:36:09.047+0000] {taskinstance.py:2698} ERROR - Task failed with exception
Traceback (most recent call last):
  File "/home/airflow/.local/lib/python3.9/site-packages/docker/api/client.py", line 265, in _raise_for_status
    response.raise_for_status()
  File "/home/airflow/.local/lib/python3.9/site-packages/requests/models.py", line 1021, in raise_for_status
    raise HTTPError(http_error_msg, response=self)
requests.exceptions.HTTPError: 400 Client Error: Bad Request for url: http+docker://localhost/v1.51/containers/create

The above exception was the direct cause of the following exception:

Traceback (most recent call last):
  File "/home/airflow/.local/lib/python3.9/site-packages/airflow/models/taskinstance.py", line 433, in _execute_task
    result = execute_callable(context=context, **execute_callable_kwargs)
  File "/home/airflow/.local/lib/python3.9/site-packages/airflow/providers/docker/operators/docker.py", line 502, in execute
    return self._run_image()
  File "/home/airflow/.local/lib/python3.9/site-packages/airflow/providers/docker/operators/docker.py", line 376, in _run_image
    return self._run_image_with_mounts(self.mounts, add_tmp_variable=False)
  File "/home/airflow/.local/lib/python3.9/site-packages/airflow/providers/docker/operators/docker.py", line 391, in _run_image_with_mounts
    self.container = self.cli.create_container(
  File "/home/airflow/.local/lib/python3.9/site-packages/docker/api/container.py", line 439, in create_container
    return self.create_container_from_config(config, name, platform)
  File "/home/airflow/.local/lib/python3.9/site-packages/docker/api/container.py", line 456, in create_container_from_config
    return self._result(res, True)
  File "/home/airflow/.local/lib/python3.9/site-packages/docker/api/client.py", line 271, in _result
    self._raise_for_status(response)
  File "/home/airflow/.local/lib/python3.9/site-packages/docker/api/client.py", line 267, in _raise_for_status
    raise create_api_error_from_http_exception(e) from e
  File "/home/airflow/.local/lib/python3.9/site-packages/docker/errors.py", line 39, in create_api_error_from_http_exception
    raise cls(e, response=response, explanation=explanation) from e
docker.errors.APIError: 400 Client Error for http+docker://localhost/v1.51/containers/create: Bad Request ("invalid mount config for type "bind": bind source path does not exist: /opt/airflow/scripts")
[2025-08-13T13:36:09.066+0000] {taskinstance.py:1138} INFO - Marking task as FAILED. dag_id=bank_data_generation_dag, task_id=generate_bank_data, execution_date=20250813T120000, start_date=20250813T133608, end_date=20250813T133609
[2025-08-13T13:36:09.090+0000] {standard_task_runner.py:107} ERROR - Failed to execute job 2 for task generate_bank_data (400 Client Error for http+docker://localhost/v1.51/containers/create: Bad Request ("invalid mount config for type "bind": bind source path does not exist: /opt/airflow/scripts"); 48)
[2025-08-13T13:36:09.112+0000] {local_task_job_runner.py:234} INFO - Task exited with return code 1
[2025-08-13T13:36:09.134+0000] {taskinstance.py:3280} INFO - 0 downstream tasks scheduled from follow-on schedule check
[2025-08-13T13:47:54.546+0000] {taskinstance.py:1956} INFO - Dependencies all met for dep_context=non-requeueable deps ti=<TaskInstance: bank_data_generation_dag.generate_bank_data scheduled__2025-08-13T12:00:00+00:00 [queued]>
[2025-08-13T13:47:54.560+0000] {taskinstance.py:1956} INFO - Dependencies all met for dep_context=requeueable deps ti=<TaskInstance: bank_data_generation_dag.generate_bank_data scheduled__2025-08-13T12:00:00+00:00 [queued]>
[2025-08-13T13:47:54.561+0000] {taskinstance.py:2170} INFO - Starting attempt 1 of 1
[2025-08-13T13:47:54.583+0000] {taskinstance.py:2191} INFO - Executing <Task(DockerOperator): generate_bank_data> on 2025-08-13 12:00:00+00:00
[2025-08-13T13:47:54.591+0000] {standard_task_runner.py:60} INFO - Started process 50 to run task
[2025-08-13T13:47:54.598+0000] {standard_task_runner.py:87} INFO - Running: ['***', 'tasks', 'run', 'bank_data_generation_dag', 'generate_bank_data', 'scheduled__2025-08-13T12:00:00+00:00', '--job-id', '2', '--raw', '--subdir', 'DAGS_FOLDER/bank_data_dag.py', '--cfg-path', '/tmp/tmp4f4dgwl3']
[2025-08-13T13:47:54.600+0000] {standard_task_runner.py:88} INFO - Job 2: Subtask generate_bank_data
[2025-08-13T13:47:54.636+0000] {warnings.py:109} WARNING - /home/***/.local/lib/python3.9/site-packages/***/settings.py:194: DeprecationWarning: The sql_alchemy_conn option in [core] has been moved to the sql_alchemy_conn option in [database] - the old setting has been used, but please update your config.
  SQL_ALCHEMY_CONN = conf.get("database", "SQL_ALCHEMY_CONN")

[2025-08-13T13:47:54.702+0000] {task_command.py:423} INFO - Running <TaskInstance: bank_data_generation_dag.generate_bank_data scheduled__2025-08-13T12:00:00+00:00 [running]> on host e096652e1243
[2025-08-13T13:47:54.803+0000] {taskinstance.py:2480} INFO - Exporting env vars: AIRFLOW_CTX_DAG_OWNER='***' AIRFLOW_CTX_DAG_ID='bank_data_generation_dag' AIRFLOW_CTX_TASK_ID='generate_bank_data' AIRFLOW_CTX_EXECUTION_DATE='2025-08-13T12:00:00+00:00' AIRFLOW_CTX_TRY_NUMBER='1' AIRFLOW_CTX_DAG_RUN_ID='scheduled__2025-08-13T12:00:00+00:00'
[2025-08-13T13:47:54.987+0000] {docker.py:359} INFO - Starting docker container from image arlequin-pyspark-client
[2025-08-13T13:47:56.103+0000] {taskinstance.py:2698} ERROR - Task failed with exception
Traceback (most recent call last):
  File "/home/airflow/.local/lib/python3.9/site-packages/docker/api/client.py", line 265, in _raise_for_status
    response.raise_for_status()
  File "/home/airflow/.local/lib/python3.9/site-packages/requests/models.py", line 1021, in raise_for_status
    raise HTTPError(http_error_msg, response=self)
requests.exceptions.HTTPError: 400 Client Error: Bad Request for url: http+docker://localhost/v1.51/containers/20951edec7e6974f4334f0f4da1e14c036a1f5243f189a1cfba00995ba6b52b2/start

The above exception was the direct cause of the following exception:

Traceback (most recent call last):
  File "/home/airflow/.local/lib/python3.9/site-packages/airflow/models/taskinstance.py", line 433, in _execute_task
    result = execute_callable(context=context, **execute_callable_kwargs)
  File "/home/airflow/.local/lib/python3.9/site-packages/airflow/providers/docker/operators/docker.py", line 502, in execute
    return self._run_image()
  File "/home/airflow/.local/lib/python3.9/site-packages/airflow/providers/docker/operators/docker.py", line 376, in _run_image
    return self._run_image_with_mounts(self.mounts, add_tmp_variable=False)
  File "/home/airflow/.local/lib/python3.9/site-packages/airflow/providers/docker/operators/docker.py", line 423, in _run_image_with_mounts
    self.cli.start(self.container["Id"])
  File "/home/airflow/.local/lib/python3.9/site-packages/docker/utils/decorators.py", line 19, in wrapped
    return f(self, resource_id, *args, **kwargs)
  File "/home/airflow/.local/lib/python3.9/site-packages/docker/api/container.py", line 1135, in start
    self._raise_for_status(res)
  File "/home/airflow/.local/lib/python3.9/site-packages/docker/api/client.py", line 267, in _raise_for_status
    raise create_api_error_from_http_exception(e) from e
  File "/home/airflow/.local/lib/python3.9/site-packages/docker/errors.py", line 39, in create_api_error_from_http_exception
    raise cls(e, response=response, explanation=explanation) from e
docker.errors.APIError: 400 Client Error for http+docker://localhost/v1.51/containers/20951edec7e6974f4334f0f4da1e14c036a1f5243f189a1cfba00995ba6b52b2/start: Bad Request ("failed to create task for container: failed to create shim task: OCI runtime create failed: runc create failed: unable to start container process: error during container init: exec: "python": executable file not found in $PATH: unknown")
[2025-08-13T13:47:56.140+0000] {taskinstance.py:1138} INFO - Marking task as FAILED. dag_id=bank_data_generation_dag, task_id=generate_bank_data, execution_date=20250813T120000, start_date=20250813T134754, end_date=20250813T134756
[2025-08-13T13:47:56.167+0000] {standard_task_runner.py:107} ERROR - Failed to execute job 2 for task generate_bank_data (400 Client Error for http+docker://localhost/v1.51/containers/20951edec7e6974f4334f0f4da1e14c036a1f5243f189a1cfba00995ba6b52b2/start: Bad Request ("failed to create task for container: failed to create shim task: OCI runtime create failed: runc create failed: unable to start container process: error during container init: exec: "python": executable file not found in $PATH: unknown"); 50)
[2025-08-13T13:47:56.218+0000] {local_task_job_runner.py:234} INFO - Task exited with return code 1
[2025-08-13T13:47:56.243+0000] {taskinstance.py:3280} INFO - 0 downstream tasks scheduled from follow-on schedule check
