[2025-08-13T04:35:51.268+0000] {taskinstance.py:1956} INFO - Dependencies all met for dep_context=non-requeueable deps ti=<TaskInstance: bank_data_generation_dag.generate_bank_data manual__2025-08-13T04:35:48.081695+00:00 [queued]>
[2025-08-13T04:35:51.287+0000] {taskinstance.py:1956} INFO - Dependencies all met for dep_context=requeueable deps ti=<TaskInstance: bank_data_generation_dag.generate_bank_data manual__2025-08-13T04:35:48.081695+00:00 [queued]>
[2025-08-13T04:35:51.287+0000] {taskinstance.py:2170} INFO - Starting attempt 1 of 1
[2025-08-13T04:35:51.310+0000] {taskinstance.py:2191} INFO - Executing <Task(DockerOperator): generate_bank_data> on 2025-08-13 04:35:48.081695+00:00
[2025-08-13T04:35:51.319+0000] {standard_task_runner.py:60} INFO - Started process 50 to run task
[2025-08-13T04:35:51.323+0000] {standard_task_runner.py:87} INFO - Running: ['***', 'tasks', 'run', 'bank_data_generation_dag', 'generate_bank_data', 'manual__2025-08-13T04:35:48.081695+00:00', '--job-id', '3', '--raw', '--subdir', 'DAGS_FOLDER/bank_data_dag.py', '--cfg-path', '/tmp/tmpc3iubu7q']
[2025-08-13T04:35:51.324+0000] {standard_task_runner.py:88} INFO - Job 3: Subtask generate_bank_data
[2025-08-13T04:35:51.343+0000] {warnings.py:109} WARNING - /home/***/.local/lib/python3.9/site-packages/***/settings.py:194: DeprecationWarning: The sql_alchemy_conn option in [core] has been moved to the sql_alchemy_conn option in [database] - the old setting has been used, but please update your config.
  SQL_ALCHEMY_CONN = conf.get("database", "SQL_ALCHEMY_CONN")

[2025-08-13T04:35:51.389+0000] {task_command.py:423} INFO - Running <TaskInstance: bank_data_generation_dag.generate_bank_data manual__2025-08-13T04:35:48.081695+00:00 [running]> on host 0cc288d64c78
[2025-08-13T04:35:51.493+0000] {taskinstance.py:2480} INFO - Exporting env vars: AIRFLOW_CTX_DAG_OWNER='***' AIRFLOW_CTX_DAG_ID='bank_data_generation_dag' AIRFLOW_CTX_TASK_ID='generate_bank_data' AIRFLOW_CTX_EXECUTION_DATE='2025-08-13T04:35:48.081695+00:00' AIRFLOW_CTX_TRY_NUMBER='1' AIRFLOW_CTX_DAG_RUN_ID='manual__2025-08-13T04:35:48.081695+00:00'
[2025-08-13T04:35:51.566+0000] {docker.py:359} INFO - Starting docker container from image arlequin-pyspark-client
[2025-08-13T04:35:52.467+0000] {docker.py:429} INFO - /opt/spark/bin/load-spark-env.sh: line 68: ps: command not found
[2025-08-13T04:36:01.994+0000] {docker.py:429} INFO - ⏳ Esperando que el maestro de Spark esté disponible en spark-master:7077...
[2025-08-13T04:36:02.173+0000] {docker.py:429} INFO - ❌ Un error crítico ha ocurrido: [Errno -2] Name or service not known
[2025-08-13T04:36:02.320+0000] {docker.py:429} INFO - 25/08/13 04:36:02 INFO ShutdownHookManager: Shutdown hook called
[2025-08-13T04:36:02.330+0000] {docker.py:429} INFO - 25/08/13 04:36:02 INFO ShutdownHookManager: Deleting directory /tmp/spark-94383f30-fd13-4d6b-ba2e-083174f52828
[2025-08-13T04:36:03.509+0000] {taskinstance.py:2698} ERROR - Task failed with exception
Traceback (most recent call last):
  File "/home/airflow/.local/lib/python3.9/site-packages/airflow/models/taskinstance.py", line 433, in _execute_task
    result = execute_callable(context=context, **execute_callable_kwargs)
  File "/home/airflow/.local/lib/python3.9/site-packages/airflow/providers/docker/operators/docker.py", line 502, in execute
    return self._run_image()
  File "/home/airflow/.local/lib/python3.9/site-packages/airflow/providers/docker/operators/docker.py", line 376, in _run_image
    return self._run_image_with_mounts(self.mounts, add_tmp_variable=False)
  File "/home/airflow/.local/lib/python3.9/site-packages/airflow/providers/docker/operators/docker.py", line 437, in _run_image_with_mounts
    raise DockerContainerFailedException(f"Docker container failed: {result!r}", logs=log_lines)
airflow.providers.docker.exceptions.DockerContainerFailedException: Docker container failed: {'StatusCode': 1}
[2025-08-13T04:36:03.522+0000] {taskinstance.py:1138} INFO - Marking task as FAILED. dag_id=bank_data_generation_dag, task_id=generate_bank_data, execution_date=20250813T043548, start_date=20250813T043551, end_date=20250813T043603
[2025-08-13T04:36:03.554+0000] {standard_task_runner.py:107} ERROR - Failed to execute job 3 for task generate_bank_data (Docker container failed: {'StatusCode': 1}; 50)
[2025-08-13T04:36:03.580+0000] {local_task_job_runner.py:234} INFO - Task exited with return code 1
[2025-08-13T04:36:03.609+0000] {taskinstance.py:3280} INFO - 0 downstream tasks scheduled from follow-on schedule check
