[2025-08-13T15:12:36.097+0000] {taskinstance.py:1956} INFO - Dependencies all met for dep_context=non-requeueable deps ti=<TaskInstance: bank_data_generation_dag.generate_bank_data scheduled__2025-08-13T14:00:00+00:00 [queued]>
[2025-08-13T15:12:36.112+0000] {taskinstance.py:1956} INFO - Dependencies all met for dep_context=requeueable deps ti=<TaskInstance: bank_data_generation_dag.generate_bank_data scheduled__2025-08-13T14:00:00+00:00 [queued]>
[2025-08-13T15:12:36.113+0000] {taskinstance.py:2170} INFO - Starting attempt 1 of 1
[2025-08-13T15:12:36.137+0000] {taskinstance.py:2191} INFO - Executing <Task(DockerOperator): generate_bank_data> on 2025-08-13 14:00:00+00:00
[2025-08-13T15:12:36.154+0000] {standard_task_runner.py:60} INFO - Started process 49 to run task
[2025-08-13T15:12:36.160+0000] {standard_task_runner.py:87} INFO - Running: ['***', 'tasks', 'run', 'bank_data_generation_dag', 'generate_bank_data', 'scheduled__2025-08-13T14:00:00+00:00', '--job-id', '2', '--raw', '--subdir', 'DAGS_FOLDER/bank_data_dag.py', '--cfg-path', '/tmp/tmpxd06uvhc']
[2025-08-13T15:12:36.164+0000] {standard_task_runner.py:88} INFO - Job 2: Subtask generate_bank_data
[2025-08-13T15:12:36.237+0000] {warnings.py:109} WARNING - /home/***/.local/lib/python3.9/site-packages/***/settings.py:194: DeprecationWarning: The sql_alchemy_conn option in [core] has been moved to the sql_alchemy_conn option in [database] - the old setting has been used, but please update your config.
  SQL_ALCHEMY_CONN = conf.get("database", "SQL_ALCHEMY_CONN")

[2025-08-13T15:12:36.328+0000] {task_command.py:423} INFO - Running <TaskInstance: bank_data_generation_dag.generate_bank_data scheduled__2025-08-13T14:00:00+00:00 [running]> on host c9275fabe7e5
[2025-08-13T15:12:36.482+0000] {taskinstance.py:2480} INFO - Exporting env vars: AIRFLOW_CTX_DAG_OWNER='***' AIRFLOW_CTX_DAG_ID='bank_data_generation_dag' AIRFLOW_CTX_TASK_ID='generate_bank_data' AIRFLOW_CTX_EXECUTION_DATE='2025-08-13T14:00:00+00:00' AIRFLOW_CTX_TRY_NUMBER='1' AIRFLOW_CTX_DAG_RUN_ID='scheduled__2025-08-13T14:00:00+00:00'
[2025-08-13T15:12:36.696+0000] {docker.py:359} INFO - Starting docker container from image arlequin-pyspark-client
[2025-08-13T15:12:39.953+0000] {docker.py:429} INFO - /opt/spark/bin/load-spark-env.sh: line 68: ps: command not found
[2025-08-13T15:12:45.185+0000] {docker.py:429} INFO - Setting default log level to "WARN".
To adjust logging level use sc.setLogLevel(newLevel). For SparkR, use setLogLevel(newLevel).
[2025-08-13T15:12:45.818+0000] {docker.py:429} INFO - 25/08/13 15:12:45 WARN NativeCodeLoader: Unable to load native-hadoop library for your platform... using builtin-java classes where applicable
[2025-08-13T15:13:11.510+0000] {job.py:213} ERROR - Job heartbeat got an exception
Traceback (most recent call last):
  File "/home/airflow/.local/lib/python3.9/site-packages/sqlalchemy/engine/base.py", line 3371, in _wrap_pool_connect
    return fn()
  File "/home/airflow/.local/lib/python3.9/site-packages/sqlalchemy/pool/base.py", line 327, in connect
    return _ConnectionFairy._checkout(self)
  File "/home/airflow/.local/lib/python3.9/site-packages/sqlalchemy/pool/base.py", line 894, in _checkout
    fairy = _ConnectionRecord.checkout(pool)
  File "/home/airflow/.local/lib/python3.9/site-packages/sqlalchemy/pool/base.py", line 493, in checkout
    rec = pool._do_get()
  File "/home/airflow/.local/lib/python3.9/site-packages/sqlalchemy/pool/impl.py", line 256, in _do_get
    return self._create_connection()
  File "/home/airflow/.local/lib/python3.9/site-packages/sqlalchemy/pool/base.py", line 273, in _create_connection
    return _ConnectionRecord(self)
  File "/home/airflow/.local/lib/python3.9/site-packages/sqlalchemy/pool/base.py", line 388, in __init__
    self.__connect()
  File "/home/airflow/.local/lib/python3.9/site-packages/sqlalchemy/pool/base.py", line 691, in __connect
    pool.logger.debug("Error on connect(): %s", e)
  File "/home/airflow/.local/lib/python3.9/site-packages/sqlalchemy/util/langhelpers.py", line 70, in __exit__
    compat.raise_(
  File "/home/airflow/.local/lib/python3.9/site-packages/sqlalchemy/util/compat.py", line 211, in raise_
    raise exception
  File "/home/airflow/.local/lib/python3.9/site-packages/sqlalchemy/pool/base.py", line 686, in __connect
    self.dbapi_connection = connection = pool._invoke_creator(self)
  File "/home/airflow/.local/lib/python3.9/site-packages/sqlalchemy/engine/create.py", line 574, in connect
    return dialect.connect(*cargs, **cparams)
  File "/home/airflow/.local/lib/python3.9/site-packages/sqlalchemy/engine/default.py", line 598, in connect
    return self.dbapi.connect(*cargs, **cparams)
  File "/home/airflow/.local/lib/python3.9/site-packages/psycopg2/__init__.py", line 122, in connect
    conn = _connect(dsn, connection_factory=connection_factory, **kwasync)
psycopg2.OperationalError: could not translate host name "postgres" to address: Temporary failure in name resolution


The above exception was the direct cause of the following exception:

Traceback (most recent call last):
  File "/home/airflow/.local/lib/python3.9/site-packages/airflow/jobs/job.py", line 187, in heartbeat
    self._merge_from(Job._fetch_from_db(self, session))
  File "/home/airflow/.local/lib/python3.9/site-packages/airflow/api_internal/internal_api_call.py", line 114, in wrapper
    return func(*args, **kwargs)
  File "/home/airflow/.local/lib/python3.9/site-packages/airflow/utils/session.py", line 76, in wrapper
    return func(*args, **kwargs)
  File "/home/airflow/.local/lib/python3.9/site-packages/airflow/jobs/job.py", line 308, in _fetch_from_db
    session.merge(job)
  File "/home/airflow/.local/lib/python3.9/site-packages/sqlalchemy/orm/session.py", line 3056, in merge
    return self._merge(
  File "/home/airflow/.local/lib/python3.9/site-packages/sqlalchemy/orm/session.py", line 3136, in _merge
    merged = self.get(
  File "/home/airflow/.local/lib/python3.9/site-packages/sqlalchemy/orm/session.py", line 2853, in get
    return self._get_impl(
  File "/home/airflow/.local/lib/python3.9/site-packages/sqlalchemy/orm/session.py", line 2975, in _get_impl
    return db_load_fn(
  File "/home/airflow/.local/lib/python3.9/site-packages/sqlalchemy/orm/loading.py", line 530, in load_on_pk_identity
    session.execute(
  File "/home/airflow/.local/lib/python3.9/site-packages/sqlalchemy/orm/session.py", line 1716, in execute
    conn = self._connection_for_bind(bind)
  File "/home/airflow/.local/lib/python3.9/site-packages/sqlalchemy/orm/session.py", line 1555, in _connection_for_bind
    return self._transaction._connection_for_bind(
  File "/home/airflow/.local/lib/python3.9/site-packages/sqlalchemy/orm/session.py", line 750, in _connection_for_bind
    conn = bind.connect()
  File "/home/airflow/.local/lib/python3.9/site-packages/sqlalchemy/future/engine.py", line 412, in connect
    return super(Engine, self).connect()
  File "/home/airflow/.local/lib/python3.9/site-packages/sqlalchemy/engine/base.py", line 3325, in connect
    return self._connection_cls(self, close_with_result=close_with_result)
  File "/home/airflow/.local/lib/python3.9/site-packages/sqlalchemy/engine/base.py", line 96, in __init__
    else engine.raw_connection()
  File "/home/airflow/.local/lib/python3.9/site-packages/sqlalchemy/engine/base.py", line 3404, in raw_connection
    return self._wrap_pool_connect(self.pool.connect, _connection)
  File "/home/airflow/.local/lib/python3.9/site-packages/sqlalchemy/engine/base.py", line 3374, in _wrap_pool_connect
    Connection._handle_dbapi_exception_noconnection(
  File "/home/airflow/.local/lib/python3.9/site-packages/sqlalchemy/engine/base.py", line 2208, in _handle_dbapi_exception_noconnection
    util.raise_(
  File "/home/airflow/.local/lib/python3.9/site-packages/sqlalchemy/util/compat.py", line 211, in raise_
    raise exception
  File "/home/airflow/.local/lib/python3.9/site-packages/sqlalchemy/engine/base.py", line 3371, in _wrap_pool_connect
    return fn()
  File "/home/airflow/.local/lib/python3.9/site-packages/sqlalchemy/pool/base.py", line 327, in connect
    return _ConnectionFairy._checkout(self)
  File "/home/airflow/.local/lib/python3.9/site-packages/sqlalchemy/pool/base.py", line 894, in _checkout
    fairy = _ConnectionRecord.checkout(pool)
  File "/home/airflow/.local/lib/python3.9/site-packages/sqlalchemy/pool/base.py", line 493, in checkout
    rec = pool._do_get()
  File "/home/airflow/.local/lib/python3.9/site-packages/sqlalchemy/pool/impl.py", line 256, in _do_get
    return self._create_connection()
  File "/home/airflow/.local/lib/python3.9/site-packages/sqlalchemy/pool/base.py", line 273, in _create_connection
    return _ConnectionRecord(self)
  File "/home/airflow/.local/lib/python3.9/site-packages/sqlalchemy/pool/base.py", line 388, in __init__
    self.__connect()
  File "/home/airflow/.local/lib/python3.9/site-packages/sqlalchemy/pool/base.py", line 691, in __connect
    pool.logger.debug("Error on connect(): %s", e)
  File "/home/airflow/.local/lib/python3.9/site-packages/sqlalchemy/util/langhelpers.py", line 70, in __exit__
    compat.raise_(
  File "/home/airflow/.local/lib/python3.9/site-packages/sqlalchemy/util/compat.py", line 211, in raise_
    raise exception
  File "/home/airflow/.local/lib/python3.9/site-packages/sqlalchemy/pool/base.py", line 686, in __connect
    self.dbapi_connection = connection = pool._invoke_creator(self)
  File "/home/airflow/.local/lib/python3.9/site-packages/sqlalchemy/engine/create.py", line 574, in connect
    return dialect.connect(*cargs, **cparams)
  File "/home/airflow/.local/lib/python3.9/site-packages/sqlalchemy/engine/default.py", line 598, in connect
    return self.dbapi.connect(*cargs, **cparams)
  File "/home/airflow/.local/lib/python3.9/site-packages/psycopg2/__init__.py", line 122, in connect
    conn = _connect(dsn, connection_factory=connection_factory, **kwasync)
sqlalchemy.exc.OperationalError: (psycopg2.OperationalError) could not translate host name "postgres" to address: Temporary failure in name resolution

(Background on this error at: https://sqlalche.me/e/14/e3q8)
[2025-08-13T15:13:11.691+0000] {job.py:221} ERROR - Job heartbeat failed with error. Scheduler is in unhealthy state
[2025-08-13T15:13:26.912+0000] {job.py:221} ERROR - Job heartbeat failed with error. Scheduler is in unhealthy state
[2025-08-13T15:13:47.328+0000] {job.py:221} ERROR - Job heartbeat failed with error. Scheduler is in unhealthy state
[2025-08-13T15:14:01.606+0000] {docker.py:429} INFO - [Stage 0:>                                                          (0 + 0) / 2][Stage 0:>                                                          (0 + 1) / 2]
[2025-08-13T15:14:03.049+0000] {docker.py:429} INFO - [Stage 0:>                                                          (0 + 1) / 2]
[2025-08-13T15:14:10.055+0000] {docker.py:429} INFO - [Stage 0:=============================>                             (1 + 1) / 2]
[2025-08-13T15:14:10.274+0000] {docker.py:429} INFO - 
[2025-08-13T15:14:22.268+0000] {docker.py:429} INFO - [Stage 2:>                                                          (0 + 2) / 2]
[2025-08-13T15:14:22.467+0000] {docker.py:429} INFO - [Stage 2:=============================>                             (1 + 1) / 2]
[2025-08-13T15:14:22.903+0000] {docker.py:429} INFO - 
[2025-08-13T15:14:28.926+0000] {docker.py:429} INFO - ⏳ Esperando que el maestro de Spark esté disponible en spark-master:7077...
✅ Maestro de Spark en spark-master:7077 está disponible.
Iniciando la generación y escritura de datos en HDFS...
Batch 1 de 50 registros escrito en HDFS en hdfs:///user/bank_data/bank_transactions.
--- Data Drift factor actualizado a: 0.17 ---
Batch 2 de 50 registros escrito en HDFS en hdfs:///user/bank_data/bank_transactions.
Batch 3 de 50 registros escrito en HDFS en hdfs:///user/bank_data/bank_transactions.
Generación de datos finalizada.
[2025-08-13T15:14:29.664+0000] {taskinstance.py:1138} INFO - Marking task as SUCCESS. dag_id=bank_data_generation_dag, task_id=generate_bank_data, execution_date=20250813T140000, start_date=20250813T151236, end_date=20250813T151429
[2025-08-13T15:14:29.747+0000] {local_task_job_runner.py:234} INFO - Task exited with return code 0
[2025-08-13T15:14:29.783+0000] {taskinstance.py:3280} INFO - 0 downstream tasks scheduled from follow-on schedule check
