[2025-08-04T22:45:27.172+0000] {processor.py:161} INFO - Started process (PID=29) to work on /opt/airflow/dags/bank_data_dag.py
[2025-08-04T22:45:27.191+0000] {processor.py:830} INFO - Processing file /opt/airflow/dags/bank_data_dag.py for tasks to queue
[2025-08-04T22:45:27.220+0000] {logging_mixin.py:188} INFO - [2025-08-04T22:45:27.213+0000] {dagbag.py:538} INFO - Filling up the DagBag from /opt/airflow/dags/bank_data_dag.py
[2025-08-04T22:45:27.578+0000] {logging_mixin.py:188} INFO - [2025-08-04T22:45:27.511+0000] {dagbag.py:348} ERROR - Failed to import: /opt/airflow/dags/bank_data_dag.py
Traceback (most recent call last):
  File "/home/airflow/.local/lib/python3.9/site-packages/airflow/models/dagbag.py", line 344, in parse
    loader.exec_module(new_module)
  File "<frozen importlib._bootstrap_external>", line 850, in exec_module
  File "<frozen importlib._bootstrap>", line 228, in _call_with_frames_removed
  File "/opt/airflow/dags/bank_data_dag.py", line 15, in <module>
    generate_bank_data = DockerOperator(
  File "/home/airflow/.local/lib/python3.9/site-packages/airflow/models/baseoperator.py", line 437, in apply_defaults
    result = func(self, **kwargs, default_args=default_args)
  File "/home/airflow/.local/lib/python3.9/site-packages/airflow/providers/docker/operators/docker.py", line 265, in __init__
    super().__init__(**kwargs)
  File "/home/airflow/.local/lib/python3.9/site-packages/airflow/models/baseoperator.py", line 437, in apply_defaults
    result = func(self, **kwargs, default_args=default_args)
  File "/home/airflow/.local/lib/python3.9/site-packages/airflow/models/baseoperator.py", line 793, in __init__
    raise AirflowException(
airflow.exceptions.AirflowException: Invalid arguments were passed to DockerOperator (task_id: generate_bank_data). Invalid arguments were:
**kwargs: {'volumes': ['/your/local/path/to/arlequin/scripts:/scripts', '/your/local/path/to/arlequin/hadoop-base/hadoop-conf:/opt/hadoop/etc/hadoop']}
[2025-08-04T22:45:27.589+0000] {processor.py:842} WARNING - No viable dags retrieved from /opt/airflow/dags/bank_data_dag.py
[2025-08-04T22:45:28.102+0000] {processor.py:183} INFO - Processing /opt/airflow/dags/bank_data_dag.py took 0.998 seconds
[2025-08-04T22:46:12.157+0000] {processor.py:161} INFO - Started process (PID=30) to work on /opt/airflow/dags/bank_data_dag.py
[2025-08-04T22:46:12.168+0000] {processor.py:830} INFO - Processing file /opt/airflow/dags/bank_data_dag.py for tasks to queue
[2025-08-04T22:46:12.293+0000] {logging_mixin.py:188} INFO - [2025-08-04T22:46:12.267+0000] {dagbag.py:538} INFO - Filling up the DagBag from /opt/airflow/dags/bank_data_dag.py
[2025-08-04T22:46:12.960+0000] {logging_mixin.py:188} INFO - [2025-08-04T22:46:12.890+0000] {dagbag.py:348} ERROR - Failed to import: /opt/airflow/dags/bank_data_dag.py
Traceback (most recent call last):
  File "/home/airflow/.local/lib/python3.9/site-packages/airflow/models/dagbag.py", line 344, in parse
    loader.exec_module(new_module)
  File "<frozen importlib._bootstrap_external>", line 850, in exec_module
  File "<frozen importlib._bootstrap>", line 228, in _call_with_frames_removed
  File "/opt/airflow/dags/bank_data_dag.py", line 15, in <module>
    generate_bank_data = DockerOperator(
  File "/home/airflow/.local/lib/python3.9/site-packages/airflow/models/baseoperator.py", line 437, in apply_defaults
    result = func(self, **kwargs, default_args=default_args)
  File "/home/airflow/.local/lib/python3.9/site-packages/airflow/providers/docker/operators/docker.py", line 265, in __init__
    super().__init__(**kwargs)
  File "/home/airflow/.local/lib/python3.9/site-packages/airflow/models/baseoperator.py", line 437, in apply_defaults
    result = func(self, **kwargs, default_args=default_args)
  File "/home/airflow/.local/lib/python3.9/site-packages/airflow/models/baseoperator.py", line 793, in __init__
    raise AirflowException(
airflow.exceptions.AirflowException: Invalid arguments were passed to DockerOperator (task_id: generate_bank_data). Invalid arguments were:
**kwargs: {'volumes': ['/your/local/path/to/arlequin/scripts:/scripts', '/your/local/path/to/arlequin/hadoop-base/hadoop-conf:/opt/hadoop/etc/hadoop']}
[2025-08-04T22:46:12.968+0000] {processor.py:842} WARNING - No viable dags retrieved from /opt/airflow/dags/bank_data_dag.py
[2025-08-04T22:46:14.224+0000] {processor.py:183} INFO - Processing /opt/airflow/dags/bank_data_dag.py took 2.248 seconds
[2025-08-04T22:46:45.253+0000] {processor.py:161} INFO - Started process (PID=31) to work on /opt/airflow/dags/bank_data_dag.py
[2025-08-04T22:46:45.315+0000] {processor.py:830} INFO - Processing file /opt/airflow/dags/bank_data_dag.py for tasks to queue
[2025-08-04T22:46:45.510+0000] {logging_mixin.py:188} INFO - [2025-08-04T22:46:45.355+0000] {dagbag.py:538} INFO - Filling up the DagBag from /opt/airflow/dags/bank_data_dag.py
[2025-08-04T22:46:45.545+0000] {logging_mixin.py:188} INFO - [2025-08-04T22:46:45.536+0000] {dagbag.py:348} ERROR - Failed to import: /opt/airflow/dags/bank_data_dag.py
Traceback (most recent call last):
  File "/home/airflow/.local/lib/python3.9/site-packages/airflow/models/dagbag.py", line 344, in parse
    loader.exec_module(new_module)
  File "<frozen importlib._bootstrap_external>", line 850, in exec_module
  File "<frozen importlib._bootstrap>", line 228, in _call_with_frames_removed
  File "/opt/airflow/dags/bank_data_dag.py", line 15, in <module>
    generate_bank_data = DockerOperator(
  File "/home/airflow/.local/lib/python3.9/site-packages/airflow/models/baseoperator.py", line 437, in apply_defaults
    result = func(self, **kwargs, default_args=default_args)
  File "/home/airflow/.local/lib/python3.9/site-packages/airflow/providers/docker/operators/docker.py", line 265, in __init__
    super().__init__(**kwargs)
  File "/home/airflow/.local/lib/python3.9/site-packages/airflow/models/baseoperator.py", line 437, in apply_defaults
    result = func(self, **kwargs, default_args=default_args)
  File "/home/airflow/.local/lib/python3.9/site-packages/airflow/models/baseoperator.py", line 793, in __init__
    raise AirflowException(
airflow.exceptions.AirflowException: Invalid arguments were passed to DockerOperator (task_id: generate_bank_data). Invalid arguments were:
**kwargs: {'volumes': ['/your/local/path/to/arlequin/scripts:/scripts', '/your/local/path/to/arlequin/hadoop-base/hadoop-conf:/opt/hadoop/etc/hadoop']}
[2025-08-04T22:46:45.546+0000] {processor.py:842} WARNING - No viable dags retrieved from /opt/airflow/dags/bank_data_dag.py
[2025-08-04T22:46:45.582+0000] {processor.py:183} INFO - Processing /opt/airflow/dags/bank_data_dag.py took 0.759 seconds
[2025-08-04T22:47:16.047+0000] {processor.py:161} INFO - Started process (PID=32) to work on /opt/airflow/dags/bank_data_dag.py
[2025-08-04T22:47:16.049+0000] {processor.py:830} INFO - Processing file /opt/airflow/dags/bank_data_dag.py for tasks to queue
[2025-08-04T22:47:16.054+0000] {logging_mixin.py:188} INFO - [2025-08-04T22:47:16.052+0000] {dagbag.py:538} INFO - Filling up the DagBag from /opt/airflow/dags/bank_data_dag.py
[2025-08-04T22:47:16.094+0000] {logging_mixin.py:188} INFO - [2025-08-04T22:47:16.085+0000] {dagbag.py:348} ERROR - Failed to import: /opt/airflow/dags/bank_data_dag.py
Traceback (most recent call last):
  File "/home/airflow/.local/lib/python3.9/site-packages/airflow/models/dagbag.py", line 344, in parse
    loader.exec_module(new_module)
  File "<frozen importlib._bootstrap_external>", line 850, in exec_module
  File "<frozen importlib._bootstrap>", line 228, in _call_with_frames_removed
  File "/opt/airflow/dags/bank_data_dag.py", line 15, in <module>
    generate_bank_data = DockerOperator(
  File "/home/airflow/.local/lib/python3.9/site-packages/airflow/models/baseoperator.py", line 437, in apply_defaults
    result = func(self, **kwargs, default_args=default_args)
  File "/home/airflow/.local/lib/python3.9/site-packages/airflow/providers/docker/operators/docker.py", line 265, in __init__
    super().__init__(**kwargs)
  File "/home/airflow/.local/lib/python3.9/site-packages/airflow/models/baseoperator.py", line 437, in apply_defaults
    result = func(self, **kwargs, default_args=default_args)
  File "/home/airflow/.local/lib/python3.9/site-packages/airflow/models/baseoperator.py", line 793, in __init__
    raise AirflowException(
airflow.exceptions.AirflowException: Invalid arguments were passed to DockerOperator (task_id: generate_bank_data). Invalid arguments were:
**kwargs: {'volumes': ['/your/local/path/to/arlequin/scripts:/scripts', '/your/local/path/to/arlequin/hadoop-base/hadoop-conf:/opt/hadoop/etc/hadoop']}
[2025-08-04T22:47:16.095+0000] {processor.py:842} WARNING - No viable dags retrieved from /opt/airflow/dags/bank_data_dag.py
[2025-08-04T22:47:16.133+0000] {processor.py:183} INFO - Processing /opt/airflow/dags/bank_data_dag.py took 0.093 seconds
[2025-08-04T22:47:46.323+0000] {processor.py:161} INFO - Started process (PID=33) to work on /opt/airflow/dags/bank_data_dag.py
[2025-08-04T22:47:46.325+0000] {processor.py:830} INFO - Processing file /opt/airflow/dags/bank_data_dag.py for tasks to queue
[2025-08-04T22:47:46.328+0000] {logging_mixin.py:188} INFO - [2025-08-04T22:47:46.327+0000] {dagbag.py:538} INFO - Filling up the DagBag from /opt/airflow/dags/bank_data_dag.py
[2025-08-04T22:47:46.364+0000] {logging_mixin.py:188} INFO - [2025-08-04T22:47:46.354+0000] {dagbag.py:348} ERROR - Failed to import: /opt/airflow/dags/bank_data_dag.py
Traceback (most recent call last):
  File "/home/airflow/.local/lib/python3.9/site-packages/airflow/models/dagbag.py", line 344, in parse
    loader.exec_module(new_module)
  File "<frozen importlib._bootstrap_external>", line 850, in exec_module
  File "<frozen importlib._bootstrap>", line 228, in _call_with_frames_removed
  File "/opt/airflow/dags/bank_data_dag.py", line 15, in <module>
    generate_bank_data = DockerOperator(
  File "/home/airflow/.local/lib/python3.9/site-packages/airflow/models/baseoperator.py", line 437, in apply_defaults
    result = func(self, **kwargs, default_args=default_args)
  File "/home/airflow/.local/lib/python3.9/site-packages/airflow/providers/docker/operators/docker.py", line 265, in __init__
    super().__init__(**kwargs)
  File "/home/airflow/.local/lib/python3.9/site-packages/airflow/models/baseoperator.py", line 437, in apply_defaults
    result = func(self, **kwargs, default_args=default_args)
  File "/home/airflow/.local/lib/python3.9/site-packages/airflow/models/baseoperator.py", line 793, in __init__
    raise AirflowException(
airflow.exceptions.AirflowException: Invalid arguments were passed to DockerOperator (task_id: generate_bank_data). Invalid arguments were:
**kwargs: {'volumes': ['/your/local/path/to/arlequin/scripts:/scripts', '/your/local/path/to/arlequin/hadoop-base/hadoop-conf:/opt/hadoop/etc/hadoop']}
[2025-08-04T22:47:46.366+0000] {processor.py:842} WARNING - No viable dags retrieved from /opt/airflow/dags/bank_data_dag.py
[2025-08-04T22:47:46.409+0000] {processor.py:183} INFO - Processing /opt/airflow/dags/bank_data_dag.py took 0.095 seconds
[2025-08-04T22:48:16.643+0000] {processor.py:161} INFO - Started process (PID=34) to work on /opt/airflow/dags/bank_data_dag.py
[2025-08-04T22:48:16.645+0000] {processor.py:830} INFO - Processing file /opt/airflow/dags/bank_data_dag.py for tasks to queue
[2025-08-04T22:48:16.650+0000] {logging_mixin.py:188} INFO - [2025-08-04T22:48:16.647+0000] {dagbag.py:538} INFO - Filling up the DagBag from /opt/airflow/dags/bank_data_dag.py
[2025-08-04T22:48:16.682+0000] {logging_mixin.py:188} INFO - [2025-08-04T22:48:16.672+0000] {dagbag.py:348} ERROR - Failed to import: /opt/airflow/dags/bank_data_dag.py
Traceback (most recent call last):
  File "/home/airflow/.local/lib/python3.9/site-packages/airflow/models/dagbag.py", line 344, in parse
    loader.exec_module(new_module)
  File "<frozen importlib._bootstrap_external>", line 850, in exec_module
  File "<frozen importlib._bootstrap>", line 228, in _call_with_frames_removed
  File "/opt/airflow/dags/bank_data_dag.py", line 15, in <module>
    generate_bank_data = DockerOperator(
  File "/home/airflow/.local/lib/python3.9/site-packages/airflow/models/baseoperator.py", line 437, in apply_defaults
    result = func(self, **kwargs, default_args=default_args)
  File "/home/airflow/.local/lib/python3.9/site-packages/airflow/providers/docker/operators/docker.py", line 265, in __init__
    super().__init__(**kwargs)
  File "/home/airflow/.local/lib/python3.9/site-packages/airflow/models/baseoperator.py", line 437, in apply_defaults
    result = func(self, **kwargs, default_args=default_args)
  File "/home/airflow/.local/lib/python3.9/site-packages/airflow/models/baseoperator.py", line 793, in __init__
    raise AirflowException(
airflow.exceptions.AirflowException: Invalid arguments were passed to DockerOperator (task_id: generate_bank_data). Invalid arguments were:
**kwargs: {'volumes': ['/your/local/path/to/arlequin/scripts:/scripts', '/your/local/path/to/arlequin/hadoop-base/hadoop-conf:/opt/hadoop/etc/hadoop']}
[2025-08-04T22:48:16.683+0000] {processor.py:842} WARNING - No viable dags retrieved from /opt/airflow/dags/bank_data_dag.py
[2025-08-04T22:48:16.719+0000] {processor.py:183} INFO - Processing /opt/airflow/dags/bank_data_dag.py took 0.082 seconds
[2025-08-04T22:48:46.873+0000] {processor.py:161} INFO - Started process (PID=35) to work on /opt/airflow/dags/bank_data_dag.py
[2025-08-04T22:48:46.875+0000] {processor.py:830} INFO - Processing file /opt/airflow/dags/bank_data_dag.py for tasks to queue
[2025-08-04T22:48:46.883+0000] {logging_mixin.py:188} INFO - [2025-08-04T22:48:46.881+0000] {dagbag.py:538} INFO - Filling up the DagBag from /opt/airflow/dags/bank_data_dag.py
[2025-08-04T22:48:46.925+0000] {logging_mixin.py:188} INFO - [2025-08-04T22:48:46.917+0000] {dagbag.py:348} ERROR - Failed to import: /opt/airflow/dags/bank_data_dag.py
Traceback (most recent call last):
  File "/home/airflow/.local/lib/python3.9/site-packages/airflow/models/dagbag.py", line 344, in parse
    loader.exec_module(new_module)
  File "<frozen importlib._bootstrap_external>", line 850, in exec_module
  File "<frozen importlib._bootstrap>", line 228, in _call_with_frames_removed
  File "/opt/airflow/dags/bank_data_dag.py", line 15, in <module>
    generate_bank_data = DockerOperator(
  File "/home/airflow/.local/lib/python3.9/site-packages/airflow/models/baseoperator.py", line 437, in apply_defaults
    result = func(self, **kwargs, default_args=default_args)
  File "/home/airflow/.local/lib/python3.9/site-packages/airflow/providers/docker/operators/docker.py", line 265, in __init__
    super().__init__(**kwargs)
  File "/home/airflow/.local/lib/python3.9/site-packages/airflow/models/baseoperator.py", line 437, in apply_defaults
    result = func(self, **kwargs, default_args=default_args)
  File "/home/airflow/.local/lib/python3.9/site-packages/airflow/models/baseoperator.py", line 793, in __init__
    raise AirflowException(
airflow.exceptions.AirflowException: Invalid arguments were passed to DockerOperator (task_id: generate_bank_data). Invalid arguments were:
**kwargs: {'volumes': ['/your/local/path/to/arlequin/scripts:/scripts', '/your/local/path/to/arlequin/hadoop-base/hadoop-conf:/opt/hadoop/etc/hadoop']}
[2025-08-04T22:48:46.925+0000] {processor.py:842} WARNING - No viable dags retrieved from /opt/airflow/dags/bank_data_dag.py
[2025-08-04T22:48:46.965+0000] {processor.py:183} INFO - Processing /opt/airflow/dags/bank_data_dag.py took 0.097 seconds
[2025-08-04T22:49:17.193+0000] {processor.py:161} INFO - Started process (PID=36) to work on /opt/airflow/dags/bank_data_dag.py
[2025-08-04T22:49:17.195+0000] {processor.py:830} INFO - Processing file /opt/airflow/dags/bank_data_dag.py for tasks to queue
[2025-08-04T22:49:17.202+0000] {logging_mixin.py:188} INFO - [2025-08-04T22:49:17.199+0000] {dagbag.py:538} INFO - Filling up the DagBag from /opt/airflow/dags/bank_data_dag.py
[2025-08-04T22:49:17.263+0000] {logging_mixin.py:188} INFO - [2025-08-04T22:49:17.253+0000] {dagbag.py:348} ERROR - Failed to import: /opt/airflow/dags/bank_data_dag.py
Traceback (most recent call last):
  File "/home/airflow/.local/lib/python3.9/site-packages/airflow/models/dagbag.py", line 344, in parse
    loader.exec_module(new_module)
  File "<frozen importlib._bootstrap_external>", line 850, in exec_module
  File "<frozen importlib._bootstrap>", line 228, in _call_with_frames_removed
  File "/opt/airflow/dags/bank_data_dag.py", line 15, in <module>
    generate_bank_data = DockerOperator(
  File "/home/airflow/.local/lib/python3.9/site-packages/airflow/models/baseoperator.py", line 437, in apply_defaults
    result = func(self, **kwargs, default_args=default_args)
  File "/home/airflow/.local/lib/python3.9/site-packages/airflow/providers/docker/operators/docker.py", line 265, in __init__
    super().__init__(**kwargs)
  File "/home/airflow/.local/lib/python3.9/site-packages/airflow/models/baseoperator.py", line 437, in apply_defaults
    result = func(self, **kwargs, default_args=default_args)
  File "/home/airflow/.local/lib/python3.9/site-packages/airflow/models/baseoperator.py", line 793, in __init__
    raise AirflowException(
airflow.exceptions.AirflowException: Invalid arguments were passed to DockerOperator (task_id: generate_bank_data). Invalid arguments were:
**kwargs: {'volumes': ['/your/local/path/to/arlequin/scripts:/scripts', '/your/local/path/to/arlequin/hadoop-base/hadoop-conf:/opt/hadoop/etc/hadoop']}
[2025-08-04T22:49:17.265+0000] {processor.py:842} WARNING - No viable dags retrieved from /opt/airflow/dags/bank_data_dag.py
[2025-08-04T22:49:17.311+0000] {processor.py:183} INFO - Processing /opt/airflow/dags/bank_data_dag.py took 0.125 seconds
[2025-08-04T22:49:47.434+0000] {processor.py:161} INFO - Started process (PID=37) to work on /opt/airflow/dags/bank_data_dag.py
[2025-08-04T22:49:47.435+0000] {processor.py:830} INFO - Processing file /opt/airflow/dags/bank_data_dag.py for tasks to queue
[2025-08-04T22:49:47.442+0000] {logging_mixin.py:188} INFO - [2025-08-04T22:49:47.438+0000] {dagbag.py:538} INFO - Filling up the DagBag from /opt/airflow/dags/bank_data_dag.py
[2025-08-04T22:49:47.490+0000] {logging_mixin.py:188} INFO - [2025-08-04T22:49:47.469+0000] {dagbag.py:348} ERROR - Failed to import: /opt/airflow/dags/bank_data_dag.py
Traceback (most recent call last):
  File "/home/airflow/.local/lib/python3.9/site-packages/airflow/models/dagbag.py", line 344, in parse
    loader.exec_module(new_module)
  File "<frozen importlib._bootstrap_external>", line 850, in exec_module
  File "<frozen importlib._bootstrap>", line 228, in _call_with_frames_removed
  File "/opt/airflow/dags/bank_data_dag.py", line 15, in <module>
    generate_bank_data = DockerOperator(
  File "/home/airflow/.local/lib/python3.9/site-packages/airflow/models/baseoperator.py", line 437, in apply_defaults
    result = func(self, **kwargs, default_args=default_args)
  File "/home/airflow/.local/lib/python3.9/site-packages/airflow/providers/docker/operators/docker.py", line 265, in __init__
    super().__init__(**kwargs)
  File "/home/airflow/.local/lib/python3.9/site-packages/airflow/models/baseoperator.py", line 437, in apply_defaults
    result = func(self, **kwargs, default_args=default_args)
  File "/home/airflow/.local/lib/python3.9/site-packages/airflow/models/baseoperator.py", line 793, in __init__
    raise AirflowException(
airflow.exceptions.AirflowException: Invalid arguments were passed to DockerOperator (task_id: generate_bank_data). Invalid arguments were:
**kwargs: {'volumes': ['/your/local/path/to/arlequin/scripts:/scripts', '/your/local/path/to/arlequin/hadoop-base/hadoop-conf:/opt/hadoop/etc/hadoop']}
[2025-08-04T22:49:47.491+0000] {processor.py:842} WARNING - No viable dags retrieved from /opt/airflow/dags/bank_data_dag.py
[2025-08-04T22:49:47.533+0000] {processor.py:183} INFO - Processing /opt/airflow/dags/bank_data_dag.py took 0.108 seconds
[2025-08-04T22:50:17.755+0000] {processor.py:161} INFO - Started process (PID=38) to work on /opt/airflow/dags/bank_data_dag.py
[2025-08-04T22:50:17.756+0000] {processor.py:830} INFO - Processing file /opt/airflow/dags/bank_data_dag.py for tasks to queue
[2025-08-04T22:50:17.759+0000] {logging_mixin.py:188} INFO - [2025-08-04T22:50:17.758+0000] {dagbag.py:538} INFO - Filling up the DagBag from /opt/airflow/dags/bank_data_dag.py
[2025-08-04T22:50:17.785+0000] {logging_mixin.py:188} INFO - [2025-08-04T22:50:17.775+0000] {dagbag.py:348} ERROR - Failed to import: /opt/airflow/dags/bank_data_dag.py
Traceback (most recent call last):
  File "/home/airflow/.local/lib/python3.9/site-packages/airflow/models/dagbag.py", line 344, in parse
    loader.exec_module(new_module)
  File "<frozen importlib._bootstrap_external>", line 850, in exec_module
  File "<frozen importlib._bootstrap>", line 228, in _call_with_frames_removed
  File "/opt/airflow/dags/bank_data_dag.py", line 15, in <module>
    generate_bank_data = DockerOperator(
  File "/home/airflow/.local/lib/python3.9/site-packages/airflow/models/baseoperator.py", line 437, in apply_defaults
    result = func(self, **kwargs, default_args=default_args)
  File "/home/airflow/.local/lib/python3.9/site-packages/airflow/providers/docker/operators/docker.py", line 265, in __init__
    super().__init__(**kwargs)
  File "/home/airflow/.local/lib/python3.9/site-packages/airflow/models/baseoperator.py", line 437, in apply_defaults
    result = func(self, **kwargs, default_args=default_args)
  File "/home/airflow/.local/lib/python3.9/site-packages/airflow/models/baseoperator.py", line 793, in __init__
    raise AirflowException(
airflow.exceptions.AirflowException: Invalid arguments were passed to DockerOperator (task_id: generate_bank_data). Invalid arguments were:
**kwargs: {'volumes': ['/your/local/path/to/arlequin/scripts:/scripts', '/your/local/path/to/arlequin/hadoop-base/hadoop-conf:/opt/hadoop/etc/hadoop']}
[2025-08-04T22:50:17.786+0000] {processor.py:842} WARNING - No viable dags retrieved from /opt/airflow/dags/bank_data_dag.py
[2025-08-04T22:50:17.819+0000] {processor.py:183} INFO - Processing /opt/airflow/dags/bank_data_dag.py took 0.070 seconds
[2025-08-04T22:50:48.741+0000] {processor.py:161} INFO - Started process (PID=39) to work on /opt/airflow/dags/bank_data_dag.py
[2025-08-04T22:50:48.747+0000] {processor.py:830} INFO - Processing file /opt/airflow/dags/bank_data_dag.py for tasks to queue
[2025-08-04T22:50:48.751+0000] {logging_mixin.py:188} INFO - [2025-08-04T22:50:48.750+0000] {dagbag.py:538} INFO - Filling up the DagBag from /opt/airflow/dags/bank_data_dag.py
[2025-08-04T22:50:48.783+0000] {logging_mixin.py:188} INFO - [2025-08-04T22:50:48.772+0000] {dagbag.py:348} ERROR - Failed to import: /opt/airflow/dags/bank_data_dag.py
Traceback (most recent call last):
  File "/home/airflow/.local/lib/python3.9/site-packages/airflow/models/dagbag.py", line 344, in parse
    loader.exec_module(new_module)
  File "<frozen importlib._bootstrap_external>", line 850, in exec_module
  File "<frozen importlib._bootstrap>", line 228, in _call_with_frames_removed
  File "/opt/airflow/dags/bank_data_dag.py", line 15, in <module>
    generate_bank_data = DockerOperator(
  File "/home/airflow/.local/lib/python3.9/site-packages/airflow/models/baseoperator.py", line 437, in apply_defaults
    result = func(self, **kwargs, default_args=default_args)
  File "/home/airflow/.local/lib/python3.9/site-packages/airflow/providers/docker/operators/docker.py", line 265, in __init__
    super().__init__(**kwargs)
  File "/home/airflow/.local/lib/python3.9/site-packages/airflow/models/baseoperator.py", line 437, in apply_defaults
    result = func(self, **kwargs, default_args=default_args)
  File "/home/airflow/.local/lib/python3.9/site-packages/airflow/models/baseoperator.py", line 793, in __init__
    raise AirflowException(
airflow.exceptions.AirflowException: Invalid arguments were passed to DockerOperator (task_id: generate_bank_data). Invalid arguments were:
**kwargs: {'volumes': ['/your/local/path/to/arlequin/scripts:/scripts', '/your/local/path/to/arlequin/hadoop-base/hadoop-conf:/opt/hadoop/etc/hadoop']}
[2025-08-04T22:50:48.784+0000] {processor.py:842} WARNING - No viable dags retrieved from /opt/airflow/dags/bank_data_dag.py
[2025-08-04T22:50:48.828+0000] {processor.py:183} INFO - Processing /opt/airflow/dags/bank_data_dag.py took 0.092 seconds
[2025-08-04T22:51:19.088+0000] {processor.py:161} INFO - Started process (PID=40) to work on /opt/airflow/dags/bank_data_dag.py
[2025-08-04T22:51:19.090+0000] {processor.py:830} INFO - Processing file /opt/airflow/dags/bank_data_dag.py for tasks to queue
[2025-08-04T22:51:19.099+0000] {logging_mixin.py:188} INFO - [2025-08-04T22:51:19.093+0000] {dagbag.py:538} INFO - Filling up the DagBag from /opt/airflow/dags/bank_data_dag.py
[2025-08-04T22:51:19.139+0000] {logging_mixin.py:188} INFO - [2025-08-04T22:51:19.129+0000] {dagbag.py:348} ERROR - Failed to import: /opt/airflow/dags/bank_data_dag.py
Traceback (most recent call last):
  File "/home/airflow/.local/lib/python3.9/site-packages/airflow/models/dagbag.py", line 344, in parse
    loader.exec_module(new_module)
  File "<frozen importlib._bootstrap_external>", line 850, in exec_module
  File "<frozen importlib._bootstrap>", line 228, in _call_with_frames_removed
  File "/opt/airflow/dags/bank_data_dag.py", line 15, in <module>
    generate_bank_data = DockerOperator(
  File "/home/airflow/.local/lib/python3.9/site-packages/airflow/models/baseoperator.py", line 437, in apply_defaults
    result = func(self, **kwargs, default_args=default_args)
  File "/home/airflow/.local/lib/python3.9/site-packages/airflow/providers/docker/operators/docker.py", line 265, in __init__
    super().__init__(**kwargs)
  File "/home/airflow/.local/lib/python3.9/site-packages/airflow/models/baseoperator.py", line 437, in apply_defaults
    result = func(self, **kwargs, default_args=default_args)
  File "/home/airflow/.local/lib/python3.9/site-packages/airflow/models/baseoperator.py", line 793, in __init__
    raise AirflowException(
airflow.exceptions.AirflowException: Invalid arguments were passed to DockerOperator (task_id: generate_bank_data). Invalid arguments were:
**kwargs: {'volumes': ['/your/local/path/to/arlequin/scripts:/scripts', '/your/local/path/to/arlequin/hadoop-base/hadoop-conf:/opt/hadoop/etc/hadoop']}
[2025-08-04T22:51:19.140+0000] {processor.py:842} WARNING - No viable dags retrieved from /opt/airflow/dags/bank_data_dag.py
[2025-08-04T22:51:19.173+0000] {processor.py:183} INFO - Processing /opt/airflow/dags/bank_data_dag.py took 0.093 seconds
[2025-08-04T22:51:49.389+0000] {processor.py:161} INFO - Started process (PID=41) to work on /opt/airflow/dags/bank_data_dag.py
[2025-08-04T22:51:49.391+0000] {processor.py:830} INFO - Processing file /opt/airflow/dags/bank_data_dag.py for tasks to queue
[2025-08-04T22:51:49.396+0000] {logging_mixin.py:188} INFO - [2025-08-04T22:51:49.393+0000] {dagbag.py:538} INFO - Filling up the DagBag from /opt/airflow/dags/bank_data_dag.py
[2025-08-04T22:51:49.472+0000] {logging_mixin.py:188} INFO - [2025-08-04T22:51:49.449+0000] {dagbag.py:348} ERROR - Failed to import: /opt/airflow/dags/bank_data_dag.py
Traceback (most recent call last):
  File "/home/airflow/.local/lib/python3.9/site-packages/airflow/models/dagbag.py", line 344, in parse
    loader.exec_module(new_module)
  File "<frozen importlib._bootstrap_external>", line 850, in exec_module
  File "<frozen importlib._bootstrap>", line 228, in _call_with_frames_removed
  File "/opt/airflow/dags/bank_data_dag.py", line 15, in <module>
    generate_bank_data = DockerOperator(
  File "/home/airflow/.local/lib/python3.9/site-packages/airflow/models/baseoperator.py", line 437, in apply_defaults
    result = func(self, **kwargs, default_args=default_args)
  File "/home/airflow/.local/lib/python3.9/site-packages/airflow/providers/docker/operators/docker.py", line 265, in __init__
    super().__init__(**kwargs)
  File "/home/airflow/.local/lib/python3.9/site-packages/airflow/models/baseoperator.py", line 437, in apply_defaults
    result = func(self, **kwargs, default_args=default_args)
  File "/home/airflow/.local/lib/python3.9/site-packages/airflow/models/baseoperator.py", line 793, in __init__
    raise AirflowException(
airflow.exceptions.AirflowException: Invalid arguments were passed to DockerOperator (task_id: generate_bank_data). Invalid arguments were:
**kwargs: {'volumes': ['/your/local/path/to/arlequin/scripts:/scripts', '/your/local/path/to/arlequin/hadoop-base/hadoop-conf:/opt/hadoop/etc/hadoop']}
[2025-08-04T22:51:49.474+0000] {processor.py:842} WARNING - No viable dags retrieved from /opt/airflow/dags/bank_data_dag.py
[2025-08-04T22:51:49.554+0000] {processor.py:183} INFO - Processing /opt/airflow/dags/bank_data_dag.py took 0.177 seconds
[2025-08-04T22:52:20.183+0000] {processor.py:161} INFO - Started process (PID=42) to work on /opt/airflow/dags/bank_data_dag.py
[2025-08-04T22:52:20.210+0000] {processor.py:830} INFO - Processing file /opt/airflow/dags/bank_data_dag.py for tasks to queue
[2025-08-04T22:52:20.278+0000] {logging_mixin.py:188} INFO - [2025-08-04T22:52:20.269+0000] {dagbag.py:538} INFO - Filling up the DagBag from /opt/airflow/dags/bank_data_dag.py
[2025-08-04T22:52:20.458+0000] {logging_mixin.py:188} INFO - [2025-08-04T22:52:20.428+0000] {dagbag.py:348} ERROR - Failed to import: /opt/airflow/dags/bank_data_dag.py
Traceback (most recent call last):
  File "/home/airflow/.local/lib/python3.9/site-packages/airflow/models/dagbag.py", line 344, in parse
    loader.exec_module(new_module)
  File "<frozen importlib._bootstrap_external>", line 850, in exec_module
  File "<frozen importlib._bootstrap>", line 228, in _call_with_frames_removed
  File "/opt/airflow/dags/bank_data_dag.py", line 15, in <module>
    generate_bank_data = DockerOperator(
  File "/home/airflow/.local/lib/python3.9/site-packages/airflow/models/baseoperator.py", line 437, in apply_defaults
    result = func(self, **kwargs, default_args=default_args)
  File "/home/airflow/.local/lib/python3.9/site-packages/airflow/providers/docker/operators/docker.py", line 265, in __init__
    super().__init__(**kwargs)
  File "/home/airflow/.local/lib/python3.9/site-packages/airflow/models/baseoperator.py", line 437, in apply_defaults
    result = func(self, **kwargs, default_args=default_args)
  File "/home/airflow/.local/lib/python3.9/site-packages/airflow/models/baseoperator.py", line 793, in __init__
    raise AirflowException(
airflow.exceptions.AirflowException: Invalid arguments were passed to DockerOperator (task_id: generate_bank_data). Invalid arguments were:
**kwargs: {'volumes': ['/your/local/path/to/arlequin/scripts:/scripts', '/your/local/path/to/arlequin/hadoop-base/hadoop-conf:/opt/hadoop/etc/hadoop']}
[2025-08-04T22:52:20.461+0000] {processor.py:842} WARNING - No viable dags retrieved from /opt/airflow/dags/bank_data_dag.py
[2025-08-04T22:52:20.683+0000] {processor.py:183} INFO - Processing /opt/airflow/dags/bank_data_dag.py took 0.537 seconds
[2025-08-04T22:59:05.050+0000] {processor.py:161} INFO - Started process (PID=29) to work on /opt/airflow/dags/bank_data_dag.py
[2025-08-04T22:59:05.055+0000] {processor.py:830} INFO - Processing file /opt/airflow/dags/bank_data_dag.py for tasks to queue
[2025-08-04T22:59:05.065+0000] {logging_mixin.py:188} INFO - [2025-08-04T22:59:05.063+0000] {dagbag.py:538} INFO - Filling up the DagBag from /opt/airflow/dags/bank_data_dag.py
[2025-08-04T22:59:05.196+0000] {logging_mixin.py:188} INFO - [2025-08-04T22:59:05.164+0000] {dagbag.py:348} ERROR - Failed to import: /opt/airflow/dags/bank_data_dag.py
Traceback (most recent call last):
  File "/home/airflow/.local/lib/python3.9/site-packages/airflow/models/dagbag.py", line 344, in parse
    loader.exec_module(new_module)
  File "<frozen importlib._bootstrap_external>", line 850, in exec_module
  File "<frozen importlib._bootstrap>", line 228, in _call_with_frames_removed
  File "/opt/airflow/dags/bank_data_dag.py", line 15, in <module>
    generate_bank_data = DockerOperator(
  File "/home/airflow/.local/lib/python3.9/site-packages/airflow/models/baseoperator.py", line 437, in apply_defaults
    result = func(self, **kwargs, default_args=default_args)
  File "/home/airflow/.local/lib/python3.9/site-packages/airflow/providers/docker/operators/docker.py", line 265, in __init__
    super().__init__(**kwargs)
  File "/home/airflow/.local/lib/python3.9/site-packages/airflow/models/baseoperator.py", line 437, in apply_defaults
    result = func(self, **kwargs, default_args=default_args)
  File "/home/airflow/.local/lib/python3.9/site-packages/airflow/models/baseoperator.py", line 793, in __init__
    raise AirflowException(
airflow.exceptions.AirflowException: Invalid arguments were passed to DockerOperator (task_id: generate_bank_data). Invalid arguments were:
**kwargs: {'volumes': ['/your/local/path/to/arlequin/scripts:/scripts', '/your/local/path/to/arlequin/hadoop-base/hadoop-conf:/opt/hadoop/etc/hadoop']}
[2025-08-04T22:59:05.198+0000] {processor.py:842} WARNING - No viable dags retrieved from /opt/airflow/dags/bank_data_dag.py
[2025-08-04T22:59:05.285+0000] {processor.py:183} INFO - Processing /opt/airflow/dags/bank_data_dag.py took 0.240 seconds
[2025-08-04T22:59:36.681+0000] {processor.py:161} INFO - Started process (PID=30) to work on /opt/airflow/dags/bank_data_dag.py
[2025-08-04T22:59:36.685+0000] {processor.py:830} INFO - Processing file /opt/airflow/dags/bank_data_dag.py for tasks to queue
[2025-08-04T22:59:36.696+0000] {logging_mixin.py:188} INFO - [2025-08-04T22:59:36.694+0000] {dagbag.py:538} INFO - Filling up the DagBag from /opt/airflow/dags/bank_data_dag.py
[2025-08-04T22:59:37.672+0000] {logging_mixin.py:188} INFO - [2025-08-04T22:59:37.642+0000] {dagbag.py:348} ERROR - Failed to import: /opt/airflow/dags/bank_data_dag.py
Traceback (most recent call last):
  File "/home/airflow/.local/lib/python3.9/site-packages/airflow/models/dagbag.py", line 344, in parse
    loader.exec_module(new_module)
  File "<frozen importlib._bootstrap_external>", line 850, in exec_module
  File "<frozen importlib._bootstrap>", line 228, in _call_with_frames_removed
  File "/opt/airflow/dags/bank_data_dag.py", line 15, in <module>
    generate_bank_data = DockerOperator(
  File "/home/airflow/.local/lib/python3.9/site-packages/airflow/models/baseoperator.py", line 437, in apply_defaults
    result = func(self, **kwargs, default_args=default_args)
  File "/home/airflow/.local/lib/python3.9/site-packages/airflow/providers/docker/operators/docker.py", line 265, in __init__
    super().__init__(**kwargs)
  File "/home/airflow/.local/lib/python3.9/site-packages/airflow/models/baseoperator.py", line 437, in apply_defaults
    result = func(self, **kwargs, default_args=default_args)
  File "/home/airflow/.local/lib/python3.9/site-packages/airflow/models/baseoperator.py", line 793, in __init__
    raise AirflowException(
airflow.exceptions.AirflowException: Invalid arguments were passed to DockerOperator (task_id: generate_bank_data). Invalid arguments were:
**kwargs: {'volumes': ['/your/local/path/to/arlequin/scripts:/scripts', '/your/local/path/to/arlequin/hadoop-base/hadoop-conf:/opt/hadoop/etc/hadoop']}
[2025-08-04T22:59:37.684+0000] {processor.py:842} WARNING - No viable dags retrieved from /opt/airflow/dags/bank_data_dag.py
[2025-08-04T22:59:37.932+0000] {processor.py:183} INFO - Processing /opt/airflow/dags/bank_data_dag.py took 1.286 seconds
[2025-08-04T23:00:08.187+0000] {processor.py:161} INFO - Started process (PID=31) to work on /opt/airflow/dags/bank_data_dag.py
[2025-08-04T23:00:08.189+0000] {processor.py:830} INFO - Processing file /opt/airflow/dags/bank_data_dag.py for tasks to queue
[2025-08-04T23:00:08.199+0000] {logging_mixin.py:188} INFO - [2025-08-04T23:00:08.196+0000] {dagbag.py:538} INFO - Filling up the DagBag from /opt/airflow/dags/bank_data_dag.py
[2025-08-04T23:00:08.261+0000] {logging_mixin.py:188} INFO - [2025-08-04T23:00:08.236+0000] {dagbag.py:348} ERROR - Failed to import: /opt/airflow/dags/bank_data_dag.py
Traceback (most recent call last):
  File "/home/airflow/.local/lib/python3.9/site-packages/airflow/models/dagbag.py", line 344, in parse
    loader.exec_module(new_module)
  File "<frozen importlib._bootstrap_external>", line 850, in exec_module
  File "<frozen importlib._bootstrap>", line 228, in _call_with_frames_removed
  File "/opt/airflow/dags/bank_data_dag.py", line 15, in <module>
    generate_bank_data = DockerOperator(
  File "/home/airflow/.local/lib/python3.9/site-packages/airflow/models/baseoperator.py", line 437, in apply_defaults
    result = func(self, **kwargs, default_args=default_args)
  File "/home/airflow/.local/lib/python3.9/site-packages/airflow/providers/docker/operators/docker.py", line 265, in __init__
    super().__init__(**kwargs)
  File "/home/airflow/.local/lib/python3.9/site-packages/airflow/models/baseoperator.py", line 437, in apply_defaults
    result = func(self, **kwargs, default_args=default_args)
  File "/home/airflow/.local/lib/python3.9/site-packages/airflow/models/baseoperator.py", line 793, in __init__
    raise AirflowException(
airflow.exceptions.AirflowException: Invalid arguments were passed to DockerOperator (task_id: generate_bank_data). Invalid arguments were:
**kwargs: {'volumes': ['/your/local/path/to/arlequin/scripts:/scripts', '/your/local/path/to/arlequin/hadoop-base/hadoop-conf:/opt/hadoop/etc/hadoop']}
[2025-08-04T23:00:08.262+0000] {processor.py:842} WARNING - No viable dags retrieved from /opt/airflow/dags/bank_data_dag.py
[2025-08-04T23:00:08.366+0000] {processor.py:183} INFO - Processing /opt/airflow/dags/bank_data_dag.py took 0.188 seconds
[2025-08-04T23:00:41.613+0000] {processor.py:161} INFO - Started process (PID=32) to work on /opt/airflow/dags/bank_data_dag.py
[2025-08-04T23:00:41.835+0000] {processor.py:830} INFO - Processing file /opt/airflow/dags/bank_data_dag.py for tasks to queue
[2025-08-04T23:00:41.877+0000] {logging_mixin.py:188} INFO - [2025-08-04T23:00:41.859+0000] {dagbag.py:538} INFO - Filling up the DagBag from /opt/airflow/dags/bank_data_dag.py
[2025-08-04T23:00:42.011+0000] {logging_mixin.py:188} INFO - [2025-08-04T23:00:41.995+0000] {dagbag.py:348} ERROR - Failed to import: /opt/airflow/dags/bank_data_dag.py
Traceback (most recent call last):
  File "/home/airflow/.local/lib/python3.9/site-packages/airflow/models/dagbag.py", line 344, in parse
    loader.exec_module(new_module)
  File "<frozen importlib._bootstrap_external>", line 850, in exec_module
  File "<frozen importlib._bootstrap>", line 228, in _call_with_frames_removed
  File "/opt/airflow/dags/bank_data_dag.py", line 15, in <module>
    generate_bank_data = DockerOperator(
  File "/home/airflow/.local/lib/python3.9/site-packages/airflow/models/baseoperator.py", line 437, in apply_defaults
    result = func(self, **kwargs, default_args=default_args)
  File "/home/airflow/.local/lib/python3.9/site-packages/airflow/providers/docker/operators/docker.py", line 265, in __init__
    super().__init__(**kwargs)
  File "/home/airflow/.local/lib/python3.9/site-packages/airflow/models/baseoperator.py", line 437, in apply_defaults
    result = func(self, **kwargs, default_args=default_args)
  File "/home/airflow/.local/lib/python3.9/site-packages/airflow/models/baseoperator.py", line 793, in __init__
    raise AirflowException(
airflow.exceptions.AirflowException: Invalid arguments were passed to DockerOperator (task_id: generate_bank_data). Invalid arguments were:
**kwargs: {'volumes': ['/your/local/path/to/arlequin/scripts:/scripts', '/your/local/path/to/arlequin/hadoop-base/hadoop-conf:/opt/hadoop/etc/hadoop']}
[2025-08-04T23:00:42.012+0000] {processor.py:842} WARNING - No viable dags retrieved from /opt/airflow/dags/bank_data_dag.py
[2025-08-04T23:00:42.074+0000] {processor.py:183} INFO - Processing /opt/airflow/dags/bank_data_dag.py took 2.942 seconds
[2025-08-04T23:01:12.226+0000] {processor.py:161} INFO - Started process (PID=33) to work on /opt/airflow/dags/bank_data_dag.py
[2025-08-04T23:01:12.228+0000] {processor.py:830} INFO - Processing file /opt/airflow/dags/bank_data_dag.py for tasks to queue
[2025-08-04T23:01:12.231+0000] {logging_mixin.py:188} INFO - [2025-08-04T23:01:12.230+0000] {dagbag.py:538} INFO - Filling up the DagBag from /opt/airflow/dags/bank_data_dag.py
[2025-08-04T23:01:12.261+0000] {logging_mixin.py:188} INFO - [2025-08-04T23:01:12.256+0000] {dagbag.py:348} ERROR - Failed to import: /opt/airflow/dags/bank_data_dag.py
Traceback (most recent call last):
  File "/home/airflow/.local/lib/python3.9/site-packages/airflow/models/dagbag.py", line 344, in parse
    loader.exec_module(new_module)
  File "<frozen importlib._bootstrap_external>", line 850, in exec_module
  File "<frozen importlib._bootstrap>", line 228, in _call_with_frames_removed
  File "/opt/airflow/dags/bank_data_dag.py", line 15, in <module>
    generate_bank_data = DockerOperator(
  File "/home/airflow/.local/lib/python3.9/site-packages/airflow/models/baseoperator.py", line 437, in apply_defaults
    result = func(self, **kwargs, default_args=default_args)
  File "/home/airflow/.local/lib/python3.9/site-packages/airflow/providers/docker/operators/docker.py", line 265, in __init__
    super().__init__(**kwargs)
  File "/home/airflow/.local/lib/python3.9/site-packages/airflow/models/baseoperator.py", line 437, in apply_defaults
    result = func(self, **kwargs, default_args=default_args)
  File "/home/airflow/.local/lib/python3.9/site-packages/airflow/models/baseoperator.py", line 793, in __init__
    raise AirflowException(
airflow.exceptions.AirflowException: Invalid arguments were passed to DockerOperator (task_id: generate_bank_data). Invalid arguments were:
**kwargs: {'volumes': ['/your/local/path/to/arlequin/scripts:/scripts', '/your/local/path/to/arlequin/hadoop-base/hadoop-conf:/opt/hadoop/etc/hadoop']}
[2025-08-04T23:01:12.263+0000] {processor.py:842} WARNING - No viable dags retrieved from /opt/airflow/dags/bank_data_dag.py
[2025-08-04T23:01:12.302+0000] {processor.py:183} INFO - Processing /opt/airflow/dags/bank_data_dag.py took 0.080 seconds
[2025-08-04T23:01:42.461+0000] {processor.py:161} INFO - Started process (PID=34) to work on /opt/airflow/dags/bank_data_dag.py
[2025-08-04T23:01:42.463+0000] {processor.py:830} INFO - Processing file /opt/airflow/dags/bank_data_dag.py for tasks to queue
[2025-08-04T23:01:42.465+0000] {logging_mixin.py:188} INFO - [2025-08-04T23:01:42.465+0000] {dagbag.py:538} INFO - Filling up the DagBag from /opt/airflow/dags/bank_data_dag.py
[2025-08-04T23:01:42.506+0000] {logging_mixin.py:188} INFO - [2025-08-04T23:01:42.495+0000] {dagbag.py:348} ERROR - Failed to import: /opt/airflow/dags/bank_data_dag.py
Traceback (most recent call last):
  File "/home/airflow/.local/lib/python3.9/site-packages/airflow/models/dagbag.py", line 344, in parse
    loader.exec_module(new_module)
  File "<frozen importlib._bootstrap_external>", line 850, in exec_module
  File "<frozen importlib._bootstrap>", line 228, in _call_with_frames_removed
  File "/opt/airflow/dags/bank_data_dag.py", line 15, in <module>
    generate_bank_data = DockerOperator(
  File "/home/airflow/.local/lib/python3.9/site-packages/airflow/models/baseoperator.py", line 437, in apply_defaults
    result = func(self, **kwargs, default_args=default_args)
  File "/home/airflow/.local/lib/python3.9/site-packages/airflow/providers/docker/operators/docker.py", line 265, in __init__
    super().__init__(**kwargs)
  File "/home/airflow/.local/lib/python3.9/site-packages/airflow/models/baseoperator.py", line 437, in apply_defaults
    result = func(self, **kwargs, default_args=default_args)
  File "/home/airflow/.local/lib/python3.9/site-packages/airflow/models/baseoperator.py", line 793, in __init__
    raise AirflowException(
airflow.exceptions.AirflowException: Invalid arguments were passed to DockerOperator (task_id: generate_bank_data). Invalid arguments were:
**kwargs: {'volumes': ['/your/local/path/to/arlequin/scripts:/scripts', '/your/local/path/to/arlequin/hadoop-base/hadoop-conf:/opt/hadoop/etc/hadoop']}
[2025-08-04T23:01:42.507+0000] {processor.py:842} WARNING - No viable dags retrieved from /opt/airflow/dags/bank_data_dag.py
[2025-08-04T23:01:42.540+0000] {processor.py:183} INFO - Processing /opt/airflow/dags/bank_data_dag.py took 0.081 seconds
[2025-08-04T23:02:13.825+0000] {processor.py:161} INFO - Started process (PID=35) to work on /opt/airflow/dags/bank_data_dag.py
[2025-08-04T23:02:13.978+0000] {processor.py:830} INFO - Processing file /opt/airflow/dags/bank_data_dag.py for tasks to queue
[2025-08-04T23:02:14.094+0000] {logging_mixin.py:188} INFO - [2025-08-04T23:02:14.064+0000] {dagbag.py:538} INFO - Filling up the DagBag from /opt/airflow/dags/bank_data_dag.py
[2025-08-04T23:02:15.028+0000] {logging_mixin.py:188} INFO - [2025-08-04T23:02:14.686+0000] {dagbag.py:348} ERROR - Failed to import: /opt/airflow/dags/bank_data_dag.py
Traceback (most recent call last):
  File "/home/airflow/.local/lib/python3.9/site-packages/airflow/models/dagbag.py", line 344, in parse
    loader.exec_module(new_module)
  File "<frozen importlib._bootstrap_external>", line 850, in exec_module
  File "<frozen importlib._bootstrap>", line 228, in _call_with_frames_removed
  File "/opt/airflow/dags/bank_data_dag.py", line 15, in <module>
    generate_bank_data = DockerOperator(
  File "/home/airflow/.local/lib/python3.9/site-packages/airflow/models/baseoperator.py", line 437, in apply_defaults
    result = func(self, **kwargs, default_args=default_args)
  File "/home/airflow/.local/lib/python3.9/site-packages/airflow/providers/docker/operators/docker.py", line 265, in __init__
    super().__init__(**kwargs)
  File "/home/airflow/.local/lib/python3.9/site-packages/airflow/models/baseoperator.py", line 437, in apply_defaults
    result = func(self, **kwargs, default_args=default_args)
  File "/home/airflow/.local/lib/python3.9/site-packages/airflow/models/baseoperator.py", line 793, in __init__
    raise AirflowException(
airflow.exceptions.AirflowException: Invalid arguments were passed to DockerOperator (task_id: generate_bank_data). Invalid arguments were:
**kwargs: {'volumes': ['/your/local/path/to/arlequin/scripts:/scripts', '/your/local/path/to/arlequin/hadoop-base/hadoop-conf:/opt/hadoop/etc/hadoop']}
[2025-08-04T23:02:15.030+0000] {processor.py:842} WARNING - No viable dags retrieved from /opt/airflow/dags/bank_data_dag.py
[2025-08-04T23:02:15.639+0000] {processor.py:183} INFO - Processing /opt/airflow/dags/bank_data_dag.py took 2.480 seconds
[2025-08-04T23:18:03.973+0000] {processor.py:161} INFO - Started process (PID=29) to work on /opt/airflow/dags/bank_data_dag.py
[2025-08-04T23:18:03.988+0000] {processor.py:830} INFO - Processing file /opt/airflow/dags/bank_data_dag.py for tasks to queue
[2025-08-04T23:18:04.008+0000] {logging_mixin.py:188} INFO - [2025-08-04T23:18:04.004+0000] {dagbag.py:538} INFO - Filling up the DagBag from /opt/airflow/dags/bank_data_dag.py
[2025-08-04T23:18:04.175+0000] {logging_mixin.py:188} INFO - [2025-08-04T23:18:04.141+0000] {dagbag.py:348} ERROR - Failed to import: /opt/airflow/dags/bank_data_dag.py
Traceback (most recent call last):
  File "/home/airflow/.local/lib/python3.9/site-packages/airflow/models/dagbag.py", line 344, in parse
    loader.exec_module(new_module)
  File "<frozen importlib._bootstrap_external>", line 850, in exec_module
  File "<frozen importlib._bootstrap>", line 228, in _call_with_frames_removed
  File "/opt/airflow/dags/bank_data_dag.py", line 15, in <module>
    generate_bank_data = DockerOperator(
  File "/home/airflow/.local/lib/python3.9/site-packages/airflow/models/baseoperator.py", line 437, in apply_defaults
    result = func(self, **kwargs, default_args=default_args)
  File "/home/airflow/.local/lib/python3.9/site-packages/airflow/providers/docker/operators/docker.py", line 265, in __init__
    super().__init__(**kwargs)
  File "/home/airflow/.local/lib/python3.9/site-packages/airflow/models/baseoperator.py", line 437, in apply_defaults
    result = func(self, **kwargs, default_args=default_args)
  File "/home/airflow/.local/lib/python3.9/site-packages/airflow/models/baseoperator.py", line 793, in __init__
    raise AirflowException(
airflow.exceptions.AirflowException: Invalid arguments were passed to DockerOperator (task_id: generate_bank_data). Invalid arguments were:
**kwargs: {'volumes': ['/your/local/path/to/arlequin/scripts:/scripts', '/your/local/path/to/arlequin/hadoop-base/hadoop-conf:/opt/hadoop/etc/hadoop']}
[2025-08-04T23:18:04.176+0000] {processor.py:842} WARNING - No viable dags retrieved from /opt/airflow/dags/bank_data_dag.py
[2025-08-04T23:18:04.305+0000] {processor.py:183} INFO - Processing /opt/airflow/dags/bank_data_dag.py took 0.395 seconds
[2025-08-04T23:18:36.586+0000] {processor.py:161} INFO - Started process (PID=30) to work on /opt/airflow/dags/bank_data_dag.py
[2025-08-04T23:18:36.613+0000] {processor.py:830} INFO - Processing file /opt/airflow/dags/bank_data_dag.py for tasks to queue
[2025-08-04T23:18:36.644+0000] {logging_mixin.py:188} INFO - [2025-08-04T23:18:36.642+0000] {dagbag.py:538} INFO - Filling up the DagBag from /opt/airflow/dags/bank_data_dag.py
[2025-08-04T23:18:36.756+0000] {logging_mixin.py:188} INFO - [2025-08-04T23:18:36.736+0000] {dagbag.py:348} ERROR - Failed to import: /opt/airflow/dags/bank_data_dag.py
Traceback (most recent call last):
  File "/home/airflow/.local/lib/python3.9/site-packages/airflow/models/dagbag.py", line 344, in parse
    loader.exec_module(new_module)
  File "<frozen importlib._bootstrap_external>", line 850, in exec_module
  File "<frozen importlib._bootstrap>", line 228, in _call_with_frames_removed
  File "/opt/airflow/dags/bank_data_dag.py", line 15, in <module>
    generate_bank_data = DockerOperator(
  File "/home/airflow/.local/lib/python3.9/site-packages/airflow/models/baseoperator.py", line 437, in apply_defaults
    result = func(self, **kwargs, default_args=default_args)
  File "/home/airflow/.local/lib/python3.9/site-packages/airflow/providers/docker/operators/docker.py", line 265, in __init__
    super().__init__(**kwargs)
  File "/home/airflow/.local/lib/python3.9/site-packages/airflow/models/baseoperator.py", line 437, in apply_defaults
    result = func(self, **kwargs, default_args=default_args)
  File "/home/airflow/.local/lib/python3.9/site-packages/airflow/models/baseoperator.py", line 793, in __init__
    raise AirflowException(
airflow.exceptions.AirflowException: Invalid arguments were passed to DockerOperator (task_id: generate_bank_data). Invalid arguments were:
**kwargs: {'volumes': ['/your/local/path/to/arlequin/scripts:/scripts', '/your/local/path/to/arlequin/hadoop-base/hadoop-conf:/opt/hadoop/etc/hadoop']}
[2025-08-04T23:18:36.757+0000] {processor.py:842} WARNING - No viable dags retrieved from /opt/airflow/dags/bank_data_dag.py
[2025-08-04T23:18:36.907+0000] {processor.py:183} INFO - Processing /opt/airflow/dags/bank_data_dag.py took 0.525 seconds
[2025-08-04T23:19:08.021+0000] {processor.py:161} INFO - Started process (PID=31) to work on /opt/airflow/dags/bank_data_dag.py
[2025-08-04T23:19:08.023+0000] {processor.py:830} INFO - Processing file /opt/airflow/dags/bank_data_dag.py for tasks to queue
[2025-08-04T23:19:08.124+0000] {logging_mixin.py:188} INFO - [2025-08-04T23:19:08.124+0000] {dagbag.py:538} INFO - Filling up the DagBag from /opt/airflow/dags/bank_data_dag.py
[2025-08-04T23:19:09.551+0000] {logging_mixin.py:188} INFO - [2025-08-04T23:19:09.110+0000] {dagbag.py:348} ERROR - Failed to import: /opt/airflow/dags/bank_data_dag.py
Traceback (most recent call last):
  File "/home/airflow/.local/lib/python3.9/site-packages/airflow/models/dagbag.py", line 344, in parse
    loader.exec_module(new_module)
  File "<frozen importlib._bootstrap_external>", line 850, in exec_module
  File "<frozen importlib._bootstrap>", line 228, in _call_with_frames_removed
  File "/opt/airflow/dags/bank_data_dag.py", line 15, in <module>
    generate_bank_data = DockerOperator(
  File "/home/airflow/.local/lib/python3.9/site-packages/airflow/models/baseoperator.py", line 437, in apply_defaults
    result = func(self, **kwargs, default_args=default_args)
  File "/home/airflow/.local/lib/python3.9/site-packages/airflow/providers/docker/operators/docker.py", line 265, in __init__
    super().__init__(**kwargs)
  File "/home/airflow/.local/lib/python3.9/site-packages/airflow/models/baseoperator.py", line 437, in apply_defaults
    result = func(self, **kwargs, default_args=default_args)
  File "/home/airflow/.local/lib/python3.9/site-packages/airflow/models/baseoperator.py", line 793, in __init__
    raise AirflowException(
airflow.exceptions.AirflowException: Invalid arguments were passed to DockerOperator (task_id: generate_bank_data). Invalid arguments were:
**kwargs: {'volumes': ['/your/local/path/to/arlequin/scripts:/scripts', '/your/local/path/to/arlequin/hadoop-base/hadoop-conf:/opt/hadoop/etc/hadoop']}
[2025-08-04T23:19:09.579+0000] {processor.py:842} WARNING - No viable dags retrieved from /opt/airflow/dags/bank_data_dag.py
[2025-08-04T23:19:10.258+0000] {processor.py:183} INFO - Processing /opt/airflow/dags/bank_data_dag.py took 2.287 seconds
[2025-08-04T23:19:40.579+0000] {processor.py:161} INFO - Started process (PID=32) to work on /opt/airflow/dags/bank_data_dag.py
[2025-08-04T23:19:40.582+0000] {processor.py:830} INFO - Processing file /opt/airflow/dags/bank_data_dag.py for tasks to queue
[2025-08-04T23:19:40.594+0000] {logging_mixin.py:188} INFO - [2025-08-04T23:19:40.592+0000] {dagbag.py:538} INFO - Filling up the DagBag from /opt/airflow/dags/bank_data_dag.py
[2025-08-04T23:19:40.684+0000] {logging_mixin.py:188} INFO - [2025-08-04T23:19:40.676+0000] {dagbag.py:348} ERROR - Failed to import: /opt/airflow/dags/bank_data_dag.py
Traceback (most recent call last):
  File "/home/airflow/.local/lib/python3.9/site-packages/airflow/models/dagbag.py", line 344, in parse
    loader.exec_module(new_module)
  File "<frozen importlib._bootstrap_external>", line 850, in exec_module
  File "<frozen importlib._bootstrap>", line 228, in _call_with_frames_removed
  File "/opt/airflow/dags/bank_data_dag.py", line 15, in <module>
    generate_bank_data = DockerOperator(
  File "/home/airflow/.local/lib/python3.9/site-packages/airflow/models/baseoperator.py", line 437, in apply_defaults
    result = func(self, **kwargs, default_args=default_args)
  File "/home/airflow/.local/lib/python3.9/site-packages/airflow/providers/docker/operators/docker.py", line 265, in __init__
    super().__init__(**kwargs)
  File "/home/airflow/.local/lib/python3.9/site-packages/airflow/models/baseoperator.py", line 437, in apply_defaults
    result = func(self, **kwargs, default_args=default_args)
  File "/home/airflow/.local/lib/python3.9/site-packages/airflow/models/baseoperator.py", line 793, in __init__
    raise AirflowException(
airflow.exceptions.AirflowException: Invalid arguments were passed to DockerOperator (task_id: generate_bank_data). Invalid arguments were:
**kwargs: {'volumes': ['/your/local/path/to/arlequin/scripts:/scripts', '/your/local/path/to/arlequin/hadoop-base/hadoop-conf:/opt/hadoop/etc/hadoop']}
[2025-08-04T23:19:40.685+0000] {processor.py:842} WARNING - No viable dags retrieved from /opt/airflow/dags/bank_data_dag.py
[2025-08-04T23:19:40.748+0000] {processor.py:183} INFO - Processing /opt/airflow/dags/bank_data_dag.py took 0.183 seconds
[2025-08-04T23:20:10.913+0000] {processor.py:161} INFO - Started process (PID=33) to work on /opt/airflow/dags/bank_data_dag.py
[2025-08-04T23:20:10.918+0000] {processor.py:830} INFO - Processing file /opt/airflow/dags/bank_data_dag.py for tasks to queue
[2025-08-04T23:20:10.923+0000] {logging_mixin.py:188} INFO - [2025-08-04T23:20:10.922+0000] {dagbag.py:538} INFO - Filling up the DagBag from /opt/airflow/dags/bank_data_dag.py
[2025-08-04T23:20:10.956+0000] {logging_mixin.py:188} INFO - [2025-08-04T23:20:10.950+0000] {dagbag.py:348} ERROR - Failed to import: /opt/airflow/dags/bank_data_dag.py
Traceback (most recent call last):
  File "/home/airflow/.local/lib/python3.9/site-packages/airflow/models/dagbag.py", line 344, in parse
    loader.exec_module(new_module)
  File "<frozen importlib._bootstrap_external>", line 850, in exec_module
  File "<frozen importlib._bootstrap>", line 228, in _call_with_frames_removed
  File "/opt/airflow/dags/bank_data_dag.py", line 15, in <module>
    generate_bank_data = DockerOperator(
  File "/home/airflow/.local/lib/python3.9/site-packages/airflow/models/baseoperator.py", line 437, in apply_defaults
    result = func(self, **kwargs, default_args=default_args)
  File "/home/airflow/.local/lib/python3.9/site-packages/airflow/providers/docker/operators/docker.py", line 265, in __init__
    super().__init__(**kwargs)
  File "/home/airflow/.local/lib/python3.9/site-packages/airflow/models/baseoperator.py", line 437, in apply_defaults
    result = func(self, **kwargs, default_args=default_args)
  File "/home/airflow/.local/lib/python3.9/site-packages/airflow/models/baseoperator.py", line 793, in __init__
    raise AirflowException(
airflow.exceptions.AirflowException: Invalid arguments were passed to DockerOperator (task_id: generate_bank_data). Invalid arguments were:
**kwargs: {'volumes': ['/your/local/path/to/arlequin/scripts:/scripts', '/your/local/path/to/arlequin/hadoop-base/hadoop-conf:/opt/hadoop/etc/hadoop']}
[2025-08-04T23:20:10.958+0000] {processor.py:842} WARNING - No viable dags retrieved from /opt/airflow/dags/bank_data_dag.py
[2025-08-04T23:20:11.035+0000] {processor.py:183} INFO - Processing /opt/airflow/dags/bank_data_dag.py took 0.134 seconds
[2025-08-04T23:20:41.164+0000] {processor.py:161} INFO - Started process (PID=34) to work on /opt/airflow/dags/bank_data_dag.py
[2025-08-04T23:20:41.166+0000] {processor.py:830} INFO - Processing file /opt/airflow/dags/bank_data_dag.py for tasks to queue
[2025-08-04T23:20:41.169+0000] {logging_mixin.py:188} INFO - [2025-08-04T23:20:41.168+0000] {dagbag.py:538} INFO - Filling up the DagBag from /opt/airflow/dags/bank_data_dag.py
[2025-08-04T23:20:41.192+0000] {logging_mixin.py:188} INFO - [2025-08-04T23:20:41.186+0000] {dagbag.py:348} ERROR - Failed to import: /opt/airflow/dags/bank_data_dag.py
Traceback (most recent call last):
  File "/home/airflow/.local/lib/python3.9/site-packages/airflow/models/dagbag.py", line 344, in parse
    loader.exec_module(new_module)
  File "<frozen importlib._bootstrap_external>", line 850, in exec_module
  File "<frozen importlib._bootstrap>", line 228, in _call_with_frames_removed
  File "/opt/airflow/dags/bank_data_dag.py", line 15, in <module>
    generate_bank_data = DockerOperator(
  File "/home/airflow/.local/lib/python3.9/site-packages/airflow/models/baseoperator.py", line 437, in apply_defaults
    result = func(self, **kwargs, default_args=default_args)
  File "/home/airflow/.local/lib/python3.9/site-packages/airflow/providers/docker/operators/docker.py", line 265, in __init__
    super().__init__(**kwargs)
  File "/home/airflow/.local/lib/python3.9/site-packages/airflow/models/baseoperator.py", line 437, in apply_defaults
    result = func(self, **kwargs, default_args=default_args)
  File "/home/airflow/.local/lib/python3.9/site-packages/airflow/models/baseoperator.py", line 793, in __init__
    raise AirflowException(
airflow.exceptions.AirflowException: Invalid arguments were passed to DockerOperator (task_id: generate_bank_data). Invalid arguments were:
**kwargs: {'volumes': ['/your/local/path/to/arlequin/scripts:/scripts', '/your/local/path/to/arlequin/hadoop-base/hadoop-conf:/opt/hadoop/etc/hadoop']}
[2025-08-04T23:20:41.193+0000] {processor.py:842} WARNING - No viable dags retrieved from /opt/airflow/dags/bank_data_dag.py
[2025-08-04T23:20:41.224+0000] {processor.py:183} INFO - Processing /opt/airflow/dags/bank_data_dag.py took 0.063 seconds
[2025-08-04T23:21:11.482+0000] {processor.py:161} INFO - Started process (PID=35) to work on /opt/airflow/dags/bank_data_dag.py
[2025-08-04T23:21:11.539+0000] {processor.py:830} INFO - Processing file /opt/airflow/dags/bank_data_dag.py for tasks to queue
[2025-08-04T23:21:11.543+0000] {logging_mixin.py:188} INFO - [2025-08-04T23:21:11.542+0000] {dagbag.py:538} INFO - Filling up the DagBag from /opt/airflow/dags/bank_data_dag.py
[2025-08-04T23:21:11.572+0000] {logging_mixin.py:188} INFO - [2025-08-04T23:21:11.566+0000] {dagbag.py:348} ERROR - Failed to import: /opt/airflow/dags/bank_data_dag.py
Traceback (most recent call last):
  File "/home/airflow/.local/lib/python3.9/site-packages/airflow/models/dagbag.py", line 344, in parse
    loader.exec_module(new_module)
  File "<frozen importlib._bootstrap_external>", line 850, in exec_module
  File "<frozen importlib._bootstrap>", line 228, in _call_with_frames_removed
  File "/opt/airflow/dags/bank_data_dag.py", line 15, in <module>
    generate_bank_data = DockerOperator(
  File "/home/airflow/.local/lib/python3.9/site-packages/airflow/models/baseoperator.py", line 437, in apply_defaults
    result = func(self, **kwargs, default_args=default_args)
  File "/home/airflow/.local/lib/python3.9/site-packages/airflow/providers/docker/operators/docker.py", line 265, in __init__
    super().__init__(**kwargs)
  File "/home/airflow/.local/lib/python3.9/site-packages/airflow/models/baseoperator.py", line 437, in apply_defaults
    result = func(self, **kwargs, default_args=default_args)
  File "/home/airflow/.local/lib/python3.9/site-packages/airflow/models/baseoperator.py", line 793, in __init__
    raise AirflowException(
airflow.exceptions.AirflowException: Invalid arguments were passed to DockerOperator (task_id: generate_bank_data). Invalid arguments were:
**kwargs: {'volumes': ['/your/local/path/to/arlequin/scripts:/scripts', '/your/local/path/to/arlequin/hadoop-base/hadoop-conf:/opt/hadoop/etc/hadoop']}
[2025-08-04T23:21:11.576+0000] {processor.py:842} WARNING - No viable dags retrieved from /opt/airflow/dags/bank_data_dag.py
[2025-08-04T23:21:11.645+0000] {processor.py:183} INFO - Processing /opt/airflow/dags/bank_data_dag.py took 0.165 seconds
[2025-08-04T23:21:41.916+0000] {processor.py:161} INFO - Started process (PID=36) to work on /opt/airflow/dags/bank_data_dag.py
[2025-08-04T23:21:41.918+0000] {processor.py:830} INFO - Processing file /opt/airflow/dags/bank_data_dag.py for tasks to queue
[2025-08-04T23:21:41.921+0000] {logging_mixin.py:188} INFO - [2025-08-04T23:21:41.921+0000] {dagbag.py:538} INFO - Filling up the DagBag from /opt/airflow/dags/bank_data_dag.py
[2025-08-04T23:21:41.948+0000] {logging_mixin.py:188} INFO - [2025-08-04T23:21:41.942+0000] {dagbag.py:348} ERROR - Failed to import: /opt/airflow/dags/bank_data_dag.py
Traceback (most recent call last):
  File "/home/airflow/.local/lib/python3.9/site-packages/airflow/models/dagbag.py", line 344, in parse
    loader.exec_module(new_module)
  File "<frozen importlib._bootstrap_external>", line 850, in exec_module
  File "<frozen importlib._bootstrap>", line 228, in _call_with_frames_removed
  File "/opt/airflow/dags/bank_data_dag.py", line 15, in <module>
    generate_bank_data = DockerOperator(
  File "/home/airflow/.local/lib/python3.9/site-packages/airflow/models/baseoperator.py", line 437, in apply_defaults
    result = func(self, **kwargs, default_args=default_args)
  File "/home/airflow/.local/lib/python3.9/site-packages/airflow/providers/docker/operators/docker.py", line 265, in __init__
    super().__init__(**kwargs)
  File "/home/airflow/.local/lib/python3.9/site-packages/airflow/models/baseoperator.py", line 437, in apply_defaults
    result = func(self, **kwargs, default_args=default_args)
  File "/home/airflow/.local/lib/python3.9/site-packages/airflow/models/baseoperator.py", line 793, in __init__
    raise AirflowException(
airflow.exceptions.AirflowException: Invalid arguments were passed to DockerOperator (task_id: generate_bank_data). Invalid arguments were:
**kwargs: {'volumes': ['/your/local/path/to/arlequin/scripts:/scripts', '/your/local/path/to/arlequin/hadoop-base/hadoop-conf:/opt/hadoop/etc/hadoop']}
[2025-08-04T23:21:41.949+0000] {processor.py:842} WARNING - No viable dags retrieved from /opt/airflow/dags/bank_data_dag.py
[2025-08-04T23:21:41.986+0000] {processor.py:183} INFO - Processing /opt/airflow/dags/bank_data_dag.py took 0.074 seconds
[2025-08-04T23:22:12.164+0000] {processor.py:161} INFO - Started process (PID=37) to work on /opt/airflow/dags/bank_data_dag.py
[2025-08-04T23:22:12.166+0000] {processor.py:830} INFO - Processing file /opt/airflow/dags/bank_data_dag.py for tasks to queue
[2025-08-04T23:22:12.171+0000] {logging_mixin.py:188} INFO - [2025-08-04T23:22:12.171+0000] {dagbag.py:538} INFO - Filling up the DagBag from /opt/airflow/dags/bank_data_dag.py
[2025-08-04T23:22:12.214+0000] {logging_mixin.py:188} INFO - [2025-08-04T23:22:12.205+0000] {dagbag.py:348} ERROR - Failed to import: /opt/airflow/dags/bank_data_dag.py
Traceback (most recent call last):
  File "/home/airflow/.local/lib/python3.9/site-packages/airflow/models/dagbag.py", line 344, in parse
    loader.exec_module(new_module)
  File "<frozen importlib._bootstrap_external>", line 850, in exec_module
  File "<frozen importlib._bootstrap>", line 228, in _call_with_frames_removed
  File "/opt/airflow/dags/bank_data_dag.py", line 15, in <module>
    generate_bank_data = DockerOperator(
  File "/home/airflow/.local/lib/python3.9/site-packages/airflow/models/baseoperator.py", line 437, in apply_defaults
    result = func(self, **kwargs, default_args=default_args)
  File "/home/airflow/.local/lib/python3.9/site-packages/airflow/providers/docker/operators/docker.py", line 265, in __init__
    super().__init__(**kwargs)
  File "/home/airflow/.local/lib/python3.9/site-packages/airflow/models/baseoperator.py", line 437, in apply_defaults
    result = func(self, **kwargs, default_args=default_args)
  File "/home/airflow/.local/lib/python3.9/site-packages/airflow/models/baseoperator.py", line 793, in __init__
    raise AirflowException(
airflow.exceptions.AirflowException: Invalid arguments were passed to DockerOperator (task_id: generate_bank_data). Invalid arguments were:
**kwargs: {'volumes': ['/your/local/path/to/arlequin/scripts:/scripts', '/your/local/path/to/arlequin/hadoop-base/hadoop-conf:/opt/hadoop/etc/hadoop']}
[2025-08-04T23:22:12.216+0000] {processor.py:842} WARNING - No viable dags retrieved from /opt/airflow/dags/bank_data_dag.py
[2025-08-04T23:22:12.264+0000] {processor.py:183} INFO - Processing /opt/airflow/dags/bank_data_dag.py took 0.105 seconds
[2025-08-04T23:22:42.441+0000] {processor.py:161} INFO - Started process (PID=38) to work on /opt/airflow/dags/bank_data_dag.py
[2025-08-04T23:22:42.442+0000] {processor.py:830} INFO - Processing file /opt/airflow/dags/bank_data_dag.py for tasks to queue
[2025-08-04T23:22:42.445+0000] {logging_mixin.py:188} INFO - [2025-08-04T23:22:42.444+0000] {dagbag.py:538} INFO - Filling up the DagBag from /opt/airflow/dags/bank_data_dag.py
[2025-08-04T23:22:42.473+0000] {logging_mixin.py:188} INFO - [2025-08-04T23:22:42.466+0000] {dagbag.py:348} ERROR - Failed to import: /opt/airflow/dags/bank_data_dag.py
Traceback (most recent call last):
  File "/home/airflow/.local/lib/python3.9/site-packages/airflow/models/dagbag.py", line 344, in parse
    loader.exec_module(new_module)
  File "<frozen importlib._bootstrap_external>", line 850, in exec_module
  File "<frozen importlib._bootstrap>", line 228, in _call_with_frames_removed
  File "/opt/airflow/dags/bank_data_dag.py", line 15, in <module>
    generate_bank_data = DockerOperator(
  File "/home/airflow/.local/lib/python3.9/site-packages/airflow/models/baseoperator.py", line 437, in apply_defaults
    result = func(self, **kwargs, default_args=default_args)
  File "/home/airflow/.local/lib/python3.9/site-packages/airflow/providers/docker/operators/docker.py", line 265, in __init__
    super().__init__(**kwargs)
  File "/home/airflow/.local/lib/python3.9/site-packages/airflow/models/baseoperator.py", line 437, in apply_defaults
    result = func(self, **kwargs, default_args=default_args)
  File "/home/airflow/.local/lib/python3.9/site-packages/airflow/models/baseoperator.py", line 793, in __init__
    raise AirflowException(
airflow.exceptions.AirflowException: Invalid arguments were passed to DockerOperator (task_id: generate_bank_data). Invalid arguments were:
**kwargs: {'volumes': ['/your/local/path/to/arlequin/scripts:/scripts', '/your/local/path/to/arlequin/hadoop-base/hadoop-conf:/opt/hadoop/etc/hadoop']}
[2025-08-04T23:22:42.474+0000] {processor.py:842} WARNING - No viable dags retrieved from /opt/airflow/dags/bank_data_dag.py
[2025-08-04T23:22:42.505+0000] {processor.py:183} INFO - Processing /opt/airflow/dags/bank_data_dag.py took 0.068 seconds
[2025-08-04T23:23:13.424+0000] {processor.py:161} INFO - Started process (PID=39) to work on /opt/airflow/dags/bank_data_dag.py
[2025-08-04T23:23:13.425+0000] {processor.py:830} INFO - Processing file /opt/airflow/dags/bank_data_dag.py for tasks to queue
[2025-08-04T23:23:13.428+0000] {logging_mixin.py:188} INFO - [2025-08-04T23:23:13.427+0000] {dagbag.py:538} INFO - Filling up the DagBag from /opt/airflow/dags/bank_data_dag.py
[2025-08-04T23:23:13.451+0000] {logging_mixin.py:188} INFO - [2025-08-04T23:23:13.446+0000] {dagbag.py:348} ERROR - Failed to import: /opt/airflow/dags/bank_data_dag.py
Traceback (most recent call last):
  File "/home/airflow/.local/lib/python3.9/site-packages/airflow/models/dagbag.py", line 344, in parse
    loader.exec_module(new_module)
  File "<frozen importlib._bootstrap_external>", line 850, in exec_module
  File "<frozen importlib._bootstrap>", line 228, in _call_with_frames_removed
  File "/opt/airflow/dags/bank_data_dag.py", line 15, in <module>
    generate_bank_data = DockerOperator(
  File "/home/airflow/.local/lib/python3.9/site-packages/airflow/models/baseoperator.py", line 437, in apply_defaults
    result = func(self, **kwargs, default_args=default_args)
  File "/home/airflow/.local/lib/python3.9/site-packages/airflow/providers/docker/operators/docker.py", line 265, in __init__
    super().__init__(**kwargs)
  File "/home/airflow/.local/lib/python3.9/site-packages/airflow/models/baseoperator.py", line 437, in apply_defaults
    result = func(self, **kwargs, default_args=default_args)
  File "/home/airflow/.local/lib/python3.9/site-packages/airflow/models/baseoperator.py", line 793, in __init__
    raise AirflowException(
airflow.exceptions.AirflowException: Invalid arguments were passed to DockerOperator (task_id: generate_bank_data). Invalid arguments were:
**kwargs: {'volumes': ['/your/local/path/to/arlequin/scripts:/scripts', '/your/local/path/to/arlequin/hadoop-base/hadoop-conf:/opt/hadoop/etc/hadoop']}
[2025-08-04T23:23:13.453+0000] {processor.py:842} WARNING - No viable dags retrieved from /opt/airflow/dags/bank_data_dag.py
[2025-08-04T23:23:13.479+0000] {processor.py:183} INFO - Processing /opt/airflow/dags/bank_data_dag.py took 0.058 seconds
[2025-08-04T23:23:45.155+0000] {processor.py:161} INFO - Started process (PID=40) to work on /opt/airflow/dags/bank_data_dag.py
[2025-08-04T23:23:45.219+0000] {processor.py:830} INFO - Processing file /opt/airflow/dags/bank_data_dag.py for tasks to queue
[2025-08-04T23:23:45.222+0000] {logging_mixin.py:188} INFO - [2025-08-04T23:23:45.221+0000] {dagbag.py:538} INFO - Filling up the DagBag from /opt/airflow/dags/bank_data_dag.py
[2025-08-04T23:23:45.776+0000] {logging_mixin.py:188} INFO - [2025-08-04T23:23:45.574+0000] {dagbag.py:348} ERROR - Failed to import: /opt/airflow/dags/bank_data_dag.py
Traceback (most recent call last):
  File "/home/airflow/.local/lib/python3.9/site-packages/airflow/models/dagbag.py", line 344, in parse
    loader.exec_module(new_module)
  File "<frozen importlib._bootstrap_external>", line 850, in exec_module
  File "<frozen importlib._bootstrap>", line 228, in _call_with_frames_removed
  File "/opt/airflow/dags/bank_data_dag.py", line 15, in <module>
    generate_bank_data = DockerOperator(
  File "/home/airflow/.local/lib/python3.9/site-packages/airflow/models/baseoperator.py", line 437, in apply_defaults
    result = func(self, **kwargs, default_args=default_args)
  File "/home/airflow/.local/lib/python3.9/site-packages/airflow/providers/docker/operators/docker.py", line 265, in __init__
    super().__init__(**kwargs)
  File "/home/airflow/.local/lib/python3.9/site-packages/airflow/models/baseoperator.py", line 437, in apply_defaults
    result = func(self, **kwargs, default_args=default_args)
  File "/home/airflow/.local/lib/python3.9/site-packages/airflow/models/baseoperator.py", line 793, in __init__
    raise AirflowException(
airflow.exceptions.AirflowException: Invalid arguments were passed to DockerOperator (task_id: generate_bank_data). Invalid arguments were:
**kwargs: {'volumes': ['/your/local/path/to/arlequin/scripts:/scripts', '/your/local/path/to/arlequin/hadoop-base/hadoop-conf:/opt/hadoop/etc/hadoop']}
[2025-08-04T23:23:45.777+0000] {processor.py:842} WARNING - No viable dags retrieved from /opt/airflow/dags/bank_data_dag.py
[2025-08-04T23:23:46.084+0000] {processor.py:183} INFO - Processing /opt/airflow/dags/bank_data_dag.py took 0.938 seconds
[2025-08-04T23:24:16.318+0000] {processor.py:161} INFO - Started process (PID=41) to work on /opt/airflow/dags/bank_data_dag.py
[2025-08-04T23:24:16.320+0000] {processor.py:830} INFO - Processing file /opt/airflow/dags/bank_data_dag.py for tasks to queue
[2025-08-04T23:24:16.323+0000] {logging_mixin.py:188} INFO - [2025-08-04T23:24:16.322+0000] {dagbag.py:538} INFO - Filling up the DagBag from /opt/airflow/dags/bank_data_dag.py
[2025-08-04T23:24:16.351+0000] {logging_mixin.py:188} INFO - [2025-08-04T23:24:16.345+0000] {dagbag.py:348} ERROR - Failed to import: /opt/airflow/dags/bank_data_dag.py
Traceback (most recent call last):
  File "/home/airflow/.local/lib/python3.9/site-packages/airflow/models/dagbag.py", line 344, in parse
    loader.exec_module(new_module)
  File "<frozen importlib._bootstrap_external>", line 850, in exec_module
  File "<frozen importlib._bootstrap>", line 228, in _call_with_frames_removed
  File "/opt/airflow/dags/bank_data_dag.py", line 15, in <module>
    generate_bank_data = DockerOperator(
  File "/home/airflow/.local/lib/python3.9/site-packages/airflow/models/baseoperator.py", line 437, in apply_defaults
    result = func(self, **kwargs, default_args=default_args)
  File "/home/airflow/.local/lib/python3.9/site-packages/airflow/providers/docker/operators/docker.py", line 265, in __init__
    super().__init__(**kwargs)
  File "/home/airflow/.local/lib/python3.9/site-packages/airflow/models/baseoperator.py", line 437, in apply_defaults
    result = func(self, **kwargs, default_args=default_args)
  File "/home/airflow/.local/lib/python3.9/site-packages/airflow/models/baseoperator.py", line 793, in __init__
    raise AirflowException(
airflow.exceptions.AirflowException: Invalid arguments were passed to DockerOperator (task_id: generate_bank_data). Invalid arguments were:
**kwargs: {'volumes': ['/your/local/path/to/arlequin/scripts:/scripts', '/your/local/path/to/arlequin/hadoop-base/hadoop-conf:/opt/hadoop/etc/hadoop']}
[2025-08-04T23:24:16.352+0000] {processor.py:842} WARNING - No viable dags retrieved from /opt/airflow/dags/bank_data_dag.py
[2025-08-04T23:24:16.396+0000] {processor.py:183} INFO - Processing /opt/airflow/dags/bank_data_dag.py took 0.082 seconds
[2025-08-04T23:24:46.565+0000] {processor.py:161} INFO - Started process (PID=42) to work on /opt/airflow/dags/bank_data_dag.py
[2025-08-04T23:24:46.567+0000] {processor.py:830} INFO - Processing file /opt/airflow/dags/bank_data_dag.py for tasks to queue
[2025-08-04T23:24:46.569+0000] {logging_mixin.py:188} INFO - [2025-08-04T23:24:46.569+0000] {dagbag.py:538} INFO - Filling up the DagBag from /opt/airflow/dags/bank_data_dag.py
[2025-08-04T23:24:46.588+0000] {logging_mixin.py:188} INFO - [2025-08-04T23:24:46.583+0000] {dagbag.py:348} ERROR - Failed to import: /opt/airflow/dags/bank_data_dag.py
Traceback (most recent call last):
  File "/home/airflow/.local/lib/python3.9/site-packages/airflow/models/dagbag.py", line 344, in parse
    loader.exec_module(new_module)
  File "<frozen importlib._bootstrap_external>", line 850, in exec_module
  File "<frozen importlib._bootstrap>", line 228, in _call_with_frames_removed
  File "/opt/airflow/dags/bank_data_dag.py", line 15, in <module>
    generate_bank_data = DockerOperator(
  File "/home/airflow/.local/lib/python3.9/site-packages/airflow/models/baseoperator.py", line 437, in apply_defaults
    result = func(self, **kwargs, default_args=default_args)
  File "/home/airflow/.local/lib/python3.9/site-packages/airflow/providers/docker/operators/docker.py", line 265, in __init__
    super().__init__(**kwargs)
  File "/home/airflow/.local/lib/python3.9/site-packages/airflow/models/baseoperator.py", line 437, in apply_defaults
    result = func(self, **kwargs, default_args=default_args)
  File "/home/airflow/.local/lib/python3.9/site-packages/airflow/models/baseoperator.py", line 793, in __init__
    raise AirflowException(
airflow.exceptions.AirflowException: Invalid arguments were passed to DockerOperator (task_id: generate_bank_data). Invalid arguments were:
**kwargs: {'volumes': ['/your/local/path/to/arlequin/scripts:/scripts', '/your/local/path/to/arlequin/hadoop-base/hadoop-conf:/opt/hadoop/etc/hadoop']}
[2025-08-04T23:24:46.589+0000] {processor.py:842} WARNING - No viable dags retrieved from /opt/airflow/dags/bank_data_dag.py
[2025-08-04T23:24:46.621+0000] {processor.py:183} INFO - Processing /opt/airflow/dags/bank_data_dag.py took 0.059 seconds
[2025-08-04T23:25:16.853+0000] {processor.py:161} INFO - Started process (PID=43) to work on /opt/airflow/dags/bank_data_dag.py
[2025-08-04T23:25:16.855+0000] {processor.py:830} INFO - Processing file /opt/airflow/dags/bank_data_dag.py for tasks to queue
[2025-08-04T23:25:16.857+0000] {logging_mixin.py:188} INFO - [2025-08-04T23:25:16.857+0000] {dagbag.py:538} INFO - Filling up the DagBag from /opt/airflow/dags/bank_data_dag.py
[2025-08-04T23:25:16.884+0000] {logging_mixin.py:188} INFO - [2025-08-04T23:25:16.878+0000] {dagbag.py:348} ERROR - Failed to import: /opt/airflow/dags/bank_data_dag.py
Traceback (most recent call last):
  File "/home/airflow/.local/lib/python3.9/site-packages/airflow/models/dagbag.py", line 344, in parse
    loader.exec_module(new_module)
  File "<frozen importlib._bootstrap_external>", line 850, in exec_module
  File "<frozen importlib._bootstrap>", line 228, in _call_with_frames_removed
  File "/opt/airflow/dags/bank_data_dag.py", line 15, in <module>
    generate_bank_data = DockerOperator(
  File "/home/airflow/.local/lib/python3.9/site-packages/airflow/models/baseoperator.py", line 437, in apply_defaults
    result = func(self, **kwargs, default_args=default_args)
  File "/home/airflow/.local/lib/python3.9/site-packages/airflow/providers/docker/operators/docker.py", line 265, in __init__
    super().__init__(**kwargs)
  File "/home/airflow/.local/lib/python3.9/site-packages/airflow/models/baseoperator.py", line 437, in apply_defaults
    result = func(self, **kwargs, default_args=default_args)
  File "/home/airflow/.local/lib/python3.9/site-packages/airflow/models/baseoperator.py", line 793, in __init__
    raise AirflowException(
airflow.exceptions.AirflowException: Invalid arguments were passed to DockerOperator (task_id: generate_bank_data). Invalid arguments were:
**kwargs: {'volumes': ['/your/local/path/to/arlequin/scripts:/scripts', '/your/local/path/to/arlequin/hadoop-base/hadoop-conf:/opt/hadoop/etc/hadoop']}
[2025-08-04T23:25:16.885+0000] {processor.py:842} WARNING - No viable dags retrieved from /opt/airflow/dags/bank_data_dag.py
[2025-08-04T23:25:16.914+0000] {processor.py:183} INFO - Processing /opt/airflow/dags/bank_data_dag.py took 0.063 seconds
[2025-08-04T23:25:47.094+0000] {processor.py:161} INFO - Started process (PID=44) to work on /opt/airflow/dags/bank_data_dag.py
[2025-08-04T23:25:47.096+0000] {processor.py:830} INFO - Processing file /opt/airflow/dags/bank_data_dag.py for tasks to queue
[2025-08-04T23:25:47.098+0000] {logging_mixin.py:188} INFO - [2025-08-04T23:25:47.098+0000] {dagbag.py:538} INFO - Filling up the DagBag from /opt/airflow/dags/bank_data_dag.py
[2025-08-04T23:25:47.122+0000] {logging_mixin.py:188} INFO - [2025-08-04T23:25:47.117+0000] {dagbag.py:348} ERROR - Failed to import: /opt/airflow/dags/bank_data_dag.py
Traceback (most recent call last):
  File "/home/airflow/.local/lib/python3.9/site-packages/airflow/models/dagbag.py", line 344, in parse
    loader.exec_module(new_module)
  File "<frozen importlib._bootstrap_external>", line 850, in exec_module
  File "<frozen importlib._bootstrap>", line 228, in _call_with_frames_removed
  File "/opt/airflow/dags/bank_data_dag.py", line 15, in <module>
    generate_bank_data = DockerOperator(
  File "/home/airflow/.local/lib/python3.9/site-packages/airflow/models/baseoperator.py", line 437, in apply_defaults
    result = func(self, **kwargs, default_args=default_args)
  File "/home/airflow/.local/lib/python3.9/site-packages/airflow/providers/docker/operators/docker.py", line 265, in __init__
    super().__init__(**kwargs)
  File "/home/airflow/.local/lib/python3.9/site-packages/airflow/models/baseoperator.py", line 437, in apply_defaults
    result = func(self, **kwargs, default_args=default_args)
  File "/home/airflow/.local/lib/python3.9/site-packages/airflow/models/baseoperator.py", line 793, in __init__
    raise AirflowException(
airflow.exceptions.AirflowException: Invalid arguments were passed to DockerOperator (task_id: generate_bank_data). Invalid arguments were:
**kwargs: {'volumes': ['/your/local/path/to/arlequin/scripts:/scripts', '/your/local/path/to/arlequin/hadoop-base/hadoop-conf:/opt/hadoop/etc/hadoop']}
[2025-08-04T23:25:47.123+0000] {processor.py:842} WARNING - No viable dags retrieved from /opt/airflow/dags/bank_data_dag.py
[2025-08-04T23:25:47.151+0000] {processor.py:183} INFO - Processing /opt/airflow/dags/bank_data_dag.py took 0.060 seconds
[2025-08-04T23:26:17.370+0000] {processor.py:161} INFO - Started process (PID=45) to work on /opt/airflow/dags/bank_data_dag.py
[2025-08-04T23:26:17.382+0000] {processor.py:830} INFO - Processing file /opt/airflow/dags/bank_data_dag.py for tasks to queue
[2025-08-04T23:26:17.385+0000] {logging_mixin.py:188} INFO - [2025-08-04T23:26:17.384+0000] {dagbag.py:538} INFO - Filling up the DagBag from /opt/airflow/dags/bank_data_dag.py
[2025-08-04T23:26:17.411+0000] {logging_mixin.py:188} INFO - [2025-08-04T23:26:17.404+0000] {dagbag.py:348} ERROR - Failed to import: /opt/airflow/dags/bank_data_dag.py
Traceback (most recent call last):
  File "/home/airflow/.local/lib/python3.9/site-packages/airflow/models/dagbag.py", line 344, in parse
    loader.exec_module(new_module)
  File "<frozen importlib._bootstrap_external>", line 850, in exec_module
  File "<frozen importlib._bootstrap>", line 228, in _call_with_frames_removed
  File "/opt/airflow/dags/bank_data_dag.py", line 15, in <module>
    generate_bank_data = DockerOperator(
  File "/home/airflow/.local/lib/python3.9/site-packages/airflow/models/baseoperator.py", line 437, in apply_defaults
    result = func(self, **kwargs, default_args=default_args)
  File "/home/airflow/.local/lib/python3.9/site-packages/airflow/providers/docker/operators/docker.py", line 265, in __init__
    super().__init__(**kwargs)
  File "/home/airflow/.local/lib/python3.9/site-packages/airflow/models/baseoperator.py", line 437, in apply_defaults
    result = func(self, **kwargs, default_args=default_args)
  File "/home/airflow/.local/lib/python3.9/site-packages/airflow/models/baseoperator.py", line 793, in __init__
    raise AirflowException(
airflow.exceptions.AirflowException: Invalid arguments were passed to DockerOperator (task_id: generate_bank_data). Invalid arguments were:
**kwargs: {'volumes': ['/your/local/path/to/arlequin/scripts:/scripts', '/your/local/path/to/arlequin/hadoop-base/hadoop-conf:/opt/hadoop/etc/hadoop']}
[2025-08-04T23:26:17.412+0000] {processor.py:842} WARNING - No viable dags retrieved from /opt/airflow/dags/bank_data_dag.py
[2025-08-04T23:26:17.440+0000] {processor.py:183} INFO - Processing /opt/airflow/dags/bank_data_dag.py took 0.073 seconds
[2025-08-04T23:26:47.615+0000] {processor.py:161} INFO - Started process (PID=46) to work on /opt/airflow/dags/bank_data_dag.py
[2025-08-04T23:26:47.617+0000] {processor.py:830} INFO - Processing file /opt/airflow/dags/bank_data_dag.py for tasks to queue
[2025-08-04T23:26:47.620+0000] {logging_mixin.py:188} INFO - [2025-08-04T23:26:47.620+0000] {dagbag.py:538} INFO - Filling up the DagBag from /opt/airflow/dags/bank_data_dag.py
[2025-08-04T23:26:47.643+0000] {logging_mixin.py:188} INFO - [2025-08-04T23:26:47.638+0000] {dagbag.py:348} ERROR - Failed to import: /opt/airflow/dags/bank_data_dag.py
Traceback (most recent call last):
  File "/home/airflow/.local/lib/python3.9/site-packages/airflow/models/dagbag.py", line 344, in parse
    loader.exec_module(new_module)
  File "<frozen importlib._bootstrap_external>", line 850, in exec_module
  File "<frozen importlib._bootstrap>", line 228, in _call_with_frames_removed
  File "/opt/airflow/dags/bank_data_dag.py", line 15, in <module>
    generate_bank_data = DockerOperator(
  File "/home/airflow/.local/lib/python3.9/site-packages/airflow/models/baseoperator.py", line 437, in apply_defaults
    result = func(self, **kwargs, default_args=default_args)
  File "/home/airflow/.local/lib/python3.9/site-packages/airflow/providers/docker/operators/docker.py", line 265, in __init__
    super().__init__(**kwargs)
  File "/home/airflow/.local/lib/python3.9/site-packages/airflow/models/baseoperator.py", line 437, in apply_defaults
    result = func(self, **kwargs, default_args=default_args)
  File "/home/airflow/.local/lib/python3.9/site-packages/airflow/models/baseoperator.py", line 793, in __init__
    raise AirflowException(
airflow.exceptions.AirflowException: Invalid arguments were passed to DockerOperator (task_id: generate_bank_data). Invalid arguments were:
**kwargs: {'volumes': ['/your/local/path/to/arlequin/scripts:/scripts', '/your/local/path/to/arlequin/hadoop-base/hadoop-conf:/opt/hadoop/etc/hadoop']}
[2025-08-04T23:26:47.644+0000] {processor.py:842} WARNING - No viable dags retrieved from /opt/airflow/dags/bank_data_dag.py
[2025-08-04T23:26:47.677+0000] {processor.py:183} INFO - Processing /opt/airflow/dags/bank_data_dag.py took 0.068 seconds
[2025-08-04T23:27:17.934+0000] {processor.py:161} INFO - Started process (PID=47) to work on /opt/airflow/dags/bank_data_dag.py
[2025-08-04T23:27:17.935+0000] {processor.py:830} INFO - Processing file /opt/airflow/dags/bank_data_dag.py for tasks to queue
[2025-08-04T23:27:17.938+0000] {logging_mixin.py:188} INFO - [2025-08-04T23:27:17.938+0000] {dagbag.py:538} INFO - Filling up the DagBag from /opt/airflow/dags/bank_data_dag.py
[2025-08-04T23:27:17.959+0000] {logging_mixin.py:188} INFO - [2025-08-04T23:27:17.954+0000] {dagbag.py:348} ERROR - Failed to import: /opt/airflow/dags/bank_data_dag.py
Traceback (most recent call last):
  File "/home/airflow/.local/lib/python3.9/site-packages/airflow/models/dagbag.py", line 344, in parse
    loader.exec_module(new_module)
  File "<frozen importlib._bootstrap_external>", line 850, in exec_module
  File "<frozen importlib._bootstrap>", line 228, in _call_with_frames_removed
  File "/opt/airflow/dags/bank_data_dag.py", line 15, in <module>
    generate_bank_data = DockerOperator(
  File "/home/airflow/.local/lib/python3.9/site-packages/airflow/models/baseoperator.py", line 437, in apply_defaults
    result = func(self, **kwargs, default_args=default_args)
  File "/home/airflow/.local/lib/python3.9/site-packages/airflow/providers/docker/operators/docker.py", line 265, in __init__
    super().__init__(**kwargs)
  File "/home/airflow/.local/lib/python3.9/site-packages/airflow/models/baseoperator.py", line 437, in apply_defaults
    result = func(self, **kwargs, default_args=default_args)
  File "/home/airflow/.local/lib/python3.9/site-packages/airflow/models/baseoperator.py", line 793, in __init__
    raise AirflowException(
airflow.exceptions.AirflowException: Invalid arguments were passed to DockerOperator (task_id: generate_bank_data). Invalid arguments were:
**kwargs: {'volumes': ['/your/local/path/to/arlequin/scripts:/scripts', '/your/local/path/to/arlequin/hadoop-base/hadoop-conf:/opt/hadoop/etc/hadoop']}
[2025-08-04T23:27:17.960+0000] {processor.py:842} WARNING - No viable dags retrieved from /opt/airflow/dags/bank_data_dag.py
[2025-08-04T23:27:17.986+0000] {processor.py:183} INFO - Processing /opt/airflow/dags/bank_data_dag.py took 0.055 seconds
[2025-08-04T23:27:48.167+0000] {processor.py:161} INFO - Started process (PID=48) to work on /opt/airflow/dags/bank_data_dag.py
[2025-08-04T23:27:48.179+0000] {processor.py:830} INFO - Processing file /opt/airflow/dags/bank_data_dag.py for tasks to queue
[2025-08-04T23:27:48.182+0000] {logging_mixin.py:188} INFO - [2025-08-04T23:27:48.182+0000] {dagbag.py:538} INFO - Filling up the DagBag from /opt/airflow/dags/bank_data_dag.py
[2025-08-04T23:27:48.206+0000] {logging_mixin.py:188} INFO - [2025-08-04T23:27:48.201+0000] {dagbag.py:348} ERROR - Failed to import: /opt/airflow/dags/bank_data_dag.py
Traceback (most recent call last):
  File "/home/airflow/.local/lib/python3.9/site-packages/airflow/models/dagbag.py", line 344, in parse
    loader.exec_module(new_module)
  File "<frozen importlib._bootstrap_external>", line 850, in exec_module
  File "<frozen importlib._bootstrap>", line 228, in _call_with_frames_removed
  File "/opt/airflow/dags/bank_data_dag.py", line 15, in <module>
    generate_bank_data = DockerOperator(
  File "/home/airflow/.local/lib/python3.9/site-packages/airflow/models/baseoperator.py", line 437, in apply_defaults
    result = func(self, **kwargs, default_args=default_args)
  File "/home/airflow/.local/lib/python3.9/site-packages/airflow/providers/docker/operators/docker.py", line 265, in __init__
    super().__init__(**kwargs)
  File "/home/airflow/.local/lib/python3.9/site-packages/airflow/models/baseoperator.py", line 437, in apply_defaults
    result = func(self, **kwargs, default_args=default_args)
  File "/home/airflow/.local/lib/python3.9/site-packages/airflow/models/baseoperator.py", line 793, in __init__
    raise AirflowException(
airflow.exceptions.AirflowException: Invalid arguments were passed to DockerOperator (task_id: generate_bank_data). Invalid arguments were:
**kwargs: {'volumes': ['/your/local/path/to/arlequin/scripts:/scripts', '/your/local/path/to/arlequin/hadoop-base/hadoop-conf:/opt/hadoop/etc/hadoop']}
[2025-08-04T23:27:48.207+0000] {processor.py:842} WARNING - No viable dags retrieved from /opt/airflow/dags/bank_data_dag.py
[2025-08-04T23:27:48.235+0000] {processor.py:183} INFO - Processing /opt/airflow/dags/bank_data_dag.py took 0.073 seconds
[2025-08-04T23:28:18.492+0000] {processor.py:161} INFO - Started process (PID=49) to work on /opt/airflow/dags/bank_data_dag.py
[2025-08-04T23:28:18.494+0000] {processor.py:830} INFO - Processing file /opt/airflow/dags/bank_data_dag.py for tasks to queue
[2025-08-04T23:28:18.504+0000] {logging_mixin.py:188} INFO - [2025-08-04T23:28:18.497+0000] {dagbag.py:538} INFO - Filling up the DagBag from /opt/airflow/dags/bank_data_dag.py
[2025-08-04T23:28:18.616+0000] {logging_mixin.py:188} INFO - [2025-08-04T23:28:18.600+0000] {dagbag.py:348} ERROR - Failed to import: /opt/airflow/dags/bank_data_dag.py
Traceback (most recent call last):
  File "/home/airflow/.local/lib/python3.9/site-packages/airflow/models/dagbag.py", line 344, in parse
    loader.exec_module(new_module)
  File "<frozen importlib._bootstrap_external>", line 850, in exec_module
  File "<frozen importlib._bootstrap>", line 228, in _call_with_frames_removed
  File "/opt/airflow/dags/bank_data_dag.py", line 15, in <module>
    generate_bank_data = DockerOperator(
  File "/home/airflow/.local/lib/python3.9/site-packages/airflow/models/baseoperator.py", line 437, in apply_defaults
    result = func(self, **kwargs, default_args=default_args)
  File "/home/airflow/.local/lib/python3.9/site-packages/airflow/providers/docker/operators/docker.py", line 265, in __init__
    super().__init__(**kwargs)
  File "/home/airflow/.local/lib/python3.9/site-packages/airflow/models/baseoperator.py", line 437, in apply_defaults
    result = func(self, **kwargs, default_args=default_args)
  File "/home/airflow/.local/lib/python3.9/site-packages/airflow/models/baseoperator.py", line 793, in __init__
    raise AirflowException(
airflow.exceptions.AirflowException: Invalid arguments were passed to DockerOperator (task_id: generate_bank_data). Invalid arguments were:
**kwargs: {'volumes': ['/your/local/path/to/arlequin/scripts:/scripts', '/your/local/path/to/arlequin/hadoop-base/hadoop-conf:/opt/hadoop/etc/hadoop']}
[2025-08-04T23:28:18.619+0000] {processor.py:842} WARNING - No viable dags retrieved from /opt/airflow/dags/bank_data_dag.py
[2025-08-04T23:28:18.752+0000] {processor.py:183} INFO - Processing /opt/airflow/dags/bank_data_dag.py took 0.262 seconds
[2025-08-04T23:28:48.992+0000] {processor.py:161} INFO - Started process (PID=50) to work on /opt/airflow/dags/bank_data_dag.py
[2025-08-04T23:28:48.994+0000] {processor.py:830} INFO - Processing file /opt/airflow/dags/bank_data_dag.py for tasks to queue
[2025-08-04T23:28:48.996+0000] {logging_mixin.py:188} INFO - [2025-08-04T23:28:48.996+0000] {dagbag.py:538} INFO - Filling up the DagBag from /opt/airflow/dags/bank_data_dag.py
[2025-08-04T23:28:49.031+0000] {logging_mixin.py:188} INFO - [2025-08-04T23:28:49.015+0000] {dagbag.py:348} ERROR - Failed to import: /opt/airflow/dags/bank_data_dag.py
Traceback (most recent call last):
  File "/home/airflow/.local/lib/python3.9/site-packages/airflow/models/dagbag.py", line 344, in parse
    loader.exec_module(new_module)
  File "<frozen importlib._bootstrap_external>", line 850, in exec_module
  File "<frozen importlib._bootstrap>", line 228, in _call_with_frames_removed
  File "/opt/airflow/dags/bank_data_dag.py", line 15, in <module>
    generate_bank_data = DockerOperator(
  File "/home/airflow/.local/lib/python3.9/site-packages/airflow/models/baseoperator.py", line 437, in apply_defaults
    result = func(self, **kwargs, default_args=default_args)
  File "/home/airflow/.local/lib/python3.9/site-packages/airflow/providers/docker/operators/docker.py", line 265, in __init__
    super().__init__(**kwargs)
  File "/home/airflow/.local/lib/python3.9/site-packages/airflow/models/baseoperator.py", line 437, in apply_defaults
    result = func(self, **kwargs, default_args=default_args)
  File "/home/airflow/.local/lib/python3.9/site-packages/airflow/models/baseoperator.py", line 793, in __init__
    raise AirflowException(
airflow.exceptions.AirflowException: Invalid arguments were passed to DockerOperator (task_id: generate_bank_data). Invalid arguments were:
**kwargs: {'volumes': ['/your/local/path/to/arlequin/scripts:/scripts', '/your/local/path/to/arlequin/hadoop-base/hadoop-conf:/opt/hadoop/etc/hadoop']}
[2025-08-04T23:28:49.032+0000] {processor.py:842} WARNING - No viable dags retrieved from /opt/airflow/dags/bank_data_dag.py
[2025-08-04T23:28:49.064+0000] {processor.py:183} INFO - Processing /opt/airflow/dags/bank_data_dag.py took 0.074 seconds
[2025-08-04T23:29:19.227+0000] {processor.py:161} INFO - Started process (PID=51) to work on /opt/airflow/dags/bank_data_dag.py
[2025-08-04T23:29:19.228+0000] {processor.py:830} INFO - Processing file /opt/airflow/dags/bank_data_dag.py for tasks to queue
[2025-08-04T23:29:19.231+0000] {logging_mixin.py:188} INFO - [2025-08-04T23:29:19.230+0000] {dagbag.py:538} INFO - Filling up the DagBag from /opt/airflow/dags/bank_data_dag.py
[2025-08-04T23:29:19.255+0000] {logging_mixin.py:188} INFO - [2025-08-04T23:29:19.249+0000] {dagbag.py:348} ERROR - Failed to import: /opt/airflow/dags/bank_data_dag.py
Traceback (most recent call last):
  File "/home/airflow/.local/lib/python3.9/site-packages/airflow/models/dagbag.py", line 344, in parse
    loader.exec_module(new_module)
  File "<frozen importlib._bootstrap_external>", line 850, in exec_module
  File "<frozen importlib._bootstrap>", line 228, in _call_with_frames_removed
  File "/opt/airflow/dags/bank_data_dag.py", line 15, in <module>
    generate_bank_data = DockerOperator(
  File "/home/airflow/.local/lib/python3.9/site-packages/airflow/models/baseoperator.py", line 437, in apply_defaults
    result = func(self, **kwargs, default_args=default_args)
  File "/home/airflow/.local/lib/python3.9/site-packages/airflow/providers/docker/operators/docker.py", line 265, in __init__
    super().__init__(**kwargs)
  File "/home/airflow/.local/lib/python3.9/site-packages/airflow/models/baseoperator.py", line 437, in apply_defaults
    result = func(self, **kwargs, default_args=default_args)
  File "/home/airflow/.local/lib/python3.9/site-packages/airflow/models/baseoperator.py", line 793, in __init__
    raise AirflowException(
airflow.exceptions.AirflowException: Invalid arguments were passed to DockerOperator (task_id: generate_bank_data). Invalid arguments were:
**kwargs: {'volumes': ['/your/local/path/to/arlequin/scripts:/scripts', '/your/local/path/to/arlequin/hadoop-base/hadoop-conf:/opt/hadoop/etc/hadoop']}
[2025-08-04T23:29:19.255+0000] {processor.py:842} WARNING - No viable dags retrieved from /opt/airflow/dags/bank_data_dag.py
[2025-08-04T23:29:19.293+0000] {processor.py:183} INFO - Processing /opt/airflow/dags/bank_data_dag.py took 0.070 seconds
[2025-08-04T23:29:49.530+0000] {processor.py:161} INFO - Started process (PID=52) to work on /opt/airflow/dags/bank_data_dag.py
[2025-08-04T23:29:49.532+0000] {processor.py:830} INFO - Processing file /opt/airflow/dags/bank_data_dag.py for tasks to queue
[2025-08-04T23:29:49.535+0000] {logging_mixin.py:188} INFO - [2025-08-04T23:29:49.534+0000] {dagbag.py:538} INFO - Filling up the DagBag from /opt/airflow/dags/bank_data_dag.py
[2025-08-04T23:29:49.553+0000] {logging_mixin.py:188} INFO - [2025-08-04T23:29:49.549+0000] {dagbag.py:348} ERROR - Failed to import: /opt/airflow/dags/bank_data_dag.py
Traceback (most recent call last):
  File "/home/airflow/.local/lib/python3.9/site-packages/airflow/models/dagbag.py", line 344, in parse
    loader.exec_module(new_module)
  File "<frozen importlib._bootstrap_external>", line 850, in exec_module
  File "<frozen importlib._bootstrap>", line 228, in _call_with_frames_removed
  File "/opt/airflow/dags/bank_data_dag.py", line 15, in <module>
    generate_bank_data = DockerOperator(
  File "/home/airflow/.local/lib/python3.9/site-packages/airflow/models/baseoperator.py", line 437, in apply_defaults
    result = func(self, **kwargs, default_args=default_args)
  File "/home/airflow/.local/lib/python3.9/site-packages/airflow/providers/docker/operators/docker.py", line 265, in __init__
    super().__init__(**kwargs)
  File "/home/airflow/.local/lib/python3.9/site-packages/airflow/models/baseoperator.py", line 437, in apply_defaults
    result = func(self, **kwargs, default_args=default_args)
  File "/home/airflow/.local/lib/python3.9/site-packages/airflow/models/baseoperator.py", line 793, in __init__
    raise AirflowException(
airflow.exceptions.AirflowException: Invalid arguments were passed to DockerOperator (task_id: generate_bank_data). Invalid arguments were:
**kwargs: {'volumes': ['/your/local/path/to/arlequin/scripts:/scripts', '/your/local/path/to/arlequin/hadoop-base/hadoop-conf:/opt/hadoop/etc/hadoop']}
[2025-08-04T23:29:49.554+0000] {processor.py:842} WARNING - No viable dags retrieved from /opt/airflow/dags/bank_data_dag.py
[2025-08-04T23:29:49.579+0000] {processor.py:183} INFO - Processing /opt/airflow/dags/bank_data_dag.py took 0.052 seconds
[2025-08-04T23:30:19.775+0000] {processor.py:161} INFO - Started process (PID=53) to work on /opt/airflow/dags/bank_data_dag.py
[2025-08-04T23:30:19.776+0000] {processor.py:830} INFO - Processing file /opt/airflow/dags/bank_data_dag.py for tasks to queue
[2025-08-04T23:30:19.779+0000] {logging_mixin.py:188} INFO - [2025-08-04T23:30:19.779+0000] {dagbag.py:538} INFO - Filling up the DagBag from /opt/airflow/dags/bank_data_dag.py
[2025-08-04T23:30:19.897+0000] {logging_mixin.py:188} INFO - [2025-08-04T23:30:19.858+0000] {dagbag.py:348} ERROR - Failed to import: /opt/airflow/dags/bank_data_dag.py
Traceback (most recent call last):
  File "/home/airflow/.local/lib/python3.9/site-packages/airflow/models/dagbag.py", line 344, in parse
    loader.exec_module(new_module)
  File "<frozen importlib._bootstrap_external>", line 850, in exec_module
  File "<frozen importlib._bootstrap>", line 228, in _call_with_frames_removed
  File "/opt/airflow/dags/bank_data_dag.py", line 15, in <module>
    generate_bank_data = DockerOperator(
  File "/home/airflow/.local/lib/python3.9/site-packages/airflow/models/baseoperator.py", line 437, in apply_defaults
    result = func(self, **kwargs, default_args=default_args)
  File "/home/airflow/.local/lib/python3.9/site-packages/airflow/providers/docker/operators/docker.py", line 265, in __init__
    super().__init__(**kwargs)
  File "/home/airflow/.local/lib/python3.9/site-packages/airflow/models/baseoperator.py", line 437, in apply_defaults
    result = func(self, **kwargs, default_args=default_args)
  File "/home/airflow/.local/lib/python3.9/site-packages/airflow/models/baseoperator.py", line 793, in __init__
    raise AirflowException(
airflow.exceptions.AirflowException: Invalid arguments were passed to DockerOperator (task_id: generate_bank_data). Invalid arguments were:
**kwargs: {'volumes': ['/your/local/path/to/arlequin/scripts:/scripts', '/your/local/path/to/arlequin/hadoop-base/hadoop-conf:/opt/hadoop/etc/hadoop']}
[2025-08-04T23:30:19.898+0000] {processor.py:842} WARNING - No viable dags retrieved from /opt/airflow/dags/bank_data_dag.py
[2025-08-04T23:30:19.944+0000] {processor.py:183} INFO - Processing /opt/airflow/dags/bank_data_dag.py took 0.179 seconds
[2025-08-04T23:30:50.039+0000] {processor.py:161} INFO - Started process (PID=54) to work on /opt/airflow/dags/bank_data_dag.py
[2025-08-04T23:30:50.040+0000] {processor.py:830} INFO - Processing file /opt/airflow/dags/bank_data_dag.py for tasks to queue
[2025-08-04T23:30:50.044+0000] {logging_mixin.py:188} INFO - [2025-08-04T23:30:50.043+0000] {dagbag.py:538} INFO - Filling up the DagBag from /opt/airflow/dags/bank_data_dag.py
[2025-08-04T23:30:50.070+0000] {logging_mixin.py:188} INFO - [2025-08-04T23:30:50.065+0000] {dagbag.py:348} ERROR - Failed to import: /opt/airflow/dags/bank_data_dag.py
Traceback (most recent call last):
  File "/home/airflow/.local/lib/python3.9/site-packages/airflow/models/dagbag.py", line 344, in parse
    loader.exec_module(new_module)
  File "<frozen importlib._bootstrap_external>", line 850, in exec_module
  File "<frozen importlib._bootstrap>", line 228, in _call_with_frames_removed
  File "/opt/airflow/dags/bank_data_dag.py", line 15, in <module>
    generate_bank_data = DockerOperator(
  File "/home/airflow/.local/lib/python3.9/site-packages/airflow/models/baseoperator.py", line 437, in apply_defaults
    result = func(self, **kwargs, default_args=default_args)
  File "/home/airflow/.local/lib/python3.9/site-packages/airflow/providers/docker/operators/docker.py", line 265, in __init__
    super().__init__(**kwargs)
  File "/home/airflow/.local/lib/python3.9/site-packages/airflow/models/baseoperator.py", line 437, in apply_defaults
    result = func(self, **kwargs, default_args=default_args)
  File "/home/airflow/.local/lib/python3.9/site-packages/airflow/models/baseoperator.py", line 793, in __init__
    raise AirflowException(
airflow.exceptions.AirflowException: Invalid arguments were passed to DockerOperator (task_id: generate_bank_data). Invalid arguments were:
**kwargs: {'volumes': ['/your/local/path/to/arlequin/scripts:/scripts', '/your/local/path/to/arlequin/hadoop-base/hadoop-conf:/opt/hadoop/etc/hadoop']}
[2025-08-04T23:30:50.071+0000] {processor.py:842} WARNING - No viable dags retrieved from /opt/airflow/dags/bank_data_dag.py
[2025-08-04T23:30:50.102+0000] {processor.py:183} INFO - Processing /opt/airflow/dags/bank_data_dag.py took 0.067 seconds
[2025-08-04T23:31:20.271+0000] {processor.py:161} INFO - Started process (PID=55) to work on /opt/airflow/dags/bank_data_dag.py
[2025-08-04T23:31:20.272+0000] {processor.py:830} INFO - Processing file /opt/airflow/dags/bank_data_dag.py for tasks to queue
[2025-08-04T23:31:20.275+0000] {logging_mixin.py:188} INFO - [2025-08-04T23:31:20.275+0000] {dagbag.py:538} INFO - Filling up the DagBag from /opt/airflow/dags/bank_data_dag.py
[2025-08-04T23:31:20.306+0000] {logging_mixin.py:188} INFO - [2025-08-04T23:31:20.295+0000] {dagbag.py:348} ERROR - Failed to import: /opt/airflow/dags/bank_data_dag.py
Traceback (most recent call last):
  File "/home/airflow/.local/lib/python3.9/site-packages/airflow/models/dagbag.py", line 344, in parse
    loader.exec_module(new_module)
  File "<frozen importlib._bootstrap_external>", line 850, in exec_module
  File "<frozen importlib._bootstrap>", line 228, in _call_with_frames_removed
  File "/opt/airflow/dags/bank_data_dag.py", line 15, in <module>
    generate_bank_data = DockerOperator(
  File "/home/airflow/.local/lib/python3.9/site-packages/airflow/models/baseoperator.py", line 437, in apply_defaults
    result = func(self, **kwargs, default_args=default_args)
  File "/home/airflow/.local/lib/python3.9/site-packages/airflow/providers/docker/operators/docker.py", line 265, in __init__
    super().__init__(**kwargs)
  File "/home/airflow/.local/lib/python3.9/site-packages/airflow/models/baseoperator.py", line 437, in apply_defaults
    result = func(self, **kwargs, default_args=default_args)
  File "/home/airflow/.local/lib/python3.9/site-packages/airflow/models/baseoperator.py", line 793, in __init__
    raise AirflowException(
airflow.exceptions.AirflowException: Invalid arguments were passed to DockerOperator (task_id: generate_bank_data). Invalid arguments were:
**kwargs: {'volumes': ['/your/local/path/to/arlequin/scripts:/scripts', '/your/local/path/to/arlequin/hadoop-base/hadoop-conf:/opt/hadoop/etc/hadoop']}
[2025-08-04T23:31:20.307+0000] {processor.py:842} WARNING - No viable dags retrieved from /opt/airflow/dags/bank_data_dag.py
[2025-08-04T23:31:20.335+0000] {processor.py:183} INFO - Processing /opt/airflow/dags/bank_data_dag.py took 0.067 seconds
[2025-08-04T23:31:50.606+0000] {processor.py:161} INFO - Started process (PID=56) to work on /opt/airflow/dags/bank_data_dag.py
[2025-08-04T23:31:50.608+0000] {processor.py:830} INFO - Processing file /opt/airflow/dags/bank_data_dag.py for tasks to queue
[2025-08-04T23:31:50.618+0000] {logging_mixin.py:188} INFO - [2025-08-04T23:31:50.617+0000] {dagbag.py:538} INFO - Filling up the DagBag from /opt/airflow/dags/bank_data_dag.py
[2025-08-04T23:31:50.680+0000] {logging_mixin.py:188} INFO - [2025-08-04T23:31:50.673+0000] {dagbag.py:348} ERROR - Failed to import: /opt/airflow/dags/bank_data_dag.py
Traceback (most recent call last):
  File "/home/airflow/.local/lib/python3.9/site-packages/airflow/models/dagbag.py", line 344, in parse
    loader.exec_module(new_module)
  File "<frozen importlib._bootstrap_external>", line 850, in exec_module
  File "<frozen importlib._bootstrap>", line 228, in _call_with_frames_removed
  File "/opt/airflow/dags/bank_data_dag.py", line 15, in <module>
    generate_bank_data = DockerOperator(
  File "/home/airflow/.local/lib/python3.9/site-packages/airflow/models/baseoperator.py", line 437, in apply_defaults
    result = func(self, **kwargs, default_args=default_args)
  File "/home/airflow/.local/lib/python3.9/site-packages/airflow/providers/docker/operators/docker.py", line 265, in __init__
    super().__init__(**kwargs)
  File "/home/airflow/.local/lib/python3.9/site-packages/airflow/models/baseoperator.py", line 437, in apply_defaults
    result = func(self, **kwargs, default_args=default_args)
  File "/home/airflow/.local/lib/python3.9/site-packages/airflow/models/baseoperator.py", line 793, in __init__
    raise AirflowException(
airflow.exceptions.AirflowException: Invalid arguments were passed to DockerOperator (task_id: generate_bank_data). Invalid arguments were:
**kwargs: {'volumes': ['/your/local/path/to/arlequin/scripts:/scripts', '/your/local/path/to/arlequin/hadoop-base/hadoop-conf:/opt/hadoop/etc/hadoop']}
[2025-08-04T23:31:50.681+0000] {processor.py:842} WARNING - No viable dags retrieved from /opt/airflow/dags/bank_data_dag.py
[2025-08-04T23:31:50.714+0000] {processor.py:183} INFO - Processing /opt/airflow/dags/bank_data_dag.py took 0.114 seconds
[2025-08-04T23:32:20.847+0000] {processor.py:161} INFO - Started process (PID=57) to work on /opt/airflow/dags/bank_data_dag.py
[2025-08-04T23:32:20.849+0000] {processor.py:830} INFO - Processing file /opt/airflow/dags/bank_data_dag.py for tasks to queue
[2025-08-04T23:32:20.852+0000] {logging_mixin.py:188} INFO - [2025-08-04T23:32:20.851+0000] {dagbag.py:538} INFO - Filling up the DagBag from /opt/airflow/dags/bank_data_dag.py
[2025-08-04T23:32:20.903+0000] {logging_mixin.py:188} INFO - [2025-08-04T23:32:20.897+0000] {dagbag.py:348} ERROR - Failed to import: /opt/airflow/dags/bank_data_dag.py
Traceback (most recent call last):
  File "/home/airflow/.local/lib/python3.9/site-packages/airflow/models/dagbag.py", line 344, in parse
    loader.exec_module(new_module)
  File "<frozen importlib._bootstrap_external>", line 850, in exec_module
  File "<frozen importlib._bootstrap>", line 228, in _call_with_frames_removed
  File "/opt/airflow/dags/bank_data_dag.py", line 15, in <module>
    generate_bank_data = DockerOperator(
  File "/home/airflow/.local/lib/python3.9/site-packages/airflow/models/baseoperator.py", line 437, in apply_defaults
    result = func(self, **kwargs, default_args=default_args)
  File "/home/airflow/.local/lib/python3.9/site-packages/airflow/providers/docker/operators/docker.py", line 265, in __init__
    super().__init__(**kwargs)
  File "/home/airflow/.local/lib/python3.9/site-packages/airflow/models/baseoperator.py", line 437, in apply_defaults
    result = func(self, **kwargs, default_args=default_args)
  File "/home/airflow/.local/lib/python3.9/site-packages/airflow/models/baseoperator.py", line 793, in __init__
    raise AirflowException(
airflow.exceptions.AirflowException: Invalid arguments were passed to DockerOperator (task_id: generate_bank_data). Invalid arguments were:
**kwargs: {'volumes': ['/your/local/path/to/arlequin/scripts:/scripts', '/your/local/path/to/arlequin/hadoop-base/hadoop-conf:/opt/hadoop/etc/hadoop']}
[2025-08-04T23:32:20.904+0000] {processor.py:842} WARNING - No viable dags retrieved from /opt/airflow/dags/bank_data_dag.py
[2025-08-04T23:32:21.042+0000] {processor.py:183} INFO - Processing /opt/airflow/dags/bank_data_dag.py took 0.199 seconds
[2025-08-04T23:32:51.239+0000] {processor.py:161} INFO - Started process (PID=58) to work on /opt/airflow/dags/bank_data_dag.py
[2025-08-04T23:32:51.241+0000] {processor.py:830} INFO - Processing file /opt/airflow/dags/bank_data_dag.py for tasks to queue
[2025-08-04T23:32:51.243+0000] {logging_mixin.py:188} INFO - [2025-08-04T23:32:51.243+0000] {dagbag.py:538} INFO - Filling up the DagBag from /opt/airflow/dags/bank_data_dag.py
[2025-08-04T23:32:51.269+0000] {logging_mixin.py:188} INFO - [2025-08-04T23:32:51.263+0000] {dagbag.py:348} ERROR - Failed to import: /opt/airflow/dags/bank_data_dag.py
Traceback (most recent call last):
  File "/home/airflow/.local/lib/python3.9/site-packages/airflow/models/dagbag.py", line 344, in parse
    loader.exec_module(new_module)
  File "<frozen importlib._bootstrap_external>", line 850, in exec_module
  File "<frozen importlib._bootstrap>", line 228, in _call_with_frames_removed
  File "/opt/airflow/dags/bank_data_dag.py", line 15, in <module>
    generate_bank_data = DockerOperator(
  File "/home/airflow/.local/lib/python3.9/site-packages/airflow/models/baseoperator.py", line 437, in apply_defaults
    result = func(self, **kwargs, default_args=default_args)
  File "/home/airflow/.local/lib/python3.9/site-packages/airflow/providers/docker/operators/docker.py", line 265, in __init__
    super().__init__(**kwargs)
  File "/home/airflow/.local/lib/python3.9/site-packages/airflow/models/baseoperator.py", line 437, in apply_defaults
    result = func(self, **kwargs, default_args=default_args)
  File "/home/airflow/.local/lib/python3.9/site-packages/airflow/models/baseoperator.py", line 793, in __init__
    raise AirflowException(
airflow.exceptions.AirflowException: Invalid arguments were passed to DockerOperator (task_id: generate_bank_data). Invalid arguments were:
**kwargs: {'volumes': ['/your/local/path/to/arlequin/scripts:/scripts', '/your/local/path/to/arlequin/hadoop-base/hadoop-conf:/opt/hadoop/etc/hadoop']}
[2025-08-04T23:32:51.270+0000] {processor.py:842} WARNING - No viable dags retrieved from /opt/airflow/dags/bank_data_dag.py
[2025-08-04T23:32:51.310+0000] {processor.py:183} INFO - Processing /opt/airflow/dags/bank_data_dag.py took 0.074 seconds
[2025-08-04T23:33:21.548+0000] {processor.py:161} INFO - Started process (PID=59) to work on /opt/airflow/dags/bank_data_dag.py
[2025-08-04T23:33:21.550+0000] {processor.py:830} INFO - Processing file /opt/airflow/dags/bank_data_dag.py for tasks to queue
[2025-08-04T23:33:21.552+0000] {logging_mixin.py:188} INFO - [2025-08-04T23:33:21.552+0000] {dagbag.py:538} INFO - Filling up the DagBag from /opt/airflow/dags/bank_data_dag.py
[2025-08-04T23:33:21.580+0000] {logging_mixin.py:188} INFO - [2025-08-04T23:33:21.574+0000] {dagbag.py:348} ERROR - Failed to import: /opt/airflow/dags/bank_data_dag.py
Traceback (most recent call last):
  File "/home/airflow/.local/lib/python3.9/site-packages/airflow/models/dagbag.py", line 344, in parse
    loader.exec_module(new_module)
  File "<frozen importlib._bootstrap_external>", line 850, in exec_module
  File "<frozen importlib._bootstrap>", line 228, in _call_with_frames_removed
  File "/opt/airflow/dags/bank_data_dag.py", line 15, in <module>
    generate_bank_data = DockerOperator(
  File "/home/airflow/.local/lib/python3.9/site-packages/airflow/models/baseoperator.py", line 437, in apply_defaults
    result = func(self, **kwargs, default_args=default_args)
  File "/home/airflow/.local/lib/python3.9/site-packages/airflow/providers/docker/operators/docker.py", line 265, in __init__
    super().__init__(**kwargs)
  File "/home/airflow/.local/lib/python3.9/site-packages/airflow/models/baseoperator.py", line 437, in apply_defaults
    result = func(self, **kwargs, default_args=default_args)
  File "/home/airflow/.local/lib/python3.9/site-packages/airflow/models/baseoperator.py", line 793, in __init__
    raise AirflowException(
airflow.exceptions.AirflowException: Invalid arguments were passed to DockerOperator (task_id: generate_bank_data). Invalid arguments were:
**kwargs: {'volumes': ['/your/local/path/to/arlequin/scripts:/scripts', '/your/local/path/to/arlequin/hadoop-base/hadoop-conf:/opt/hadoop/etc/hadoop']}
[2025-08-04T23:33:21.581+0000] {processor.py:842} WARNING - No viable dags retrieved from /opt/airflow/dags/bank_data_dag.py
[2025-08-04T23:33:21.605+0000] {processor.py:183} INFO - Processing /opt/airflow/dags/bank_data_dag.py took 0.059 seconds
[2025-08-04T23:33:51.792+0000] {processor.py:161} INFO - Started process (PID=60) to work on /opt/airflow/dags/bank_data_dag.py
[2025-08-04T23:33:51.795+0000] {processor.py:830} INFO - Processing file /opt/airflow/dags/bank_data_dag.py for tasks to queue
[2025-08-04T23:33:51.798+0000] {logging_mixin.py:188} INFO - [2025-08-04T23:33:51.797+0000] {dagbag.py:538} INFO - Filling up the DagBag from /opt/airflow/dags/bank_data_dag.py
[2025-08-04T23:33:51.828+0000] {logging_mixin.py:188} INFO - [2025-08-04T23:33:51.821+0000] {dagbag.py:348} ERROR - Failed to import: /opt/airflow/dags/bank_data_dag.py
Traceback (most recent call last):
  File "/home/airflow/.local/lib/python3.9/site-packages/airflow/models/dagbag.py", line 344, in parse
    loader.exec_module(new_module)
  File "<frozen importlib._bootstrap_external>", line 850, in exec_module
  File "<frozen importlib._bootstrap>", line 228, in _call_with_frames_removed
  File "/opt/airflow/dags/bank_data_dag.py", line 15, in <module>
    generate_bank_data = DockerOperator(
  File "/home/airflow/.local/lib/python3.9/site-packages/airflow/models/baseoperator.py", line 437, in apply_defaults
    result = func(self, **kwargs, default_args=default_args)
  File "/home/airflow/.local/lib/python3.9/site-packages/airflow/providers/docker/operators/docker.py", line 265, in __init__
    super().__init__(**kwargs)
  File "/home/airflow/.local/lib/python3.9/site-packages/airflow/models/baseoperator.py", line 437, in apply_defaults
    result = func(self, **kwargs, default_args=default_args)
  File "/home/airflow/.local/lib/python3.9/site-packages/airflow/models/baseoperator.py", line 793, in __init__
    raise AirflowException(
airflow.exceptions.AirflowException: Invalid arguments were passed to DockerOperator (task_id: generate_bank_data). Invalid arguments were:
**kwargs: {'volumes': ['/your/local/path/to/arlequin/scripts:/scripts', '/your/local/path/to/arlequin/hadoop-base/hadoop-conf:/opt/hadoop/etc/hadoop']}
[2025-08-04T23:33:51.829+0000] {processor.py:842} WARNING - No viable dags retrieved from /opt/airflow/dags/bank_data_dag.py
[2025-08-04T23:33:51.859+0000] {processor.py:183} INFO - Processing /opt/airflow/dags/bank_data_dag.py took 0.070 seconds
[2025-08-04T23:34:22.055+0000] {processor.py:161} INFO - Started process (PID=61) to work on /opt/airflow/dags/bank_data_dag.py
[2025-08-04T23:34:22.057+0000] {processor.py:830} INFO - Processing file /opt/airflow/dags/bank_data_dag.py for tasks to queue
[2025-08-04T23:34:22.059+0000] {logging_mixin.py:188} INFO - [2025-08-04T23:34:22.059+0000] {dagbag.py:538} INFO - Filling up the DagBag from /opt/airflow/dags/bank_data_dag.py
[2025-08-04T23:34:22.078+0000] {logging_mixin.py:188} INFO - [2025-08-04T23:34:22.074+0000] {dagbag.py:348} ERROR - Failed to import: /opt/airflow/dags/bank_data_dag.py
Traceback (most recent call last):
  File "/home/airflow/.local/lib/python3.9/site-packages/airflow/models/dagbag.py", line 344, in parse
    loader.exec_module(new_module)
  File "<frozen importlib._bootstrap_external>", line 850, in exec_module
  File "<frozen importlib._bootstrap>", line 228, in _call_with_frames_removed
  File "/opt/airflow/dags/bank_data_dag.py", line 15, in <module>
    generate_bank_data = DockerOperator(
  File "/home/airflow/.local/lib/python3.9/site-packages/airflow/models/baseoperator.py", line 437, in apply_defaults
    result = func(self, **kwargs, default_args=default_args)
  File "/home/airflow/.local/lib/python3.9/site-packages/airflow/providers/docker/operators/docker.py", line 265, in __init__
    super().__init__(**kwargs)
  File "/home/airflow/.local/lib/python3.9/site-packages/airflow/models/baseoperator.py", line 437, in apply_defaults
    result = func(self, **kwargs, default_args=default_args)
  File "/home/airflow/.local/lib/python3.9/site-packages/airflow/models/baseoperator.py", line 793, in __init__
    raise AirflowException(
airflow.exceptions.AirflowException: Invalid arguments were passed to DockerOperator (task_id: generate_bank_data). Invalid arguments were:
**kwargs: {'volumes': ['/your/local/path/to/arlequin/scripts:/scripts', '/your/local/path/to/arlequin/hadoop-base/hadoop-conf:/opt/hadoop/etc/hadoop']}
[2025-08-04T23:34:22.079+0000] {processor.py:842} WARNING - No viable dags retrieved from /opt/airflow/dags/bank_data_dag.py
[2025-08-04T23:34:22.117+0000] {processor.py:183} INFO - Processing /opt/airflow/dags/bank_data_dag.py took 0.064 seconds
[2025-08-04T23:34:52.304+0000] {processor.py:161} INFO - Started process (PID=62) to work on /opt/airflow/dags/bank_data_dag.py
[2025-08-04T23:34:52.305+0000] {processor.py:830} INFO - Processing file /opt/airflow/dags/bank_data_dag.py for tasks to queue
[2025-08-04T23:34:52.308+0000] {logging_mixin.py:188} INFO - [2025-08-04T23:34:52.307+0000] {dagbag.py:538} INFO - Filling up the DagBag from /opt/airflow/dags/bank_data_dag.py
[2025-08-04T23:34:52.326+0000] {logging_mixin.py:188} INFO - [2025-08-04T23:34:52.321+0000] {dagbag.py:348} ERROR - Failed to import: /opt/airflow/dags/bank_data_dag.py
Traceback (most recent call last):
  File "/home/airflow/.local/lib/python3.9/site-packages/airflow/models/dagbag.py", line 344, in parse
    loader.exec_module(new_module)
  File "<frozen importlib._bootstrap_external>", line 850, in exec_module
  File "<frozen importlib._bootstrap>", line 228, in _call_with_frames_removed
  File "/opt/airflow/dags/bank_data_dag.py", line 15, in <module>
    generate_bank_data = DockerOperator(
  File "/home/airflow/.local/lib/python3.9/site-packages/airflow/models/baseoperator.py", line 437, in apply_defaults
    result = func(self, **kwargs, default_args=default_args)
  File "/home/airflow/.local/lib/python3.9/site-packages/airflow/providers/docker/operators/docker.py", line 265, in __init__
    super().__init__(**kwargs)
  File "/home/airflow/.local/lib/python3.9/site-packages/airflow/models/baseoperator.py", line 437, in apply_defaults
    result = func(self, **kwargs, default_args=default_args)
  File "/home/airflow/.local/lib/python3.9/site-packages/airflow/models/baseoperator.py", line 793, in __init__
    raise AirflowException(
airflow.exceptions.AirflowException: Invalid arguments were passed to DockerOperator (task_id: generate_bank_data). Invalid arguments were:
**kwargs: {'volumes': ['/your/local/path/to/arlequin/scripts:/scripts', '/your/local/path/to/arlequin/hadoop-base/hadoop-conf:/opt/hadoop/etc/hadoop']}
[2025-08-04T23:34:52.327+0000] {processor.py:842} WARNING - No viable dags retrieved from /opt/airflow/dags/bank_data_dag.py
[2025-08-04T23:34:52.352+0000] {processor.py:183} INFO - Processing /opt/airflow/dags/bank_data_dag.py took 0.052 seconds
[2025-08-04T23:35:22.558+0000] {processor.py:161} INFO - Started process (PID=63) to work on /opt/airflow/dags/bank_data_dag.py
[2025-08-04T23:35:22.559+0000] {processor.py:830} INFO - Processing file /opt/airflow/dags/bank_data_dag.py for tasks to queue
[2025-08-04T23:35:22.561+0000] {logging_mixin.py:188} INFO - [2025-08-04T23:35:22.561+0000] {dagbag.py:538} INFO - Filling up the DagBag from /opt/airflow/dags/bank_data_dag.py
[2025-08-04T23:35:22.584+0000] {logging_mixin.py:188} INFO - [2025-08-04T23:35:22.579+0000] {dagbag.py:348} ERROR - Failed to import: /opt/airflow/dags/bank_data_dag.py
Traceback (most recent call last):
  File "/home/airflow/.local/lib/python3.9/site-packages/airflow/models/dagbag.py", line 344, in parse
    loader.exec_module(new_module)
  File "<frozen importlib._bootstrap_external>", line 850, in exec_module
  File "<frozen importlib._bootstrap>", line 228, in _call_with_frames_removed
  File "/opt/airflow/dags/bank_data_dag.py", line 15, in <module>
    generate_bank_data = DockerOperator(
  File "/home/airflow/.local/lib/python3.9/site-packages/airflow/models/baseoperator.py", line 437, in apply_defaults
    result = func(self, **kwargs, default_args=default_args)
  File "/home/airflow/.local/lib/python3.9/site-packages/airflow/providers/docker/operators/docker.py", line 265, in __init__
    super().__init__(**kwargs)
  File "/home/airflow/.local/lib/python3.9/site-packages/airflow/models/baseoperator.py", line 437, in apply_defaults
    result = func(self, **kwargs, default_args=default_args)
  File "/home/airflow/.local/lib/python3.9/site-packages/airflow/models/baseoperator.py", line 793, in __init__
    raise AirflowException(
airflow.exceptions.AirflowException: Invalid arguments were passed to DockerOperator (task_id: generate_bank_data). Invalid arguments were:
**kwargs: {'volumes': ['/your/local/path/to/arlequin/scripts:/scripts', '/your/local/path/to/arlequin/hadoop-base/hadoop-conf:/opt/hadoop/etc/hadoop']}
[2025-08-04T23:35:22.584+0000] {processor.py:842} WARNING - No viable dags retrieved from /opt/airflow/dags/bank_data_dag.py
[2025-08-04T23:35:22.620+0000] {processor.py:183} INFO - Processing /opt/airflow/dags/bank_data_dag.py took 0.065 seconds
[2025-08-04T23:35:52.818+0000] {processor.py:161} INFO - Started process (PID=64) to work on /opt/airflow/dags/bank_data_dag.py
[2025-08-04T23:35:52.820+0000] {processor.py:830} INFO - Processing file /opt/airflow/dags/bank_data_dag.py for tasks to queue
[2025-08-04T23:35:52.827+0000] {logging_mixin.py:188} INFO - [2025-08-04T23:35:52.826+0000] {dagbag.py:538} INFO - Filling up the DagBag from /opt/airflow/dags/bank_data_dag.py
[2025-08-04T23:35:52.858+0000] {logging_mixin.py:188} INFO - [2025-08-04T23:35:52.852+0000] {dagbag.py:348} ERROR - Failed to import: /opt/airflow/dags/bank_data_dag.py
Traceback (most recent call last):
  File "/home/airflow/.local/lib/python3.9/site-packages/airflow/models/dagbag.py", line 344, in parse
    loader.exec_module(new_module)
  File "<frozen importlib._bootstrap_external>", line 850, in exec_module
  File "<frozen importlib._bootstrap>", line 228, in _call_with_frames_removed
  File "/opt/airflow/dags/bank_data_dag.py", line 15, in <module>
    generate_bank_data = DockerOperator(
  File "/home/airflow/.local/lib/python3.9/site-packages/airflow/models/baseoperator.py", line 437, in apply_defaults
    result = func(self, **kwargs, default_args=default_args)
  File "/home/airflow/.local/lib/python3.9/site-packages/airflow/providers/docker/operators/docker.py", line 265, in __init__
    super().__init__(**kwargs)
  File "/home/airflow/.local/lib/python3.9/site-packages/airflow/models/baseoperator.py", line 437, in apply_defaults
    result = func(self, **kwargs, default_args=default_args)
  File "/home/airflow/.local/lib/python3.9/site-packages/airflow/models/baseoperator.py", line 793, in __init__
    raise AirflowException(
airflow.exceptions.AirflowException: Invalid arguments were passed to DockerOperator (task_id: generate_bank_data). Invalid arguments were:
**kwargs: {'volumes': ['/your/local/path/to/arlequin/scripts:/scripts', '/your/local/path/to/arlequin/hadoop-base/hadoop-conf:/opt/hadoop/etc/hadoop']}
[2025-08-04T23:35:52.859+0000] {processor.py:842} WARNING - No viable dags retrieved from /opt/airflow/dags/bank_data_dag.py
[2025-08-04T23:35:53.120+0000] {processor.py:183} INFO - Processing /opt/airflow/dags/bank_data_dag.py took 0.309 seconds
[2025-08-04T23:57:27.343+0000] {processor.py:161} INFO - Started process (PID=65) to work on /opt/airflow/dags/bank_data_dag.py
[2025-08-04T23:57:27.359+0000] {processor.py:830} INFO - Processing file /opt/airflow/dags/bank_data_dag.py for tasks to queue
[2025-08-04T23:57:27.394+0000] {logging_mixin.py:188} INFO - [2025-08-04T23:57:27.388+0000] {dagbag.py:538} INFO - Filling up the DagBag from /opt/airflow/dags/bank_data_dag.py
[2025-08-04T23:57:27.529+0000] {logging_mixin.py:188} INFO - [2025-08-04T23:57:27.509+0000] {dagbag.py:348} ERROR - Failed to import: /opt/airflow/dags/bank_data_dag.py
Traceback (most recent call last):
  File "/home/airflow/.local/lib/python3.9/site-packages/airflow/models/dagbag.py", line 344, in parse
    loader.exec_module(new_module)
  File "<frozen importlib._bootstrap_external>", line 850, in exec_module
  File "<frozen importlib._bootstrap>", line 228, in _call_with_frames_removed
  File "/opt/airflow/dags/bank_data_dag.py", line 15, in <module>
    generate_bank_data = DockerOperator(
  File "/home/airflow/.local/lib/python3.9/site-packages/airflow/models/baseoperator.py", line 437, in apply_defaults
    result = func(self, **kwargs, default_args=default_args)
  File "/home/airflow/.local/lib/python3.9/site-packages/airflow/providers/docker/operators/docker.py", line 265, in __init__
    super().__init__(**kwargs)
  File "/home/airflow/.local/lib/python3.9/site-packages/airflow/models/baseoperator.py", line 437, in apply_defaults
    result = func(self, **kwargs, default_args=default_args)
  File "/home/airflow/.local/lib/python3.9/site-packages/airflow/models/baseoperator.py", line 793, in __init__
    raise AirflowException(
airflow.exceptions.AirflowException: Invalid arguments were passed to DockerOperator (task_id: generate_bank_data). Invalid arguments were:
**kwargs: {'volumes': ['/your/local/path/to/arlequin/scripts:/scripts', '/your/local/path/to/arlequin/hadoop-base/hadoop-conf:/opt/hadoop/etc/hadoop']}
[2025-08-04T23:57:27.534+0000] {processor.py:842} WARNING - No viable dags retrieved from /opt/airflow/dags/bank_data_dag.py
[2025-08-04T23:57:27.677+0000] {processor.py:183} INFO - Processing /opt/airflow/dags/bank_data_dag.py took 0.437 seconds
[2025-08-04T23:57:58.197+0000] {processor.py:161} INFO - Started process (PID=66) to work on /opt/airflow/dags/bank_data_dag.py
[2025-08-04T23:57:58.200+0000] {processor.py:830} INFO - Processing file /opt/airflow/dags/bank_data_dag.py for tasks to queue
[2025-08-04T23:57:58.214+0000] {logging_mixin.py:188} INFO - [2025-08-04T23:57:58.212+0000] {dagbag.py:538} INFO - Filling up the DagBag from /opt/airflow/dags/bank_data_dag.py
[2025-08-04T23:57:58.273+0000] {logging_mixin.py:188} INFO - [2025-08-04T23:57:58.263+0000] {dagbag.py:348} ERROR - Failed to import: /opt/airflow/dags/bank_data_dag.py
Traceback (most recent call last):
  File "/home/airflow/.local/lib/python3.9/site-packages/airflow/models/dagbag.py", line 344, in parse
    loader.exec_module(new_module)
  File "<frozen importlib._bootstrap_external>", line 850, in exec_module
  File "<frozen importlib._bootstrap>", line 228, in _call_with_frames_removed
  File "/opt/airflow/dags/bank_data_dag.py", line 15, in <module>
    generate_bank_data = DockerOperator(
  File "/home/airflow/.local/lib/python3.9/site-packages/airflow/models/baseoperator.py", line 437, in apply_defaults
    result = func(self, **kwargs, default_args=default_args)
  File "/home/airflow/.local/lib/python3.9/site-packages/airflow/providers/docker/operators/docker.py", line 265, in __init__
    super().__init__(**kwargs)
  File "/home/airflow/.local/lib/python3.9/site-packages/airflow/models/baseoperator.py", line 437, in apply_defaults
    result = func(self, **kwargs, default_args=default_args)
  File "/home/airflow/.local/lib/python3.9/site-packages/airflow/models/baseoperator.py", line 793, in __init__
    raise AirflowException(
airflow.exceptions.AirflowException: Invalid arguments were passed to DockerOperator (task_id: generate_bank_data). Invalid arguments were:
**kwargs: {'volumes': ['/your/local/path/to/arlequin/scripts:/scripts', '/your/local/path/to/arlequin/hadoop-base/hadoop-conf:/opt/hadoop/etc/hadoop']}
[2025-08-04T23:57:58.274+0000] {processor.py:842} WARNING - No viable dags retrieved from /opt/airflow/dags/bank_data_dag.py
[2025-08-04T23:57:58.347+0000] {processor.py:183} INFO - Processing /opt/airflow/dags/bank_data_dag.py took 0.170 seconds
[2025-08-04T23:58:28.756+0000] {processor.py:161} INFO - Started process (PID=67) to work on /opt/airflow/dags/bank_data_dag.py
[2025-08-04T23:58:28.757+0000] {processor.py:830} INFO - Processing file /opt/airflow/dags/bank_data_dag.py for tasks to queue
[2025-08-04T23:58:28.759+0000] {logging_mixin.py:188} INFO - [2025-08-04T23:58:28.759+0000] {dagbag.py:538} INFO - Filling up the DagBag from /opt/airflow/dags/bank_data_dag.py
[2025-08-04T23:58:28.833+0000] {logging_mixin.py:188} INFO - [2025-08-04T23:58:28.828+0000] {dagbag.py:348} ERROR - Failed to import: /opt/airflow/dags/bank_data_dag.py
Traceback (most recent call last):
  File "/home/airflow/.local/lib/python3.9/site-packages/airflow/models/dagbag.py", line 344, in parse
    loader.exec_module(new_module)
  File "<frozen importlib._bootstrap_external>", line 850, in exec_module
  File "<frozen importlib._bootstrap>", line 228, in _call_with_frames_removed
  File "/opt/airflow/dags/bank_data_dag.py", line 15, in <module>
    generate_bank_data = DockerOperator(
  File "/home/airflow/.local/lib/python3.9/site-packages/airflow/models/baseoperator.py", line 437, in apply_defaults
    result = func(self, **kwargs, default_args=default_args)
  File "/home/airflow/.local/lib/python3.9/site-packages/airflow/providers/docker/operators/docker.py", line 265, in __init__
    super().__init__(**kwargs)
  File "/home/airflow/.local/lib/python3.9/site-packages/airflow/models/baseoperator.py", line 437, in apply_defaults
    result = func(self, **kwargs, default_args=default_args)
  File "/home/airflow/.local/lib/python3.9/site-packages/airflow/models/baseoperator.py", line 793, in __init__
    raise AirflowException(
airflow.exceptions.AirflowException: Invalid arguments were passed to DockerOperator (task_id: generate_bank_data). Invalid arguments were:
**kwargs: {'volumes': ['/your/local/path/to/arlequin/scripts:/scripts', '/your/local/path/to/arlequin/hadoop-base/hadoop-conf:/opt/hadoop/etc/hadoop']}
[2025-08-04T23:58:28.834+0000] {processor.py:842} WARNING - No viable dags retrieved from /opt/airflow/dags/bank_data_dag.py
[2025-08-04T23:58:28.995+0000] {processor.py:183} INFO - Processing /opt/airflow/dags/bank_data_dag.py took 0.243 seconds
[2025-08-04T23:58:59.226+0000] {processor.py:161} INFO - Started process (PID=68) to work on /opt/airflow/dags/bank_data_dag.py
[2025-08-04T23:58:59.228+0000] {processor.py:830} INFO - Processing file /opt/airflow/dags/bank_data_dag.py for tasks to queue
[2025-08-04T23:58:59.231+0000] {logging_mixin.py:188} INFO - [2025-08-04T23:58:59.231+0000] {dagbag.py:538} INFO - Filling up the DagBag from /opt/airflow/dags/bank_data_dag.py
[2025-08-04T23:58:59.258+0000] {logging_mixin.py:188} INFO - [2025-08-04T23:58:59.251+0000] {dagbag.py:348} ERROR - Failed to import: /opt/airflow/dags/bank_data_dag.py
Traceback (most recent call last):
  File "/home/airflow/.local/lib/python3.9/site-packages/airflow/models/dagbag.py", line 344, in parse
    loader.exec_module(new_module)
  File "<frozen importlib._bootstrap_external>", line 850, in exec_module
  File "<frozen importlib._bootstrap>", line 228, in _call_with_frames_removed
  File "/opt/airflow/dags/bank_data_dag.py", line 15, in <module>
    generate_bank_data = DockerOperator(
  File "/home/airflow/.local/lib/python3.9/site-packages/airflow/models/baseoperator.py", line 437, in apply_defaults
    result = func(self, **kwargs, default_args=default_args)
  File "/home/airflow/.local/lib/python3.9/site-packages/airflow/providers/docker/operators/docker.py", line 265, in __init__
    super().__init__(**kwargs)
  File "/home/airflow/.local/lib/python3.9/site-packages/airflow/models/baseoperator.py", line 437, in apply_defaults
    result = func(self, **kwargs, default_args=default_args)
  File "/home/airflow/.local/lib/python3.9/site-packages/airflow/models/baseoperator.py", line 793, in __init__
    raise AirflowException(
airflow.exceptions.AirflowException: Invalid arguments were passed to DockerOperator (task_id: generate_bank_data). Invalid arguments were:
**kwargs: {'volumes': ['/your/local/path/to/arlequin/scripts:/scripts', '/your/local/path/to/arlequin/hadoop-base/hadoop-conf:/opt/hadoop/etc/hadoop']}
[2025-08-04T23:58:59.259+0000] {processor.py:842} WARNING - No viable dags retrieved from /opt/airflow/dags/bank_data_dag.py
[2025-08-04T23:58:59.287+0000] {processor.py:183} INFO - Processing /opt/airflow/dags/bank_data_dag.py took 0.064 seconds
