[2025-08-13T13:49:09.330+0000] {taskinstance.py:1956} INFO - Dependencies all met for dep_context=non-requeueable deps ti=<TaskInstance: bank_data_generation_dag.generate_bank_data manual__2025-08-13T13:49:05.248545+00:00 [queued]>
[2025-08-13T13:49:09.356+0000] {taskinstance.py:1956} INFO - Dependencies all met for dep_context=requeueable deps ti=<TaskInstance: bank_data_generation_dag.generate_bank_data manual__2025-08-13T13:49:05.248545+00:00 [queued]>
[2025-08-13T13:49:09.357+0000] {taskinstance.py:2170} INFO - Starting attempt 1 of 1
[2025-08-13T13:49:09.387+0000] {taskinstance.py:2191} INFO - Executing <Task(DockerOperator): generate_bank_data> on 2025-08-13 13:49:05.248545+00:00
[2025-08-13T13:49:09.402+0000] {standard_task_runner.py:60} INFO - Started process 52 to run task
[2025-08-13T13:49:09.409+0000] {standard_task_runner.py:87} INFO - Running: ['***', 'tasks', 'run', 'bank_data_generation_dag', 'generate_bank_data', 'manual__2025-08-13T13:49:05.248545+00:00', '--job-id', '3', '--raw', '--subdir', 'DAGS_FOLDER/bank_data_dag.py', '--cfg-path', '/tmp/tmpa6d5tbny']
[2025-08-13T13:49:09.414+0000] {standard_task_runner.py:88} INFO - Job 3: Subtask generate_bank_data
[2025-08-13T13:49:09.458+0000] {warnings.py:109} WARNING - /home/***/.local/lib/python3.9/site-packages/***/settings.py:194: DeprecationWarning: The sql_alchemy_conn option in [core] has been moved to the sql_alchemy_conn option in [database] - the old setting has been used, but please update your config.
  SQL_ALCHEMY_CONN = conf.get("database", "SQL_ALCHEMY_CONN")

[2025-08-13T13:49:09.524+0000] {task_command.py:423} INFO - Running <TaskInstance: bank_data_generation_dag.generate_bank_data manual__2025-08-13T13:49:05.248545+00:00 [running]> on host e096652e1243
[2025-08-13T13:49:09.712+0000] {taskinstance.py:2480} INFO - Exporting env vars: AIRFLOW_CTX_DAG_OWNER='***' AIRFLOW_CTX_DAG_ID='bank_data_generation_dag' AIRFLOW_CTX_TASK_ID='generate_bank_data' AIRFLOW_CTX_EXECUTION_DATE='2025-08-13T13:49:05.248545+00:00' AIRFLOW_CTX_TRY_NUMBER='1' AIRFLOW_CTX_DAG_RUN_ID='manual__2025-08-13T13:49:05.248545+00:00'
[2025-08-13T13:49:10.017+0000] {docker.py:359} INFO - Starting docker container from image arlequin-pyspark-client
[2025-08-13T13:49:11.420+0000] {taskinstance.py:2698} ERROR - Task failed with exception
Traceback (most recent call last):
  File "/home/airflow/.local/lib/python3.9/site-packages/docker/api/client.py", line 265, in _raise_for_status
    response.raise_for_status()
  File "/home/airflow/.local/lib/python3.9/site-packages/requests/models.py", line 1021, in raise_for_status
    raise HTTPError(http_error_msg, response=self)
requests.exceptions.HTTPError: 400 Client Error: Bad Request for url: http+docker://localhost/v1.51/containers/de0ec0d342b9333739260436caced1383bb909b369a351462ce110db1aef4b49/start

The above exception was the direct cause of the following exception:

Traceback (most recent call last):
  File "/home/airflow/.local/lib/python3.9/site-packages/airflow/models/taskinstance.py", line 433, in _execute_task
    result = execute_callable(context=context, **execute_callable_kwargs)
  File "/home/airflow/.local/lib/python3.9/site-packages/airflow/providers/docker/operators/docker.py", line 502, in execute
    return self._run_image()
  File "/home/airflow/.local/lib/python3.9/site-packages/airflow/providers/docker/operators/docker.py", line 376, in _run_image
    return self._run_image_with_mounts(self.mounts, add_tmp_variable=False)
  File "/home/airflow/.local/lib/python3.9/site-packages/airflow/providers/docker/operators/docker.py", line 423, in _run_image_with_mounts
    self.cli.start(self.container["Id"])
  File "/home/airflow/.local/lib/python3.9/site-packages/docker/utils/decorators.py", line 19, in wrapped
    return f(self, resource_id, *args, **kwargs)
  File "/home/airflow/.local/lib/python3.9/site-packages/docker/api/container.py", line 1135, in start
    self._raise_for_status(res)
  File "/home/airflow/.local/lib/python3.9/site-packages/docker/api/client.py", line 267, in _raise_for_status
    raise create_api_error_from_http_exception(e) from e
  File "/home/airflow/.local/lib/python3.9/site-packages/docker/errors.py", line 39, in create_api_error_from_http_exception
    raise cls(e, response=response, explanation=explanation) from e
docker.errors.APIError: 400 Client Error for http+docker://localhost/v1.51/containers/de0ec0d342b9333739260436caced1383bb909b369a351462ce110db1aef4b49/start: Bad Request ("failed to create task for container: failed to create shim task: OCI runtime create failed: runc create failed: unable to start container process: error during container init: exec: "python": executable file not found in $PATH: unknown")
[2025-08-13T13:49:11.457+0000] {taskinstance.py:1138} INFO - Marking task as FAILED. dag_id=bank_data_generation_dag, task_id=generate_bank_data, execution_date=20250813T134905, start_date=20250813T134909, end_date=20250813T134911
[2025-08-13T13:49:11.487+0000] {standard_task_runner.py:107} ERROR - Failed to execute job 3 for task generate_bank_data (400 Client Error for http+docker://localhost/v1.51/containers/de0ec0d342b9333739260436caced1383bb909b369a351462ce110db1aef4b49/start: Bad Request ("failed to create task for container: failed to create shim task: OCI runtime create failed: runc create failed: unable to start container process: error during container init: exec: "python": executable file not found in $PATH: unknown"); 52)
[2025-08-13T13:49:11.520+0000] {local_task_job_runner.py:234} INFO - Task exited with return code 1
[2025-08-13T13:49:11.550+0000] {taskinstance.py:3280} INFO - 0 downstream tasks scheduled from follow-on schedule check
