[2025-08-13T16:40:50.419+0000] {taskinstance.py:1956} INFO - Dependencies all met for dep_context=non-requeueable deps ti=<TaskInstance: bank_data_generation_dag.generate_bank_data manual__2025-08-13T16:40:47.539107+00:00 [queued]>
[2025-08-13T16:40:50.434+0000] {taskinstance.py:1956} INFO - Dependencies all met for dep_context=requeueable deps ti=<TaskInstance: bank_data_generation_dag.generate_bank_data manual__2025-08-13T16:40:47.539107+00:00 [queued]>
[2025-08-13T16:40:50.435+0000] {taskinstance.py:2170} INFO - Starting attempt 1 of 1
[2025-08-13T16:40:50.457+0000] {taskinstance.py:2191} INFO - Executing <Task(DockerOperator): generate_bank_data> on 2025-08-13 16:40:47.539107+00:00
[2025-08-13T16:40:50.465+0000] {standard_task_runner.py:60} INFO - Started process 49 to run task
[2025-08-13T16:40:50.473+0000] {standard_task_runner.py:87} INFO - Running: ['***', 'tasks', 'run', 'bank_data_generation_dag', 'generate_bank_data', 'manual__2025-08-13T16:40:47.539107+00:00', '--job-id', '6', '--raw', '--subdir', 'DAGS_FOLDER/bank_data_dag.py', '--cfg-path', '/tmp/tmpaz46q3bs']
[2025-08-13T16:40:50.477+0000] {standard_task_runner.py:88} INFO - Job 6: Subtask generate_bank_data
[2025-08-13T16:40:50.580+0000] {task_command.py:423} INFO - Running <TaskInstance: bank_data_generation_dag.generate_bank_data manual__2025-08-13T16:40:47.539107+00:00 [running]> on host 8f2b302cd61d
[2025-08-13T16:40:50.696+0000] {taskinstance.py:2480} INFO - Exporting env vars: AIRFLOW_CTX_DAG_OWNER='***' AIRFLOW_CTX_DAG_ID='bank_data_generation_dag' AIRFLOW_CTX_TASK_ID='generate_bank_data' AIRFLOW_CTX_EXECUTION_DATE='2025-08-13T16:40:47.539107+00:00' AIRFLOW_CTX_TRY_NUMBER='1' AIRFLOW_CTX_DAG_RUN_ID='manual__2025-08-13T16:40:47.539107+00:00'
[2025-08-13T16:40:50.760+0000] {docker.py:359} INFO - Starting docker container from image arlequin-pyspark-client
[2025-08-13T16:40:53.175+0000] {docker.py:429} INFO - /opt/spark/bin/load-spark-env.sh: line 68: ps: command not found
[2025-08-13T16:40:57.875+0000] {docker.py:429} INFO - Setting default log level to "WARN".
To adjust logging level use sc.setLogLevel(newLevel). For SparkR, use setLogLevel(newLevel).
[2025-08-13T16:40:58.270+0000] {docker.py:429} INFO - 25/08/13 16:40:58 WARN NativeCodeLoader: Unable to load native-hadoop library for your platform... using builtin-java classes where applicable
[2025-08-13T16:41:20.841+0000] {job.py:213} ERROR - Job heartbeat got an exception
Traceback (most recent call last):
  File "/home/airflow/.local/lib/python3.9/site-packages/sqlalchemy/engine/base.py", line 3371, in _wrap_pool_connect
    return fn()
  File "/home/airflow/.local/lib/python3.9/site-packages/sqlalchemy/pool/base.py", line 327, in connect
    return _ConnectionFairy._checkout(self)
  File "/home/airflow/.local/lib/python3.9/site-packages/sqlalchemy/pool/base.py", line 894, in _checkout
    fairy = _ConnectionRecord.checkout(pool)
  File "/home/airflow/.local/lib/python3.9/site-packages/sqlalchemy/pool/base.py", line 493, in checkout
    rec = pool._do_get()
  File "/home/airflow/.local/lib/python3.9/site-packages/sqlalchemy/pool/impl.py", line 256, in _do_get
    return self._create_connection()
  File "/home/airflow/.local/lib/python3.9/site-packages/sqlalchemy/pool/base.py", line 273, in _create_connection
    return _ConnectionRecord(self)
  File "/home/airflow/.local/lib/python3.9/site-packages/sqlalchemy/pool/base.py", line 388, in __init__
    self.__connect()
  File "/home/airflow/.local/lib/python3.9/site-packages/sqlalchemy/pool/base.py", line 691, in __connect
    pool.logger.debug("Error on connect(): %s", e)
  File "/home/airflow/.local/lib/python3.9/site-packages/sqlalchemy/util/langhelpers.py", line 70, in __exit__
    compat.raise_(
  File "/home/airflow/.local/lib/python3.9/site-packages/sqlalchemy/util/compat.py", line 211, in raise_
    raise exception
  File "/home/airflow/.local/lib/python3.9/site-packages/sqlalchemy/pool/base.py", line 686, in __connect
    self.dbapi_connection = connection = pool._invoke_creator(self)
  File "/home/airflow/.local/lib/python3.9/site-packages/sqlalchemy/engine/create.py", line 574, in connect
    return dialect.connect(*cargs, **cparams)
  File "/home/airflow/.local/lib/python3.9/site-packages/sqlalchemy/engine/default.py", line 598, in connect
    return self.dbapi.connect(*cargs, **cparams)
  File "/home/airflow/.local/lib/python3.9/site-packages/psycopg2/__init__.py", line 122, in connect
    conn = _connect(dsn, connection_factory=connection_factory, **kwasync)
psycopg2.OperationalError: could not translate host name "postgres" to address: Temporary failure in name resolution


The above exception was the direct cause of the following exception:

Traceback (most recent call last):
  File "/home/airflow/.local/lib/python3.9/site-packages/airflow/jobs/job.py", line 187, in heartbeat
    self._merge_from(Job._fetch_from_db(self, session))
  File "/home/airflow/.local/lib/python3.9/site-packages/airflow/api_internal/internal_api_call.py", line 114, in wrapper
    return func(*args, **kwargs)
  File "/home/airflow/.local/lib/python3.9/site-packages/airflow/utils/session.py", line 76, in wrapper
    return func(*args, **kwargs)
  File "/home/airflow/.local/lib/python3.9/site-packages/airflow/jobs/job.py", line 308, in _fetch_from_db
    session.merge(job)
  File "/home/airflow/.local/lib/python3.9/site-packages/sqlalchemy/orm/session.py", line 3056, in merge
    return self._merge(
  File "/home/airflow/.local/lib/python3.9/site-packages/sqlalchemy/orm/session.py", line 3136, in _merge
    merged = self.get(
  File "/home/airflow/.local/lib/python3.9/site-packages/sqlalchemy/orm/session.py", line 2853, in get
    return self._get_impl(
  File "/home/airflow/.local/lib/python3.9/site-packages/sqlalchemy/orm/session.py", line 2975, in _get_impl
    return db_load_fn(
  File "/home/airflow/.local/lib/python3.9/site-packages/sqlalchemy/orm/loading.py", line 530, in load_on_pk_identity
    session.execute(
  File "/home/airflow/.local/lib/python3.9/site-packages/sqlalchemy/orm/session.py", line 1716, in execute
    conn = self._connection_for_bind(bind)
  File "/home/airflow/.local/lib/python3.9/site-packages/sqlalchemy/orm/session.py", line 1555, in _connection_for_bind
    return self._transaction._connection_for_bind(
  File "/home/airflow/.local/lib/python3.9/site-packages/sqlalchemy/orm/session.py", line 750, in _connection_for_bind
    conn = bind.connect()
  File "/home/airflow/.local/lib/python3.9/site-packages/sqlalchemy/future/engine.py", line 412, in connect
    return super(Engine, self).connect()
  File "/home/airflow/.local/lib/python3.9/site-packages/sqlalchemy/engine/base.py", line 3325, in connect
    return self._connection_cls(self, close_with_result=close_with_result)
  File "/home/airflow/.local/lib/python3.9/site-packages/sqlalchemy/engine/base.py", line 96, in __init__
    else engine.raw_connection()
  File "/home/airflow/.local/lib/python3.9/site-packages/sqlalchemy/engine/base.py", line 3404, in raw_connection
    return self._wrap_pool_connect(self.pool.connect, _connection)
  File "/home/airflow/.local/lib/python3.9/site-packages/sqlalchemy/engine/base.py", line 3374, in _wrap_pool_connect
    Connection._handle_dbapi_exception_noconnection(
  File "/home/airflow/.local/lib/python3.9/site-packages/sqlalchemy/engine/base.py", line 2208, in _handle_dbapi_exception_noconnection
    util.raise_(
  File "/home/airflow/.local/lib/python3.9/site-packages/sqlalchemy/util/compat.py", line 211, in raise_
    raise exception
  File "/home/airflow/.local/lib/python3.9/site-packages/sqlalchemy/engine/base.py", line 3371, in _wrap_pool_connect
    return fn()
  File "/home/airflow/.local/lib/python3.9/site-packages/sqlalchemy/pool/base.py", line 327, in connect
    return _ConnectionFairy._checkout(self)
  File "/home/airflow/.local/lib/python3.9/site-packages/sqlalchemy/pool/base.py", line 894, in _checkout
    fairy = _ConnectionRecord.checkout(pool)
  File "/home/airflow/.local/lib/python3.9/site-packages/sqlalchemy/pool/base.py", line 493, in checkout
    rec = pool._do_get()
  File "/home/airflow/.local/lib/python3.9/site-packages/sqlalchemy/pool/impl.py", line 256, in _do_get
    return self._create_connection()
  File "/home/airflow/.local/lib/python3.9/site-packages/sqlalchemy/pool/base.py", line 273, in _create_connection
    return _ConnectionRecord(self)
  File "/home/airflow/.local/lib/python3.9/site-packages/sqlalchemy/pool/base.py", line 388, in __init__
    self.__connect()
  File "/home/airflow/.local/lib/python3.9/site-packages/sqlalchemy/pool/base.py", line 691, in __connect
    pool.logger.debug("Error on connect(): %s", e)
  File "/home/airflow/.local/lib/python3.9/site-packages/sqlalchemy/util/langhelpers.py", line 70, in __exit__
    compat.raise_(
  File "/home/airflow/.local/lib/python3.9/site-packages/sqlalchemy/util/compat.py", line 211, in raise_
    raise exception
  File "/home/airflow/.local/lib/python3.9/site-packages/sqlalchemy/pool/base.py", line 686, in __connect
    self.dbapi_connection = connection = pool._invoke_creator(self)
  File "/home/airflow/.local/lib/python3.9/site-packages/sqlalchemy/engine/create.py", line 574, in connect
    return dialect.connect(*cargs, **cparams)
  File "/home/airflow/.local/lib/python3.9/site-packages/sqlalchemy/engine/default.py", line 598, in connect
    return self.dbapi.connect(*cargs, **cparams)
  File "/home/airflow/.local/lib/python3.9/site-packages/psycopg2/__init__.py", line 122, in connect
    conn = _connect(dsn, connection_factory=connection_factory, **kwasync)
sqlalchemy.exc.OperationalError: (psycopg2.OperationalError) could not translate host name "postgres" to address: Temporary failure in name resolution

(Background on this error at: https://sqlalche.me/e/14/e3q8)
[2025-08-13T16:41:20.890+0000] {job.py:221} ERROR - Job heartbeat failed with error. Scheduler is in unhealthy state
[2025-08-13T16:41:23.495+0000] {docker.py:429} INFO - [Stage 0:>                                                          (0 + 0) / 2]
[2025-08-13T16:41:35.950+0000] {job.py:221} ERROR - Job heartbeat failed with error. Scheduler is in unhealthy state
[2025-08-13T16:41:51.135+0000] {job.py:221} ERROR - Job heartbeat failed with error. Scheduler is in unhealthy state
[2025-08-13T16:42:06.323+0000] {job.py:221} ERROR - Job heartbeat failed with error. Scheduler is in unhealthy state
[2025-08-13T16:42:21.443+0000] {job.py:221} ERROR - Job heartbeat failed with error. Scheduler is in unhealthy state
[2025-08-13T16:42:23.713+0000] {docker.py:429} INFO - 25/08/13 16:41:38 WARN TaskSchedulerImpl: Initial job has not accepted any resources; check your cluster UI to ensure that workers are registered and have sufficient resources
[2025-08-13T16:42:23.722+0000] {docker.py:429} INFO - 25/08/13 16:41:53 WARN TaskSchedulerImpl: Initial job has not accepted any resources; check your cluster UI to ensure that workers are registered and have sufficient resources
25/08/13 16:42:08 WARN TaskSchedulerImpl: Initial job has not accepted any resources; check your cluster UI to ensure that workers are registered and have sufficient resources
25/08/13 16:42:23 WARN TaskSchedulerImpl: Initial job has not accepted any resources; check your cluster UI to ensure that workers are registered and have sufficient resources
[Stage 0:>                                                          (0 + 0) / 2]
[2025-08-13T16:42:53.819+0000] {job.py:221} ERROR - Job heartbeat failed with error. Scheduler is in unhealthy state
[2025-08-13T16:43:10.824+0000] {job.py:221} ERROR - Job heartbeat failed with error. Scheduler is in unhealthy state
[2025-08-13T16:43:27.618+0000] {job.py:221} ERROR - Job heartbeat failed with error. Scheduler is in unhealthy state
[2025-08-13T16:44:00.577+0000] {job.py:221} ERROR - Job heartbeat failed with error. Scheduler is in unhealthy state
